Workbook
Name P1X: OFFSET(MODEL_PARETO!$G$2,0,0,COUNT(MODEL_PARETO!$B$2:$B$26),1)
Name P1Y1: OFFSET(MODEL_PARETO!$L$2,0,0,COUNT(MODEL_PARETO!$B$2:$B$26),1)
Name P1Y2: OFFSET(MODEL_PARETO!$M$2,0,0,COUNT(MODEL_PARETO!$B$2:$B$26),1)
Name P2X: OFFSET(MODEL_PARETO!$O$2,0,0,COUNT(MODEL_PARETO!$B$2:$B$26),1)
Name P2Y1: OFFSET(MODEL_PARETO!$S$2,0,0,COUNT(MODEL_PARETO!$B$2:$B$26),1)
Name P2Y2: OFFSET(MODEL_PARETO!$T$2,0,0,COUNT(MODEL_PARETO!$B$2:$B$26),1)

Sheet INSTRUCTIONS
A1: INSTRUCTIONS
A3: 1 | B3: Copy your experimental matrix in the EXP_MATRIX sheet. | N3: EXP_MATRIX
A4: 2 | B4: Go to the MODEL sheet and indicate the model to be analyzed (only main factors and interaction terms, quadratic factors can also be included). | N4: MODEL
A6: MAIN RESULTS
B8: Design >> | E8: Orthogonality of the design | N8: DESIGN_CORRELATION
B9: Exploratory data analysis >> | E9: Responses | N9: EDA
E10: Effects >> | G10: Pareto chart | N10: MODEL_PARETO
G11: Main effects plots | N11: MODEL_MAINEFFECTS
G12: Two-factor interaction plots | N12: MODEL_INTERACTIONS
B13: Model >> | E13: Orthogonality of the model components | N13: MODEL_CORRELATION
E14: Model fit | N14: MODEL_FIT
E15: Model ANOVA | N15: MODEL_ANOVA
E16: Residuals >> | G16: Residuals plots (vs experimental order & vs predicted value) | N16: MODEL_RESIDUALPLOTS
G17: Residual normality test | N17: MODEL_RESIDUALSQQ
E18: Prediction | N18: MODEL_PREDICTION
E19: Analyses for center and pseudo-center points | N19: CENTER_POINTS
A21: The other worksheets include some alternative analyses and some intermediate calculations.
A23: This workbook requires Office 365 (Excel 2021 or newer). License: CC-BY-SA 4-0, https://creativecommons.org/licenses/by-sa/4.0/ 2024-2025, Jordi Cuadros, IQS Univ Ramon Llull, https://orcid.org/0000-0001-6513-9140

Sheet EXP_MATRIX
B1: Y | C1: A | D1: B | E1: C | F1: D | G1: E | H1: F | I1: G | J1: H | K1: J | L1: K | M1: L | N1: M | O1: N | P1: O | Q1: P | R1: Q | S1: R | T1: S | U1: T | V1: U | W1: V | X1: W | Y1: X | Z1: Z | AA1: Enter your experimental matrix into the yellow cells. Leave them blank for the columns and rows you don't need to use. Feel free to leave the Y column empty in case you only need to analyze the design matrix or still do not have the outcomes of your experiment. Many calculations on this workbook will work better (or be easier to interpret) if you use standard coding for your design matrix, i.e. experimental domain for each factor coded from -1 to 1. This workbook can handle up to 25 factors, 25 model components and 70 experimental runs.
A2: 1 | B2: 4.2919815 | C2: -1 | D2: -1 | E2: -1 | F2: -1 | G2: -1 | H2: -1 | I2: -1 | J2: -1 | K2: -1
A3: 2 | B3: 4.0079398 | C3: 1 | D3: -1 | E3: -1 | F3: -1 | G3: -1 | H3: 1 | I3: 1 | J3: -1 | K3: -1
A4: 3 | B4: 5.180476 | C4: -1 | D4: 1 | E4: -1 | F4: -1 | G4: -1 | H4: 1 | I4: 1 | J4: 1 | K4: -1
A5: 4 | B5: 4.6917005 | C5: 1 | D5: 1 | E5: -1 | F5: -1 | G5: -1 | H5: -1 | I5: -1 | J5: 1 | K5: -1
A6: 5 | B6: 8.533188 | C6: -1 | D6: -1 | E6: 1 | F6: -1 | G6: -1 | H6: 1 | I6: -1 | J6: 1 | K6: -1
A7: 6 | B7: 4.312169 | C7: 1 | D7: -1 | E7: 1 | F7: -1 | G7: -1 | H7: -1 | I7: 1 | J7: 1 | K7: -1
A8: 7 | B8: 8.317046 | C8: -1 | D8: 1 | E8: 1 | F8: -1 | G8: -1 | H8: -1 | I8: 1 | J8: -1 | K8: -1
A9: 8 | B9: 4.242967 | C9: 1 | D9: 1 | E9: 1 | F9: -1 | G9: -1 | H9: 1 | I9: -1 | J9: -1 | K9: -1
A10: 9 | B10: 4.73794 | C10: -1 | D10: -1 | E10: -1 | F10: 1 | G10: -1 | H10: -1 | I10: 1 | J10: 1 | K10: 1
A11: 10 | B11: 3.8313653 | C11: 1 | D11: -1 | E11: -1 | F11: 1 | G11: -1 | H11: 1 | I11: -1 | J11: 1 | K11: 1
A12: 11 | B12: 5.428064 | C12: -1 | D12: 1 | E12: -1 | F12: 1 | G12: -1 | H12: 1 | I12: -1 | J12: -1 | K12: 1
A13: 12 | B13: 4.822603 | C13: 1 | D13: 1 | E13: -1 | F13: 1 | G13: -1 | H13: -1 | I13: 1 | J13: -1 | K13: -1
... A33: 32 | B33: 7.239197 | C33: 1 | D33: 1 | E33: 1 | F33: 1 | G33: 1 | H33: 1 | I33: 1 | J33: -1 | K33: 1
A34: 33
A35: 34
A36: 35
A37: 36
A38: 37
A39: 38
A40: 39
A41: 40
A42: 41
A43: 42
A44: 43
A45: 44
... A71: 70

Sheet MODEL
A1: Indicate here the factors and interactions to be included in the model (max. 25) | Z1: Enter the components on your model into the yellow cells. Factors shall be included names with uppercase letters (A-X,Z). Interactions should indicated as ordered uppercase string, e.g, AB or ACD. Quadratic terms (e.g. A2) can also be included provided the variable is quantitative and at least three levels are included for these factors. Intercept is always included in the model and can not be taken out.
A2: A | B2: C | C2: E | D2: AC | E2: AE
A3: Orthogonality | F3: =IFERROR(MODEL_CORRELATION!F1,"") -> 1 | H3: (as determinant of the correlation matrix for the model matrix)
A4: =IFERROR(IF(F3<0.5,"AVAILABLE DATA/DESIGN DOES NOT ALLOW FITTING THIS MODEL",""),"")
A6: =IF(A2="","",A2) -> A | B6: =IF(B2="","",B2) -> C | C6: =IF(C2="","",C2) -> E | D6: =IF(D2="","",D2) -> AC | E6: =IF(E2="","",E2) -> AE | F6: =IF(F2="","",F2) | G6: =IF(G2="","",G2) | H6: =IF(H2="","",H2) | ... Y6: =IF(Y2="","",Y2)
A7: =IFERROR(A80,A64) -> 0.094223632 | B7: =IFERROR(B80,B64) -> 0.48788166 | C7: =IFERROR(C80,C64) -> 0.090986247 | D7: =IFERROR(D80,D64) -> 0.053799627 | E7: =IFERROR(E80,E64) -> 0.072876124 | F7: =IFERROR(F80,F64) | G7: =IFERROR(G80,G64) | H7: =IFERROR(H80,H64) | ... Y7: =IFERROR(Y80,Y64)
A8: ="↑ " & IF(ISERROR(A80),A61,A78) -> ↑ Explained variability (ANOVA Type II - Unique SS)
A9: Model explained variability | G9: =MODEL_FIT!B8 -> 0.79976729
A12: Levels per factor
A13: =A15 -> A | B13: =B15 -> C | C13: =C15 -> E | D13: =D15 -> AC | E13: =E15 -> AE | F13: =F15 | G13: =G15 | H13: =H15 | ... Y13: =Y15
A14: =IF(COUNT(A16:A24)>0,COUNT(A16:A24),"") -> 2 | B14: =IF(COUNT(B16:B24)>0,COUNT(B16:B24),"") -> 2 | C14: =IF(COUNT(C16:C24)>0,COUNT(C16:C24),"") -> 2 | D14: =IF(COUNT(D16:D24)>0,COUNT(D16:D24),"") -> 2 | E14: =IF(COUNT(E16:E24)>0,COUNT(E16:E24),"") -> 2 | F14: =IF(COUNT(F16:F24)>0,COUNT(F16:F24),"") | G14: =IF(COUNT(G16:G24)>0,COUNT(G16:G24),"") | H14: =IF(COUNT(H16:H24)>0,COUNT(H16:H24),"") | ... Y14: =IF(COUNT(Y16:Y24)>0,COUNT(Y16:Y24),"")
A15: =IF(A2="","",A2) -> A | B15: =IF(B2="","",B2) -> C | C15: =IF(C2="","",C2) -> E | D15: =IF(D2="","",D2) -> AC | E15: =IF(E2="","",E2) -> AE | F15: =IF(F2="","",F2) | G15: =IF(G2="","",G2) | H15: =IF(H2="","",H2) | ... Y15: =IF(Y2="","",Y2)
A16: {=_xlfn._xlws.SORT(_xlfn.UNIQUE(IF(MODEL_MATRIX!C2:C71="","",ROUND(MODEL_MATRIX!C2:C71,10))))} -> -1 | B16: {=_xlfn._xlws.SORT(_xlfn.UNIQUE(IF(MODEL_MATRIX!D2:D71="","",ROUND(MODEL_MATRIX!D2:D71,10))))} -> -1 | C16: {=_xlfn._xlws.SORT(_xlfn.UNIQUE(IF(MODEL_MATRIX!E2:E71="","",ROUND(MODEL_MATRIX!E2:E71,10))))} -> -1 | D16: {=_xlfn._xlws.SORT(_xlfn.UNIQUE(IF(MODEL_MATRIX!F2:F71="","",ROUND(MODEL_MATRIX!F2:F71,10))))} -> -1 | E16: {=_xlfn._xlws.SORT(_xlfn.UNIQUE(IF(MODEL_MATRIX!G2:G71="","",ROUND(MODEL_MATRIX!G2:G71,10))))} -> -1 | F16: {=_xlfn._xlws.SORT(_xlfn.UNIQUE(IF(MODEL_MATRIX!H2:H71="","",ROUND(MODEL_MATRIX!H2:H71,10))))} | G16: {=_xlfn._xlws.SORT(_xlfn.UNIQUE(IF(MODEL_MATRIX!I2:I71="","",ROUND(MODEL_MATRIX!I2:I71,10))))} | H16: {=_xlfn._xlws.SORT(_xlfn.UNIQUE(IF(MODEL_MATRIX!J2:J71="","",ROUND(MODEL_MATRIX!J2:J71,10))))} | ... Y16: {=_xlfn._xlws.SORT(_xlfn.UNIQUE(IF(MODEL_MATRIX!AA2:AA71="","",ROUND(MODEL_MATRIX!AA2:AA71,10))))}
A17: 1 | B17: 1 | C17: 1 | D17: 1 | E17: 1
A26: DoF
A27: =IF(A2="","",A2) -> A | B27: =IF(B2="","",B2) -> C | C27: =IF(C2="","",C2) -> E | D27: =IF(D2="","",D2) -> AC | E27: =IF(E2="","",E2) -> AE | F27: =IF(F2="","",F2) | G27: =IF(G2="","",G2) | H27: =IF(H2="","",H2) | ... Y27: =IF(Y2="","",Y2)
A28: {=IF(A27="","",PRODUCT(IF(ISERROR(FIND(DESIGN_FEATURES!$A$6:$X$6,MODEL!A27)),1,DESIGN_FEATURES!$A$5:$X$5-1)))} -> 1 | B28: {=IF(B27="","",PRODUCT(IF(ISERROR(FIND(DESIGN_FEATURES!$A$6:$X$6,MODEL!B27)),1,DESIGN_FEATURES!$A$5:$X$5-1)))} -> 1 | C28: {=IF(C27="","",PRODUCT(IF(ISERROR(FIND(DESIGN_FEATURES!$A$6:$X$6,MODEL!C27)),1,DESIGN_FEATURES!$A$5:$X$5-1)))} -> 1 | D28: {=IF(D27="","",PRODUCT(IF(ISERROR(FIND(DESIGN_FEATURES!$A$6:$X$6,MODEL!D27)),1,DESIGN_FEATURES!$A$5:$X$5-1)))} -> 1 | E28: {=IF(E27="","",PRODUCT(IF(ISERROR(FIND(DESIGN_FEATURES!$A$6:$X$6,MODEL!E27)),1,DESIGN_FEATURES!$A$5:$X$5-1)))} -> 1 | F28: {=IF(F27="","",PRODUCT(IF(ISERROR(FIND(DESIGN_FEATURES!$A$6:$X$6,MODEL!F27)),1,DESIGN_FEATURES!$A$5:$X$5-1)))} | G28: {=IF(G27="","",PRODUCT(IF(ISERROR(FIND(DESIGN_FEATURES!$A$6:$X$6,MODEL!G27)),1,DESIGN_FEATURES!$A$5:$X$5-1)))} | H28: {=IF(H27="","",PRODUCT(IF(ISERROR(FIND(DESIGN_FEATURES!$A$6:$X$6,MODEL!H27)),1,DESIGN_FEATURES!$A$5:$X$5-1)))} | ... Y28: {=IF(Y27="","",PRODUCT(IF(ISERROR(FIND(DESIGN_FEATURES!$A$6:$X$6,MODEL!Y27)),1,DESIGN_FEATURES!$A$5:$X$5-1)))}
A32: Counts per level
A33: =A15 -> A | B33: =B15 -> C | C33: =C15 -> E | D33: =D15 -> AC | E33: =E15 -> AE | F33: =F15 | G33: =G15 | H33: =H15 | ... Y33: =Y15
A34: =IF(A16="","",COUNTIF(MODEL_MATRIX!C$2:C$71,A16)) -> 16 | B34: =IF(B16="","",COUNTIF(MODEL_MATRIX!D$2:D$71,B16)) -> 16 | C34: =IF(C16="","",COUNTIF(MODEL_MATRIX!E$2:E$71,C16)) -> 16 | D34: =IF(D16="","",COUNTIF(MODEL_MATRIX!F$2:F$71,D16)) -> 16 | E34: =IF(E16="","",COUNTIF(MODEL_MATRIX!G$2:G$71,E16)) -> 16 | F34: =IF(F16="","",COUNTIF(MODEL_MATRIX!H$2:H$71,F16)) | G34: =IF(G16="","",COUNTIF(MODEL_MATRIX!I$2:I$71,G16)) | H34: =IF(H16="","",COUNTIF(MODEL_MATRIX!J$2:J$71,H16)) | ... Y34: =IF(Y16="","",COUNTIF(MODEL_MATRIX!AA$2:AA$71,Y16))
A35: =IF(A17="","",COUNTIF(MODEL_MATRIX!C$2:C$71,A17)) -> 16 | B35: =IF(B17="","",COUNTIF(MODEL_MATRIX!D$2:D$71,B17)) -> 16 | C35: =IF(C17="","",COUNTIF(MODEL_MATRIX!E$2:E$71,C17)) -> 16 | D35: =IF(D17="","",COUNTIF(MODEL_MATRIX!F$2:F$71,D17)) -> 16 | E35: =IF(E17="","",COUNTIF(MODEL_MATRIX!G$2:G$71,E17)) -> 16 | F35: =IF(F17="","",COUNTIF(MODEL_MATRIX!H$2:H$71,F17)) | G35: =IF(G17="","",COUNTIF(MODEL_MATRIX!I$2:I$71,G17)) | H35: =IF(H17="","",COUNTIF(MODEL_MATRIX!J$2:J$71,H17)) | ... Y35: =IF(Y17="","",COUNTIF(MODEL_MATRIX!AA$2:AA$71,Y17))
A36: =IF(A18="","",COUNTIF(MODEL_MATRIX!C$2:C$71,A18)) | B36: =IF(B18="","",COUNTIF(MODEL_MATRIX!D$2:D$71,B18)) | C36: =IF(C18="","",COUNTIF(MODEL_MATRIX!E$2:E$71,C18)) | D36: =IF(D18="","",COUNTIF(MODEL_MATRIX!F$2:F$71,D18)) | E36: =IF(E18="","",COUNTIF(MODEL_MATRIX!G$2:G$71,E18)) | F36: =IF(F18="","",COUNTIF(MODEL_MATRIX!H$2:H$71,F18)) | G36: =IF(G18="","",COUNTIF(MODEL_MATRIX!I$2:I$71,G18)) | H36: =IF(H18="","",COUNTIF(MODEL_MATRIX!J$2:J$71,H18)) | ... Y36: =IF(Y18="","",COUNTIF(MODEL_MATRIX!AA$2:AA$71,Y18))
A37: =IF(A19="","",COUNTIF(MODEL_MATRIX!C$2:C$71,A19)) | B37: =IF(B19="","",COUNTIF(MODEL_MATRIX!D$2:D$71,B19)) | C37: =IF(C19="","",COUNTIF(MODEL_MATRIX!E$2:E$71,C19)) | D37: =IF(D19="","",COUNTIF(MODEL_MATRIX!F$2:F$71,D19)) | E37: =IF(E19="","",COUNTIF(MODEL_MATRIX!G$2:G$71,E19)) | F37: =IF(F19="","",COUNTIF(MODEL_MATRIX!H$2:H$71,F19)) | G37: =IF(G19="","",COUNTIF(MODEL_MATRIX!I$2:I$71,G19)) | H37: =IF(H19="","",COUNTIF(MODEL_MATRIX!J$2:J$71,H19)) | ... Y37: =IF(Y19="","",COUNTIF(MODEL_MATRIX!AA$2:AA$71,Y19))
A38: =IF(A20="","",COUNTIF(MODEL_MATRIX!C$2:C$71,A20)) | B38: =IF(B20="","",COUNTIF(MODEL_MATRIX!D$2:D$71,B20)) | C38: =IF(C20="","",COUNTIF(MODEL_MATRIX!E$2:E$71,C20)) | D38: =IF(D20="","",COUNTIF(MODEL_MATRIX!F$2:F$71,D20)) | E38: =IF(E20="","",COUNTIF(MODEL_MATRIX!G$2:G$71,E20)) | F38: =IF(F20="","",COUNTIF(MODEL_MATRIX!H$2:H$71,F20)) | G38: =IF(G20="","",COUNTIF(MODEL_MATRIX!I$2:I$71,G20)) | H38: =IF(H20="","",COUNTIF(MODEL_MATRIX!J$2:J$71,H20)) | ... Y38: =IF(Y20="","",COUNTIF(MODEL_MATRIX!AA$2:AA$71,Y20))
A39: =IF(A21="","",COUNTIF(MODEL_MATRIX!C$2:C$71,A21)) | B39: =IF(B21="","",COUNTIF(MODEL_MATRIX!D$2:D$71,B21)) | C39: =IF(C21="","",COUNTIF(MODEL_MATRIX!E$2:E$71,C21)) | D39: =IF(D21="","",COUNTIF(MODEL_MATRIX!F$2:F$71,D21)) | E39: =IF(E21="","",COUNTIF(MODEL_MATRIX!G$2:G$71,E21)) | F39: =IF(F21="","",COUNTIF(MODEL_MATRIX!H$2:H$71,F21)) | G39: =IF(G21="","",COUNTIF(MODEL_MATRIX!I$2:I$71,G21)) | H39: =IF(H21="","",COUNTIF(MODEL_MATRIX!J$2:J$71,H21)) | ... Y39: =IF(Y21="","",COUNTIF(MODEL_MATRIX!AA$2:AA$71,Y21))
A40: =IF(A22="","",COUNTIF(MODEL_MATRIX!C$2:C$71,A22)) | B40: =IF(B22="","",COUNTIF(MODEL_MATRIX!D$2:D$71,B22)) | C40: =IF(C22="","",COUNTIF(MODEL_MATRIX!E$2:E$71,C22)) | D40: =IF(D22="","",COUNTIF(MODEL_MATRIX!F$2:F$71,D22)) | E40: =IF(E22="","",COUNTIF(MODEL_MATRIX!G$2:G$71,E22)) | F40: =IF(F22="","",COUNTIF(MODEL_MATRIX!H$2:H$71,F22)) | G40: =IF(G22="","",COUNTIF(MODEL_MATRIX!I$2:I$71,G22)) | H40: =IF(H22="","",COUNTIF(MODEL_MATRIX!J$2:J$71,H22)) | ... Y40: =IF(Y22="","",COUNTIF(MODEL_MATRIX!AA$2:AA$71,Y22))
A41: =IF(A23="","",COUNTIF(MODEL_MATRIX!C$2:C$71,A23)) | B41: =IF(B23="","",COUNTIF(MODEL_MATRIX!D$2:D$71,B23)) | C41: =IF(C23="","",COUNTIF(MODEL_MATRIX!E$2:E$71,C23)) | D41: =IF(D23="","",COUNTIF(MODEL_MATRIX!F$2:F$71,D23)) | E41: =IF(E23="","",COUNTIF(MODEL_MATRIX!G$2:G$71,E23)) | F41: =IF(F23="","",COUNTIF(MODEL_MATRIX!H$2:H$71,F23)) | G41: =IF(G23="","",COUNTIF(MODEL_MATRIX!I$2:I$71,G23)) | H41: =IF(H23="","",COUNTIF(MODEL_MATRIX!J$2:J$71,H23)) | ... Y41: =IF(Y23="","",COUNTIF(MODEL_MATRIX!AA$2:AA$71,Y23))
A42: =IF(A24="","",COUNTIF(MODEL_MATRIX!C$2:C$71,A24)) | B42: =IF(B24="","",COUNTIF(MODEL_MATRIX!D$2:D$71,B24)) | C42: =IF(C24="","",COUNTIF(MODEL_MATRIX!E$2:E$71,C24)) | D42: =IF(D24="","",COUNTIF(MODEL_MATRIX!F$2:F$71,D24)) | E42: =IF(E24="","",COUNTIF(MODEL_MATRIX!G$2:G$71,E24)) | F42: =IF(F24="","",COUNTIF(MODEL_MATRIX!H$2:H$71,F24)) | G42: =IF(G24="","",COUNTIF(MODEL_MATRIX!I$2:I$71,G24)) | H42: =IF(H24="","",COUNTIF(MODEL_MATRIX!J$2:J$71,H24)) | ... Y42: =IF(Y24="","",COUNTIF(MODEL_MATRIX!AA$2:AA$71,Y24))
A45: Averages per level | J45: Grand average | M45: =AVERAGE(EXP_MATRIX!B2:B71) -> 5.988929
A46: =A49 -> A | B46: =B49 -> C | C46: =C49 -> E | D46: =D49 -> AC | E46: =E49 -> AE | F46: =F49 | G46: =G49 | H46: =H49 | ... Y46: =Y49
A47: =IF(A49="","",OFFSET(A49,COUNT(A50:A58),0)-A50) -> -0.95248633 | B47: =IF(B49="","",OFFSET(B49,COUNT(B50:B58),0)-B50) -> 2.1673851 | C47: =IF(C49="","",OFFSET(C49,COUNT(C50:C58),0)-C50) -> 0.9359803 | D47: =IF(D49="","",OFFSET(D49,COUNT(D50:D58),0)-D50) -> -0.71972811 | E47: =IF(E49="","",OFFSET(E49,COUNT(E50:E58),0)-E50) -> 0.83766711 | F47: =IF(F49="","",OFFSET(F49,COUNT(F50:F58),0)-F50) | G47: =IF(G49="","",OFFSET(G49,COUNT(G50:G58),0)-G50) | H47: =IF(H49="","",OFFSET(H49,COUNT(H50:H58),0)-H50) | ... Y47: =IF(Y49="","",OFFSET(Y49,COUNT(Y50:Y58),0)-Y50) | Z47: << High-Low
A48: =IF(A49="","",MAX(A50:A58)-MIN(A50:A58)) -> 0.95248633 | B48: =IF(B49="","",MAX(B50:B58)-MIN(B50:B58)) -> 2.1673851 | C48: =IF(C49="","",MAX(C50:C58)-MIN(C50:C58)) -> 0.9359803 | D48: =IF(D49="","",MAX(D50:D58)-MIN(D50:D58)) -> 0.71972811 | E48: =IF(E49="","",MAX(E50:E58)-MIN(E50:E58)) -> 0.83766711 | F48: =IF(F49="","",MAX(F50:F58)-MIN(F50:F58)) | G48: =IF(G49="","",MAX(G50:G58)-MIN(G50:G58)) | H48: =IF(H49="","",MAX(H50:H58)-MIN(H50:H58)) | ... Y48: =IF(Y49="","",MAX(Y50:Y58)-MIN(Y50:Y58)) | Z48: << Range
A49: =A15 -> A | B49: =B15 -> C | C49: =C15 -> E | D49: =D15 -> AC | E49: =E15 -> AE | F49: =F15 | G49: =G15 | H49: =H15 | ... Y49: =Y15
A50: {=IF(A16="","",AVERAGE(IF(MODEL_MATRIX!C$2:C$71="","",IF(ROUND(MODEL_MATRIX!C$2:C$71,10)=ROUND(A16,10),MODEL_MATRIX!$B$2:$B$71))))} -> 6.4651722 | B50: {=IF(B16="","",AVERAGE(IF(MODEL_MATRIX!D$2:D$71="","",IF(ROUND(MODEL_MATRIX!D$2:D$71,10)=ROUND(B16,10),MODEL_MATRIX!$B$2:$B$71))))} -> 4.9052365 | C50: {=IF(C16="","",AVERAGE(IF(MODEL_MATRIX!E$2:E$71="","",IF(ROUND(MODEL_MATRIX!E$2:E$71,10)=ROUND(C16,10),MODEL_MATRIX!$B$2:$B$71))))} -> 5.5209389 | D50: {=IF(D16="","",AVERAGE(IF(MODEL_MATRIX!F$2:F$71="","",IF(ROUND(MODEL_MATRIX!F$2:F$71,10)=ROUND(D16,10),MODEL_MATRIX!$B$2:$B$71))))} -> 6.3487931 | E50: {=IF(E16="","",AVERAGE(IF(MODEL_MATRIX!G$2:G$71="","",IF(ROUND(MODEL_MATRIX!G$2:G$71,10)=ROUND(E16,10),MODEL_MATRIX!$B$2:$B$71))))} -> 5.5700955 | F50: {=IF(F16="","",AVERAGE(IF(MODEL_MATRIX!H$2:H$71="","",IF(ROUND(MODEL_MATRIX!H$2:H$71,10)=ROUND(F16,10),MODEL_MATRIX!$B$2:$B$71))))} | G50: {=IF(G16="","",AVERAGE(IF(MODEL_MATRIX!I$2:I$71="","",IF(ROUND(MODEL_MATRIX!I$2:I$71,10)=ROUND(G16,10),MODEL_MATRIX!$B$2:$B$71))))} | H50: {=IF(H16="","",AVERAGE(IF(MODEL_MATRIX!J$2:J$71="","",IF(ROUND(MODEL_MATRIX!J$2:J$71,10)=ROUND(H16,10),MODEL_MATRIX!$B$2:$B$71))))} | ... Y50: {=IF(Y16="","",AVERAGE(IF(MODEL_MATRIX!AA$2:AA$71="","",IF(ROUND(MODEL_MATRIX!AA$2:AA$71,10)=ROUND(Y16,10),MODEL_MATRIX!$B$2:$B$71))))}
A51: {=IF(A17="","",AVERAGE(IF(MODEL_MATRIX!C$2:C$71="","",IF(ROUND(MODEL_MATRIX!C$2:C$71,10)=ROUND(A17,10),MODEL_MATRIX!$B$2:$B$71))))} -> 5.5126858 | B51: {=IF(B17="","",AVERAGE(IF(MODEL_MATRIX!D$2:D$71="","",IF(ROUND(MODEL_MATRIX!D$2:D$71,10)=ROUND(B17,10),MODEL_MATRIX!$B$2:$B$71))))} -> 7.0726216 | C51: {=IF(C17="","",AVERAGE(IF(MODEL_MATRIX!E$2:E$71="","",IF(ROUND(MODEL_MATRIX!E$2:E$71,10)=ROUND(C17,10),MODEL_MATRIX!$B$2:$B$71))))} -> 6.4569192 | D51: {=IF(D17="","",AVERAGE(IF(MODEL_MATRIX!F$2:F$71="","",IF(ROUND(MODEL_MATRIX!F$2:F$71,10)=ROUND(D17,10),MODEL_MATRIX!$B$2:$B$71))))} -> 5.629065 | E51: {=IF(E17="","",AVERAGE(IF(MODEL_MATRIX!G$2:G$71="","",IF(ROUND(MODEL_MATRIX!G$2:G$71,10)=ROUND(E17,10),MODEL_MATRIX!$B$2:$B$71))))} -> 6.4077626 | F51: {=IF(F17="","",AVERAGE(IF(MODEL_MATRIX!H$2:H$71="","",IF(ROUND(MODEL_MATRIX!H$2:H$71,10)=ROUND(F17,10),MODEL_MATRIX!$B$2:$B$71))))} | G51: {=IF(G17="","",AVERAGE(IF(MODEL_MATRIX!I$2:I$71="","",IF(ROUND(MODEL_MATRIX!I$2:I$71,10)=ROUND(G17,10),MODEL_MATRIX!$B$2:$B$71))))} | H51: {=IF(H17="","",AVERAGE(IF(MODEL_MATRIX!J$2:J$71="","",IF(ROUND(MODEL_MATRIX!J$2:J$71,10)=ROUND(H17,10),MODEL_MATRIX!$B$2:$B$71))))} | ... Y51: {=IF(Y17="","",AVERAGE(IF(MODEL_MATRIX!AA$2:AA$71="","",IF(ROUND(MODEL_MATRIX!AA$2:AA$71,10)=ROUND(Y17,10),MODEL_MATRIX!$B$2:$B$71))))}
A52: {=IF(A18="","",AVERAGE(IF(MODEL_MATRIX!C$2:C$71="","",IF(ROUND(MODEL_MATRIX!C$2:C$71,10)=ROUND(A18,10),MODEL_MATRIX!$B$2:$B$71))))} | B52: {=IF(B18="","",AVERAGE(IF(MODEL_MATRIX!D$2:D$71="","",IF(ROUND(MODEL_MATRIX!D$2:D$71,10)=ROUND(B18,10),MODEL_MATRIX!$B$2:$B$71))))} | C52: {=IF(C18="","",AVERAGE(IF(MODEL_MATRIX!E$2:E$71="","",IF(ROUND(MODEL_MATRIX!E$2:E$71,10)=ROUND(C18,10),MODEL_MATRIX!$B$2:$B$71))))} | D52: {=IF(D18="","",AVERAGE(IF(MODEL_MATRIX!F$2:F$71="","",IF(ROUND(MODEL_MATRIX!F$2:F$71,10)=ROUND(D18,10),MODEL_MATRIX!$B$2:$B$71))))} | E52: {=IF(E18="","",AVERAGE(IF(MODEL_MATRIX!G$2:G$71="","",IF(ROUND(MODEL_MATRIX!G$2:G$71,10)=ROUND(E18,10),MODEL_MATRIX!$B$2:$B$71))))} | F52: {=IF(F18="","",AVERAGE(IF(MODEL_MATRIX!H$2:H$71="","",IF(ROUND(MODEL_MATRIX!H$2:H$71,10)=ROUND(F18,10),MODEL_MATRIX!$B$2:$B$71))))} | G52: {=IF(G18="","",AVERAGE(IF(MODEL_MATRIX!I$2:I$71="","",IF(ROUND(MODEL_MATRIX!I$2:I$71,10)=ROUND(G18,10),MODEL_MATRIX!$B$2:$B$71))))} | H52: {=IF(H18="","",AVERAGE(IF(MODEL_MATRIX!J$2:J$71="","",IF(ROUND(MODEL_MATRIX!J$2:J$71,10)=ROUND(H18,10),MODEL_MATRIX!$B$2:$B$71))))} | ... Y52: {=IF(Y18="","",AVERAGE(IF(MODEL_MATRIX!AA$2:AA$71="","",IF(ROUND(MODEL_MATRIX!AA$2:AA$71,10)=ROUND(Y18,10),MODEL_MATRIX!$B$2:$B$71))))}
A53: {=IF(A19="","",AVERAGE(IF(MODEL_MATRIX!C$2:C$71="","",IF(ROUND(MODEL_MATRIX!C$2:C$71,10)=ROUND(A19,10),MODEL_MATRIX!$B$2:$B$71))))} | B53: {=IF(B19="","",AVERAGE(IF(MODEL_MATRIX!D$2:D$71="","",IF(ROUND(MODEL_MATRIX!D$2:D$71,10)=ROUND(B19,10),MODEL_MATRIX!$B$2:$B$71))))} | C53: {=IF(C19="","",AVERAGE(IF(MODEL_MATRIX!E$2:E$71="","",IF(ROUND(MODEL_MATRIX!E$2:E$71,10)=ROUND(C19,10),MODEL_MATRIX!$B$2:$B$71))))} | D53: {=IF(D19="","",AVERAGE(IF(MODEL_MATRIX!F$2:F$71="","",IF(ROUND(MODEL_MATRIX!F$2:F$71,10)=ROUND(D19,10),MODEL_MATRIX!$B$2:$B$71))))} | E53: {=IF(E19="","",AVERAGE(IF(MODEL_MATRIX!G$2:G$71="","",IF(ROUND(MODEL_MATRIX!G$2:G$71,10)=ROUND(E19,10),MODEL_MATRIX!$B$2:$B$71))))} | F53: {=IF(F19="","",AVERAGE(IF(MODEL_MATRIX!H$2:H$71="","",IF(ROUND(MODEL_MATRIX!H$2:H$71,10)=ROUND(F19,10),MODEL_MATRIX!$B$2:$B$71))))} | G53: {=IF(G19="","",AVERAGE(IF(MODEL_MATRIX!I$2:I$71="","",IF(ROUND(MODEL_MATRIX!I$2:I$71,10)=ROUND(G19,10),MODEL_MATRIX!$B$2:$B$71))))} | H53: {=IF(H19="","",AVERAGE(IF(MODEL_MATRIX!J$2:J$71="","",IF(ROUND(MODEL_MATRIX!J$2:J$71,10)=ROUND(H19,10),MODEL_MATRIX!$B$2:$B$71))))} | ... Y53: {=IF(Y19="","",AVERAGE(IF(MODEL_MATRIX!AA$2:AA$71="","",IF(ROUND(MODEL_MATRIX!AA$2:AA$71,10)=ROUND(Y19,10),MODEL_MATRIX!$B$2:$B$71))))}
A54: {=IF(A20="","",AVERAGE(IF(MODEL_MATRIX!C$2:C$71="","",IF(ROUND(MODEL_MATRIX!C$2:C$71,10)=ROUND(A20,10),MODEL_MATRIX!$B$2:$B$71))))} | B54: {=IF(B20="","",AVERAGE(IF(MODEL_MATRIX!D$2:D$71="","",IF(ROUND(MODEL_MATRIX!D$2:D$71,10)=ROUND(B20,10),MODEL_MATRIX!$B$2:$B$71))))} | C54: {=IF(C20="","",AVERAGE(IF(MODEL_MATRIX!E$2:E$71="","",IF(ROUND(MODEL_MATRIX!E$2:E$71,10)=ROUND(C20,10),MODEL_MATRIX!$B$2:$B$71))))} | D54: {=IF(D20="","",AVERAGE(IF(MODEL_MATRIX!F$2:F$71="","",IF(ROUND(MODEL_MATRIX!F$2:F$71,10)=ROUND(D20,10),MODEL_MATRIX!$B$2:$B$71))))} | E54: {=IF(E20="","",AVERAGE(IF(MODEL_MATRIX!G$2:G$71="","",IF(ROUND(MODEL_MATRIX!G$2:G$71,10)=ROUND(E20,10),MODEL_MATRIX!$B$2:$B$71))))} | F54: {=IF(F20="","",AVERAGE(IF(MODEL_MATRIX!H$2:H$71="","",IF(ROUND(MODEL_MATRIX!H$2:H$71,10)=ROUND(F20,10),MODEL_MATRIX!$B$2:$B$71))))} | G54: {=IF(G20="","",AVERAGE(IF(MODEL_MATRIX!I$2:I$71="","",IF(ROUND(MODEL_MATRIX!I$2:I$71,10)=ROUND(G20,10),MODEL_MATRIX!$B$2:$B$71))))} | H54: {=IF(H20="","",AVERAGE(IF(MODEL_MATRIX!J$2:J$71="","",IF(ROUND(MODEL_MATRIX!J$2:J$71,10)=ROUND(H20,10),MODEL_MATRIX!$B$2:$B$71))))} | ... Y54: {=IF(Y20="","",AVERAGE(IF(MODEL_MATRIX!AA$2:AA$71="","",IF(ROUND(MODEL_MATRIX!AA$2:AA$71,10)=ROUND(Y20,10),MODEL_MATRIX!$B$2:$B$71))))}
A55: {=IF(A21="","",AVERAGE(IF(MODEL_MATRIX!C$2:C$71="","",IF(ROUND(MODEL_MATRIX!C$2:C$71,10)=ROUND(A21,10),MODEL_MATRIX!$B$2:$B$71))))} | B55: {=IF(B21="","",AVERAGE(IF(MODEL_MATRIX!D$2:D$71="","",IF(ROUND(MODEL_MATRIX!D$2:D$71,10)=ROUND(B21,10),MODEL_MATRIX!$B$2:$B$71))))} | C55: {=IF(C21="","",AVERAGE(IF(MODEL_MATRIX!E$2:E$71="","",IF(ROUND(MODEL_MATRIX!E$2:E$71,10)=ROUND(C21,10),MODEL_MATRIX!$B$2:$B$71))))} | D55: {=IF(D21="","",AVERAGE(IF(MODEL_MATRIX!F$2:F$71="","",IF(ROUND(MODEL_MATRIX!F$2:F$71,10)=ROUND(D21,10),MODEL_MATRIX!$B$2:$B$71))))} | E55: {=IF(E21="","",AVERAGE(IF(MODEL_MATRIX!G$2:G$71="","",IF(ROUND(MODEL_MATRIX!G$2:G$71,10)=ROUND(E21,10),MODEL_MATRIX!$B$2:$B$71))))} | F55: {=IF(F21="","",AVERAGE(IF(MODEL_MATRIX!H$2:H$71="","",IF(ROUND(MODEL_MATRIX!H$2:H$71,10)=ROUND(F21,10),MODEL_MATRIX!$B$2:$B$71))))} | G55: {=IF(G21="","",AVERAGE(IF(MODEL_MATRIX!I$2:I$71="","",IF(ROUND(MODEL_MATRIX!I$2:I$71,10)=ROUND(G21,10),MODEL_MATRIX!$B$2:$B$71))))} | H55: {=IF(H21="","",AVERAGE(IF(MODEL_MATRIX!J$2:J$71="","",IF(ROUND(MODEL_MATRIX!J$2:J$71,10)=ROUND(H21,10),MODEL_MATRIX!$B$2:$B$71))))} | ... Y55: {=IF(Y21="","",AVERAGE(IF(MODEL_MATRIX!AA$2:AA$71="","",IF(ROUND(MODEL_MATRIX!AA$2:AA$71,10)=ROUND(Y21,10),MODEL_MATRIX!$B$2:$B$71))))}
A56: {=IF(A22="","",AVERAGE(IF(MODEL_MATRIX!C$2:C$71="","",IF(ROUND(MODEL_MATRIX!C$2:C$71,10)=ROUND(A22,10),MODEL_MATRIX!$B$2:$B$71))))} | B56: {=IF(B22="","",AVERAGE(IF(MODEL_MATRIX!D$2:D$71="","",IF(ROUND(MODEL_MATRIX!D$2:D$71,10)=ROUND(B22,10),MODEL_MATRIX!$B$2:$B$71))))} | C56: {=IF(C22="","",AVERAGE(IF(MODEL_MATRIX!E$2:E$71="","",IF(ROUND(MODEL_MATRIX!E$2:E$71,10)=ROUND(C22,10),MODEL_MATRIX!$B$2:$B$71))))} | D56: {=IF(D22="","",AVERAGE(IF(MODEL_MATRIX!F$2:F$71="","",IF(ROUND(MODEL_MATRIX!F$2:F$71,10)=ROUND(D22,10),MODEL_MATRIX!$B$2:$B$71))))} | E56: {=IF(E22="","",AVERAGE(IF(MODEL_MATRIX!G$2:G$71="","",IF(ROUND(MODEL_MATRIX!G$2:G$71,10)=ROUND(E22,10),MODEL_MATRIX!$B$2:$B$71))))} | F56: {=IF(F22="","",AVERAGE(IF(MODEL_MATRIX!H$2:H$71="","",IF(ROUND(MODEL_MATRIX!H$2:H$71,10)=ROUND(F22,10),MODEL_MATRIX!$B$2:$B$71))))} | G56: {=IF(G22="","",AVERAGE(IF(MODEL_MATRIX!I$2:I$71="","",IF(ROUND(MODEL_MATRIX!I$2:I$71,10)=ROUND(G22,10),MODEL_MATRIX!$B$2:$B$71))))} | H56: {=IF(H22="","",AVERAGE(IF(MODEL_MATRIX!J$2:J$71="","",IF(ROUND(MODEL_MATRIX!J$2:J$71,10)=ROUND(H22,10),MODEL_MATRIX!$B$2:$B$71))))} | ... Y56: {=IF(Y22="","",AVERAGE(IF(MODEL_MATRIX!AA$2:AA$71="","",IF(ROUND(MODEL_MATRIX!AA$2:AA$71,10)=ROUND(Y22,10),MODEL_MATRIX!$B$2:$B$71))))}
...

Sheet MODEL_PREDICTION
B1: alpha | C1: 0.05 | D1: k | E1: =_xlfn.T.INV(1-C1/2,AK7) -> 2.0555294
B3: Ypred | C3: S_Ypred | D3: CI_lwr | E3: CI_upr | F3: I | G3: =MODEL_MATRIX!C1 -> A | H3: =MODEL_MATRIX!D1 -> C | I3: =MODEL_MATRIX!E1 -> E | J3: =MODEL_MATRIX!F1 -> AC | K3: =MODEL_MATRIX!G1 -> AE | L3: =MODEL_MATRIX!H1 | M3: =MODEL_MATRIX!I1 | N3: =MODEL_MATRIX!J1 | ... AE3: =MODEL_MATRIX!AA1 | AG3: b | AH3: S_b | AJ3: S_res
A4: 1 | B4: {=IF(G4="","",MMULT(OFFSET(F4,0,0,COUNT(F4:F23),COUNT(F4:AE4)),OFFSET(AG4,0,0,COUNT(F4:AE4),1)))} | C4: {=IF(G4="","",(MMULT((OFFSET(F4,0,0,COUNT(F4:F23),COUNT(F4:AE4))-OFFSET(F31,0,0,COUNT(F4:F23),COUNT(F4:AE4)))^2,OFFSET(AH4,0,0,COUNT(F4:AE4),1)^2)+$AJ$4^2/$AJ$7)^0.5)} | D4: =IF(B4="","",B4-C4*$E$1) | E4: =IF(B4="","",B4+C4*$E$1) | F4: =IF(G4="","",1) | AF4: 1 | AG4: =IF(AF4>MODEL_FIT!$H$1+1,"",OFFSET(MODEL_FIT!$A$6,0,MODEL_FIT!$H$1+1-ROW()+ROW($AG$4),1,1)) -> 5.988929 | AH4: =IF(AF4>MODEL_FIT!$H$1+1,"",OFFSET(MODEL_FIT!$A$7,0,MODEL_FIT!$H$1+1-ROW()+ROW($AG$4),1,1)) -> 0.13615377 | AI4: =IF(AF4>MODEL_FIT!$H$1+1,"",OFFSET(MODEL_FIT!$A$5,0,MODEL_FIT!$H$1+1-ROW()+ROW($AG$4),1,1)) -> Intercept | AJ4: =MODEL_FIT!C8 -> 0.77020203 | AK4: =SQRT(AJ4^2/AJ7) -> 0.13615377
A5: 2 | D5: =IF(B5="","",B5-C5*$E$1) | E5: =IF(B5="","",B5+C5*$E$1) | F5: =IF(G5="","",1) | AF5: 2 | AG5: =IF(AF5>MODEL_FIT!$H$1+1,"",OFFSET(MODEL_FIT!$A$6,0,MODEL_FIT!$H$1+1-ROW()+ROW($AG$4),1,1)) -> -0.47624316 | AH5: =IF(AF5>MODEL_FIT!$H$1+1,"",OFFSET(MODEL_FIT!$A$7,0,MODEL_FIT!$H$1+1-ROW()+ROW($AG$4),1,1)) -> 0.13615377 | AI5: =IF(AF5>MODEL_FIT!$H$1+1,"",OFFSET(MODEL_FIT!$A$5,0,MODEL_FIT!$H$1+1-ROW()+ROW($AG$4),1,1)) -> A
A6: 3 | D6: =IF(B6="","",B6-C6*$E$1) | E6: =IF(B6="","",B6+C6*$E$1) | F6: =IF(G6="","",1) | AF6: 3 | AG6: =IF(AF6>MODEL_FIT!$H$1+1,"",OFFSET(MODEL_FIT!$A$6,0,MODEL_FIT!$H$1+1-ROW()+ROW($AG$4),1,1)) -> 1.0836925 | AH6: =IF(AF6>MODEL_FIT!$H$1+1,"",OFFSET(MODEL_FIT!$A$7,0,MODEL_FIT!$H$1+1-ROW()+ROW($AG$4),1,1)) -> 0.13615377 | AI6: =IF(AF6>MODEL_FIT!$H$1+1,"",OFFSET(MODEL_FIT!$A$5,0,MODEL_FIT!$H$1+1-ROW()+ROW($AG$4),1,1)) -> C | AJ6: n | AK6: gl
A7: 4 | D7: =IF(B7="","",B7-C7*$E$1) | E7: =IF(B7="","",B7+C7*$E$1) | F7: =IF(G7="","",1) | AF7: 4 | AG7: =IF(AF7>MODEL_FIT!$H$1+1,"",OFFSET(MODEL_FIT!$A$6,0,MODEL_FIT!$H$1+1-ROW()+ROW($AG$4),1,1)) -> 0.46799015 | AH7: =IF(AF7>MODEL_FIT!$H$1+1,"",OFFSET(MODEL_FIT!$A$7,0,MODEL_FIT!$H$1+1-ROW()+ROW($AG$4),1,1)) -> 0.13615377 | AI7: =IF(AF7>MODEL_FIT!$H$1+1,"",OFFSET(MODEL_FIT!$A$5,0,MODEL_FIT!$H$1+1-ROW()+ROW($AG$4),1,1)) -> E | AJ7: =DESIGN_FEATURES!E1 -> 32 | AK7: =MODEL_FIT!C9 -> 26
A8: 5 | D8: =IF(B8="","",B8-C8*$E$1) | E8: =IF(B8="","",B8+C8*$E$1) | F8: =IF(G8="","",1) | AF8: 5 | AG8: =IF(AF8>MODEL_FIT!$H$1+1,"",OFFSET(MODEL_FIT!$A$6,0,MODEL_FIT!$H$1+1-ROW()+ROW($AG$4),1,1)) -> -0.35986405 | AH8: =IF(AF8>MODEL_FIT!$H$1+1,"",OFFSET(MODEL_FIT!$A$7,0,MODEL_FIT!$H$1+1-ROW()+ROW($AG$4),1,1)) -> 0.13615377 | AI8: =IF(AF8>MODEL_FIT!$H$1+1,"",OFFSET(MODEL_FIT!$A$5,0,MODEL_FIT!$H$1+1-ROW()+ROW($AG$4),1,1)) -> AC
A9: 6 | D9: =IF(B9="","",B9-C9*$E$1) | E9: =IF(B9="","",B9+C9*$E$1) | F9: =IF(G9="","",1) | AF9: 6 | AG9: =IF(AF9>MODEL_FIT!$H$1+1,"",OFFSET(MODEL_FIT!$A$6,0,MODEL_FIT!$H$1+1-ROW()+ROW($AG$4),1,1)) -> 0.41883355 | AH9: =IF(AF9>MODEL_FIT!$H$1+1,"",OFFSET(MODEL_FIT!$A$7,0,MODEL_FIT!$H$1+1-ROW()+ROW($AG$4),1,1)) -> 0.13615377 | AI9: =IF(AF9>MODEL_FIT!$H$1+1,"",OFFSET(MODEL_FIT!$A$5,0,MODEL_FIT!$H$1+1-ROW()+ROW($AG$4),1,1)) -> AE
A10: 7 | D10: =IF(B10="","",B10-C10*$E$1) | E10: =IF(B10="","",B10+C10*$E$1) | F10: =IF(G10="","",1) | AF10: 7 | AG10: =IF(AF10>MODEL_FIT!$H$1+1,"",OFFSET(MODEL_FIT!$A$6,0,MODEL_FIT!$H$1+1-ROW()+ROW($AG$4),1,1)) | AH10: =IF(AF10>MODEL_FIT!$H$1+1,"",OFFSET(MODEL_FIT!$A$7,0,MODEL_FIT!$H$1+1-ROW()+ROW($AG$4),1,1)) | AI10: =IF(AF10>MODEL_FIT!$H$1+1,"",OFFSET(MODEL_FIT!$A$5,0,MODEL_FIT!$H$1+1-ROW()+ROW($AG$4),1,1))
A11: 8 | D11: =IF(B11="","",B11-C11*$E$1) | E11: =IF(B11="","",B11+C11*$E$1) | F11: =IF(G11="","",1) | AF11: 8 | AG11: =IF(AF11>MODEL_FIT!$H$1+1,"",OFFSET(MODEL_FIT!$A$6,0,MODEL_FIT!$H$1+1-ROW()+ROW($AG$4),1,1)) | AH11: =IF(AF11>MODEL_FIT!$H$1+1,"",OFFSET(MODEL_FIT!$A$7,0,MODEL_FIT!$H$1+1-ROW()+ROW($AG$4),1,1)) | AI11: =IF(AF11>MODEL_FIT!$H$1+1,"",OFFSET(MODEL_FIT!$A$5,0,MODEL_FIT!$H$1+1-ROW()+ROW($AG$4),1,1))
A12: 9 | D12: =IF(B12="","",B12-C12*$E$1) | E12: =IF(B12="","",B12+C12*$E$1) | F12: =IF(G12="","",1) | AF12: 9 | AG12: =IF(AF12>MODEL_FIT!$H$1+1,"",OFFSET(MODEL_FIT!$A$6,0,MODEL_FIT!$H$1+1-ROW()+ROW($AG$4),1,1)) | AH12: =IF(AF12>MODEL_FIT!$H$1+1,"",OFFSET(MODEL_FIT!$A$7,0,MODEL_FIT!$H$1+1-ROW()+ROW($AG$4),1,1)) | AI12: =IF(AF12>MODEL_FIT!$H$1+1,"",OFFSET(MODEL_FIT!$A$5,0,MODEL_FIT!$H$1+1-ROW()+ROW($AG$4),1,1))
A13: 10 | D13: =IF(B13="","",B13-C13*$E$1) | E13: =IF(B13="","",B13+C13*$E$1) | F13: =IF(G13="","",1) | AF13: 10 | AG13: =IF(AF13>MODEL_FIT!$H$1+1,"",OFFSET(MODEL_FIT!$A$6,0,MODEL_FIT!$H$1+1-ROW()+ROW($AG$4),1,1)) | AH13: =IF(AF13>MODEL_FIT!$H$1+1,"",OFFSET(MODEL_FIT!$A$7,0,MODEL_FIT!$H$1+1-ROW()+ROW($AG$4),1,1)) | AI13: =IF(AF13>MODEL_FIT!$H$1+1,"",OFFSET(MODEL_FIT!$A$5,0,MODEL_FIT!$H$1+1-ROW()+ROW($AG$4),1,1))
A14: 11 | D14: =IF(B14="","",B14-C14*$E$1) | E14: =IF(B14="","",B14+C14*$E$1) | F14: =IF(G14="","",1) | AF14: 11 | AG14: =IF(AF14>MODEL_FIT!$H$1+1,"",OFFSET(MODEL_FIT!$A$6,0,MODEL_FIT!$H$1+1-ROW()+ROW($AG$4),1,1)) | AH14: =IF(AF14>MODEL_FIT!$H$1+1,"",OFFSET(MODEL_FIT!$A$7,0,MODEL_FIT!$H$1+1-ROW()+ROW($AG$4),1,1)) | AI14: =IF(AF14>MODEL_FIT!$H$1+1,"",OFFSET(MODEL_FIT!$A$5,0,MODEL_FIT!$H$1+1-ROW()+ROW($AG$4),1,1))
A15: 12 | D15: =IF(B15="","",B15-C15*$E$1) | E15: =IF(B15="","",B15+C15*$E$1) | F15: =IF(G15="","",1) | AF15: 12 | AG15: =IF(AF15>MODEL_FIT!$H$1+1,"",OFFSET(MODEL_FIT!$A$6,0,MODEL_FIT!$H$1+1-ROW()+ROW($AG$4),1,1)) | AH15: =IF(AF15>MODEL_FIT!$H$1+1,"",OFFSET(MODEL_FIT!$A$7,0,MODEL_FIT!$H$1+1-ROW()+ROW($AG$4),1,1)) | AI15: =IF(AF15>MODEL_FIT!$H$1+1,"",OFFSET(MODEL_FIT!$A$5,0,MODEL_FIT!$H$1+1-ROW()+ROW($AG$4),1,1))
A16: 13 | D16: =IF(B16="","",B16-C16*$E$1) | E16: =IF(B16="","",B16+C16*$E$1) | F16: =IF(G16="","",1) | AF16: 13 | AG16: =IF(AF16>MODEL_FIT!$H$1+1,"",OFFSET(MODEL_FIT!$A$6,0,MODEL_FIT!$H$1+1-ROW()+ROW($AG$4),1,1)) | AH16: =IF(AF16>MODEL_FIT!$H$1+1,"",OFFSET(MODEL_FIT!$A$7,0,MODEL_FIT!$H$1+1-ROW()+ROW($AG$4),1,1)) | AI16: =IF(AF16>MODEL_FIT!$H$1+1,"",OFFSET(MODEL_FIT!$A$5,0,MODEL_FIT!$H$1+1-ROW()+ROW($AG$4),1,1))
A17: 14 | D17: =IF(B17="","",B17-C17*$E$1) | E17: =IF(B17="","",B17+C17*$E$1) | F17: =IF(G17="","",1) | AF17: 14 | AG17: =IF(AF17>MODEL_FIT!$H$1+1,"",OFFSET(MODEL_FIT!$A$6,0,MODEL_FIT!$H$1+1-ROW()+ROW($AG$4),1,1)) | AH17: =IF(AF17>MODEL_FIT!$H$1+1,"",OFFSET(MODEL_FIT!$A$7,0,MODEL_FIT!$H$1+1-ROW()+ROW($AG$4),1,1)) | AI17: =IF(AF17>MODEL_FIT!$H$1+1,"",OFFSET(MODEL_FIT!$A$5,0,MODEL_FIT!$H$1+1-ROW()+ROW($AG$4),1,1))
A18: 15 | D18: =IF(B18="","",B18-C18*$E$1) | E18: =IF(B18="","",B18+C18*$E$1) | F18: =IF(G18="","",1) | AF18: 15 | AG18: =IF(AF18>MODEL_FIT!$H$1+1,"",OFFSET(MODEL_FIT!$A$6,0,MODEL_FIT!$H$1+1-ROW()+ROW($AG$4),1,1)) | AH18: =IF(AF18>MODEL_FIT!$H$1+1,"",OFFSET(MODEL_FIT!$A$7,0,MODEL_FIT!$H$1+1-ROW()+ROW($AG$4),1,1)) | AI18: =IF(AF18>MODEL_FIT!$H$1+1,"",OFFSET(MODEL_FIT!$A$5,0,MODEL_FIT!$H$1+1-ROW()+ROW($AG$4),1,1))
A19: 16 | D19: =IF(B19="","",B19-C19*$E$1) | E19: =IF(B19="","",B19+C19*$E$1) | F19: =IF(G19="","",1) | AF19: 16 | AG19: =IF(AF19>MODEL_FIT!$H$1+1,"",OFFSET(MODEL_FIT!$A$6,0,MODEL_FIT!$H$1+1-ROW()+ROW($AG$4),1,1)) | AH19: =IF(AF19>MODEL_FIT!$H$1+1,"",OFFSET(MODEL_FIT!$A$7,0,MODEL_FIT!$H$1+1-ROW()+ROW($AG$4),1,1)) | AI19: =IF(AF19>MODEL_FIT!$H$1+1,"",OFFSET(MODEL_FIT!$A$5,0,MODEL_FIT!$H$1+1-ROW()+ROW($AG$4),1,1))
... A23: 20 | D23: =IF(B23="","",B23-C23*$E$1) | E23: =IF(B23="","",B23+C23*$E$1) | F23: =IF(G23="","",1) | AF23: 20 | AG23: =IF(AF23>MODEL_FIT!$H$1+1,"",OFFSET(MODEL_FIT!$A$6,0,MODEL_FIT!$H$1+1-ROW()+ROW($AG$4),1,1)) | AH23: =IF(AF23>MODEL_FIT!$H$1+1,"",OFFSET(MODEL_FIT!$A$7,0,MODEL_FIT!$H$1+1-ROW()+ROW($AG$4),1,1)) | AI23: =IF(AF23>MODEL_FIT!$H$1+1,"",OFFSET(MODEL_FIT!$A$5,0,MODEL_FIT!$H$1+1-ROW()+ROW($AG$4),1,1))
AF24: 21 | AG24: =IF(AF24>MODEL_FIT!$H$1+1,"",OFFSET(MODEL_FIT!$A$6,0,MODEL_FIT!$H$1+1-ROW()+ROW($AG$4),1,1)) | AH24: =IF(AF24>MODEL_FIT!$H$1+1,"",OFFSET(MODEL_FIT!$A$7,0,MODEL_FIT!$H$1+1-ROW()+ROW($AG$4),1,1)) | AI24: =IF(AF24>MODEL_FIT!$H$1+1,"",OFFSET(MODEL_FIT!$A$5,0,MODEL_FIT!$H$1+1-ROW()+ROW($AG$4),1,1))
A25: Enter the values for the components of the model in the yellow cells in order to evaluate the outcome (mean population value) at these conditions. Include the interactions if needed. Standard deviation for the predicted value, and confidence interval are also calculated (for the significance level set by the user, common value is 0,05). For additional details, check https://stats.libretexts.org/Bookshelves/Advanced_Statistics/Intermediate_Statistics_with_R_(Greenwood)/07%3A_Simple_linear_regression_inference/7.07%3A_Confidence_interval_for_the_mean_and_prediction_intervals_for_a_new_observation | AF25: 22 | AG25: =IF(AF25>MODEL_FIT!$H$1+1,"",OFFSET(MODEL_FIT!$A$6,0,MODEL_FIT!$H$1+1-ROW()+ROW($AG$4),1,1)) | AH25: =IF(AF25>MODEL_FIT!$H$1+1,"",OFFSET(MODEL_FIT!$A$7,0,MODEL_FIT!$H$1+1-ROW()+ROW($AG$4),1,1)) | AI25: =IF(AF25>MODEL_FIT!$H$1+1,"",OFFSET(MODEL_FIT!$A$5,0,MODEL_FIT!$H$1+1-ROW()+ROW($AG$4),1,1))
AF26: 23 | AG26: =IF(AF26>MODEL_FIT!$H$1+1,"",OFFSET(MODEL_FIT!$A$6,0,MODEL_FIT!$H$1+1-ROW()+ROW($AG$4),1,1)) | AH26: =IF(AF26>MODEL_FIT!$H$1+1,"",OFFSET(MODEL_FIT!$A$7,0,MODEL_FIT!$H$1+1-ROW()+ROW($AG$4),1,1)) | AI26: =IF(AF26>MODEL_FIT!$H$1+1,"",OFFSET(MODEL_FIT!$A$5,0,MODEL_FIT!$H$1+1-ROW()+ROW($AG$4),1,1))
AF27: 24 | AG27: =IF(AF27>MODEL_FIT!$H$1+1,"",OFFSET(MODEL_FIT!$A$6,0,MODEL_FIT!$H$1+1-ROW()+ROW($AG$4),1,1)) | AH27: =IF(AF27>MODEL_FIT!$H$1+1,"",OFFSET(MODEL_FIT!$A$7,0,MODEL_FIT!$H$1+1-ROW()+ROW($AG$4),1,1)) | AI27: =IF(AF27>MODEL_FIT!$H$1+1,"",OFFSET(MODEL_FIT!$A$5,0,MODEL_FIT!$H$1+1-ROW()+ROW($AG$4),1,1))
AF28: 25 | AG28: =IF(AF28>MODEL_FIT!$H$1+1,"",OFFSET(MODEL_FIT!$A$6,0,MODEL_FIT!$H$1+1-ROW()+ROW($AG$4),1,1)) | AH28: =IF(AF28>MODEL_FIT!$H$1+1,"",OFFSET(MODEL_FIT!$A$7,0,MODEL_FIT!$H$1+1-ROW()+ROW($AG$4),1,1)) | AI28: =IF(AF28>MODEL_FIT!$H$1+1,"",OFFSET(MODEL_FIT!$A$5,0,MODEL_FIT!$H$1+1-ROW()+ROW($AG$4),1,1))
AF29: 26 | AG29: =IF(AF29>MODEL_FIT!$H$1+1,"",OFFSET(MODEL_FIT!$A$6,0,MODEL_FIT!$H$1+1-ROW()+ROW($AG$4),1,1)) | AH29: =IF(AF29>MODEL_FIT!$H$1+1,"",OFFSET(MODEL_FIT!$A$7,0,MODEL_FIT!$H$1+1-ROW()+ROW($AG$4),1,1)) | AI29: =IF(AF29>MODEL_FIT!$H$1+1,"",OFFSET(MODEL_FIT!$A$5,0,MODEL_FIT!$H$1+1-ROW()+ROW($AG$4),1,1))
C31: Means x | F31: 1 | G31: =IF(G3="","",AVERAGE(MODEL_MATRIX!C2:C71)) -> 0 | H31: =IF(H3="","",AVERAGE(MODEL_MATRIX!D2:D71)) -> 0 | I31: =IF(I3="","",AVERAGE(MODEL_MATRIX!E2:E71)) -> 0 | J31: =IF(J3="","",AVERAGE(MODEL_MATRIX!F2:F71)) -> 0 | K31: =IF(K3="","",AVERAGE(MODEL_MATRIX!G2:G71)) -> 0 | L31: =IF(L3="","",AVERAGE(MODEL_MATRIX!H2:H71)) | M31: =IF(M3="","",AVERAGE(MODEL_MATRIX!I2:I71)) | N31: =IF(N3="","",AVERAGE(MODEL_MATRIX!J2:J71)) | ... AE31: =IF(AE3="","",AVERAGE(MODEL_MATRIX!AA2:AA71))
F32: =IF(F4="","",F$31) | G32: =IF(G4="","",G$31) | H32: =IF(H4="","",H$31) | I32: =IF(I4="","",I$31) | J32: =IF(J4="","",J$31) | K32: =IF(K4="","",K$31) | L32: =IF(L4="","",L$31) | M32: =IF(M4="","",M$31) | ... AE32: =IF(AE4="","",AE$31)
D33: {=MMULT((OFFSET(F4,0,0,COUNT(F4:F23),COUNT(F4:AE4))-OFFSET(F31,0,0,COUNT(F4:F23),COUNT(F4:AE4)))^2,OFFSET(AH4,0,0,COUNT(F4:AE4),1)^2)} -> #REF! | F33: =IF(F5="","",F$31) | G33: =IF(G5="","",G$31) | H33: =IF(H5="","",H$31) | I33: =IF(I5="","",I$31) | J33: =IF(J5="","",J$31) | K33: =IF(K5="","",K$31) | L33: =IF(L5="","",L$31) | M33: =IF(M5="","",M$31) | ... AE33: =IF(AE5="","",AE$31)
F34: =IF(F6="","",F$31) | G34: =IF(G6="","",G$31) | H34: =IF(H6="","",H$31) | I34: =IF(I6="","",I$31) | J34: =IF(J6="","",J$31) | K34: =IF(K6="","",K$31) | L34: =IF(L6="","",L$31) | M34: =IF(M6="","",M$31) | ... AE34: =IF(AE6="","",AE$31)
F35: =IF(F7="","",F$31) | G35: =IF(G7="","",G$31) | H35: =IF(H7="","",H$31) | I35: =IF(I7="","",I$31) | J35: =IF(J7="","",J$31) | K35: =IF(K7="","",K$31) | L35: =IF(L7="","",L$31) | M35: =IF(M7="","",M$31) | ... AE35: =IF(AE7="","",AE$31)
F36: =IF(F8="","",F$31) | G36: =IF(G8="","",G$31) | H36: =IF(H8="","",H$31) | I36: =IF(I8="","",I$31) | J36: =IF(J8="","",J$31) | K36: =IF(K8="","",K$31) | L36: =IF(L8="","",L$31) | M36: =IF(M8="","",M$31) | ... AE36: =IF(AE8="","",AE$31)
F37: =IF(F9="","",F$31) | G37: =IF(G9="","",G$31) | H37: =IF(H9="","",H$31) | I37: =IF(I9="","",I$31) | J37: =IF(J9="","",J$31) | K37: =IF(K9="","",K$31) | L37: =IF(L9="","",L$31) | M37: =IF(M9="","",M$31) | ... AE37: =IF(AE9="","",AE$31)
F38: =IF(F10="","",F$31) | G38: =IF(G10="","",G$31) | H38: =IF(H10="","",H$31) | I38: =IF(I10="","",I$31) | J38: =IF(J10="","",J$31) | K38: =IF(K10="","",K$31) | L38: =IF(L10="","",L$31) | M38: =IF(M10="","",M$31) | ... AE38: =IF(AE10="","",AE$31)
F39: =IF(F11="","",F$31) | G39: =IF(G11="","",G$31) | H39: =IF(H11="","",H$31) | I39: =IF(I11="","",I$31) | J39: =IF(J11="","",J$31) | K39: =IF(K11="","",K$31) | L39: =IF(L11="","",L$31) | M39: =IF(M11="","",M$31) | ... AE39: =IF(AE11="","",AE$31)
F40: =IF(F12="","",F$31) | G40: =IF(G12="","",G$31) | H40: =IF(H12="","",H$31) | I40: =IF(I12="","",I$31) | J40: =IF(J12="","",J$31) | K40: =IF(K12="","",K$31) | L40: =IF(L12="","",L$31) | M40: =IF(M12="","",M$31) | ... AE40: =IF(AE12="","",AE$31)
F41: =IF(F13="","",F$31) | G41: =IF(G13="","",G$31) | H41: =IF(H13="","",H$31) | I41: =IF(I13="","",I$31) | J41: =IF(J13="","",J$31) | K41: =IF(K13="","",K$31) | L41: =IF(L13="","",L$31) | M41: =IF(M13="","",M$31) | ... AE41: =IF(AE13="","",AE$31)
F42: =IF(F14="","",F$31) | G42: =IF(G14="","",G$31) | H42: =IF(H14="","",H$31) | I42: =IF(I14="","",I$31) | J42: =IF(J14="","",J$31) | K42: =IF(K14="","",K$31) | L42: =IF(L14="","",L$31) | M42: =IF(M14="","",M$31) | ... AE42: =IF(AE14="","",AE$31)
F43: =IF(F15="","",F$31) | G43: =IF(G15="","",G$31) | H43: =IF(H15="","",H$31) | I43: =IF(I15="","",I$31) | J43: =IF(J15="","",J$31) | K43: =IF(K15="","",K$31) | L43: =IF(L15="","",L$31) | M43: =IF(M15="","",M$31) | ... AE43: =IF(AE15="","",AE$31)
F44: =IF(F16="","",F$31) | G44: =IF(G16="","",G$31) | H44: =IF(H16="","",H$31) | I44: =IF(I16="","",I$31) | J44: =IF(J16="","",J$31) | K44: =IF(K16="","",K$31) | L44: =IF(L16="","",L$31) | M44: =IF(M16="","",M$31) | ... AE44: =IF(AE16="","",AE$31)
F45: =IF(F17="","",F$31) | G45: =IF(G17="","",G$31) | H45: =IF(H17="","",H$31) | I45: =IF(I17="","",I$31) | J45: =IF(J17="","",J$31) | K45: =IF(K17="","",K$31) | L45: =IF(L17="","",L$31) | M45: =IF(M17="","",M$31) | ... AE45: =IF(AE17="","",AE$31)
...

Sheet CENTER_POINTS
C1: alpha | D1: 0.05 | E1: k | F1: =_xlfn.T.INV(1-D1/2,AR7) -> 2.0555294
B3: Y | C3: Ypred | D3: S_Ypred | E3: CI_lwr | F3: CI_upr | G3: PI_lwr | H3: PI_upr | I3: I | J3: =MODEL_MATRIX!C1 -> A | K3: =MODEL_MATRIX!D1 -> C | L3: =MODEL_MATRIX!E1 -> E | M3: =MODEL_MATRIX!F1 -> AC | N3: =MODEL_MATRIX!G1 -> AE | O3: =MODEL_MATRIX!H1 | P3: =MODEL_MATRIX!I1 | Q3: =MODEL_MATRIX!J1 | ... AH3: =MODEL_MATRIX!AA1 | AJ3: i | AK3: Y | AN3: b | AO3: S_b | AQ3: S_res
A4: 1 | C4: {=IF(J4="","",MMULT(OFFSET(I4,0,0,COUNT(I4:I23),COUNT(I4:AH4)),OFFSET(AN4,0,0,COUNT(I4:AH4),1)))} | D4: {=IF(J4="","",(MMULT((OFFSET(I4,0,0,COUNT(I4:I23),COUNT(I4:AH4))-OFFSET(G35,0,0,COUNT(I4:I23),COUNT(I4:AH4)))^2,OFFSET(AO4,0,0,COUNT(I4:AH4),1)^2)+$AQ$4^2/$AQ$7)^0.5)} | E4: =IF(C4="","",C4-D4*$F$1) | F4: =IF(C4="","",C4+D4*$F$1) | G4: =IF(C4="","",C4-(D4^2+$AQ$4^2)^0.5*$F$1) | H4: =IF(C4="","",C4+(D4^2+$AQ$4^2)^0.5*$F$1) | I4: =IF(J4="","",1) | AJ4: =IF($B4="",NA(),A4) -> #N/A | AK4: =IF($B4="",NA(),B4) -> #N/A | AM4: 1 | AN4: =IF(AM4>MODEL_FIT!$H$1+1,"",OFFSET(MODEL_FIT!$A$6,0,MODEL_FIT!$H$1+1-ROW()+ROW($AN$4),1,1)) -> 5.988929 | AO4: =IF(AM4>MODEL_FIT!$H$1+1,"",OFFSET(MODEL_FIT!$A$7,0,MODEL_FIT!$H$1+1-ROW()+ROW($AN$4),1,1)) -> 0.13615377 | AP4: =IF(AM4>MODEL_FIT!$H$1+1,"",OFFSET(MODEL_FIT!$A$5,0,MODEL_FIT!$H$1+1-ROW()+ROW($AN$4),1,1)) -> Intercept | AQ4: =MODEL_FIT!C8 -> 0.77020203 | AR4: =SQRT(AQ4^2/AQ7) -> 0.13615377
A5: 2 | E5: =IF(C5="","",C5-D5*$F$1) | F5: =IF(C5="","",C5+D5*$F$1) | G5: =IF(C5="","",C5-(D5^2+$AQ$4^2)^0.5*$F$1) | H5: =IF(C5="","",C5+(D5^2+$AQ$4^2)^0.5*$F$1) | I5: =IF(OR(I$3="",$B5=""),"",I4) | J5: =IF(OR(J$3="",$B5=""),"",J4) | K5: =IF(OR(K$3="",$B5=""),"",K4) | L5: =IF(OR(L$3="",$B5=""),"",L4) | M5: =IF(OR(M$3="",$B5=""),"",M4) | N5: =IF(OR(N$3="",$B5=""),"",N4) | O5: =IF(OR(O$3="",$B5=""),"",O4) | P5: =IF(OR(P$3="",$B5=""),"",P4) | ... AH5: =IF(OR(AH$3="",$B5=""),"",AH4) | AJ5: =IF($B5="",NA(),A5) -> #N/A | AK5: =IF($B5="",NA(),B5) -> #N/A | AM5: 2 | AN5: =IF(AM5>MODEL_FIT!$H$1+1,"",OFFSET(MODEL_FIT!$A$6,0,MODEL_FIT!$H$1+1-ROW()+ROW($AN$4),1,1)) -> -0.47624316 | AO5: =IF(AM5>MODEL_FIT!$H$1+1,"",OFFSET(MODEL_FIT!$A$7,0,MODEL_FIT!$H$1+1-ROW()+ROW($AN$4),1,1)) -> 0.13615377 | AP5: =IF(AM5>MODEL_FIT!$H$1+1,"",OFFSET(MODEL_FIT!$A$5,0,MODEL_FIT!$H$1+1-ROW()+ROW($AN$4),1,1)) -> A
A6: 3 | E6: =IF(C6="","",C6-D6*$F$1) | F6: =IF(C6="","",C6+D6*$F$1) | G6: =IF(C6="","",C6-(D6^2+$AQ$4^2)^0.5*$F$1) | H6: =IF(C6="","",C6+(D6^2+$AQ$4^2)^0.5*$F$1) | I6: =IF(OR(I$3="",$B6=""),"",I5) | J6: =IF(OR(J$3="",$B6=""),"",J5) | K6: =IF(OR(K$3="",$B6=""),"",K5) | L6: =IF(OR(L$3="",$B6=""),"",L5) | M6: =IF(OR(M$3="",$B6=""),"",M5) | N6: =IF(OR(N$3="",$B6=""),"",N5) | O6: =IF(OR(O$3="",$B6=""),"",O5) | P6: =IF(OR(P$3="",$B6=""),"",P5) | ... AH6: =IF(OR(AH$3="",$B6=""),"",AH5) | AJ6: =IF($B6="",NA(),A6) -> #N/A | AK6: =IF($B6="",NA(),B6) -> #N/A | AM6: 3 | AN6: =IF(AM6>MODEL_FIT!$H$1+1,"",OFFSET(MODEL_FIT!$A$6,0,MODEL_FIT!$H$1+1-ROW()+ROW($AN$4),1,1)) -> 1.0836925 | AO6: =IF(AM6>MODEL_FIT!$H$1+1,"",OFFSET(MODEL_FIT!$A$7,0,MODEL_FIT!$H$1+1-ROW()+ROW($AN$4),1,1)) -> 0.13615377 | AP6: =IF(AM6>MODEL_FIT!$H$1+1,"",OFFSET(MODEL_FIT!$A$5,0,MODEL_FIT!$H$1+1-ROW()+ROW($AN$4),1,1)) -> C | AQ6: n | AR6: gl
A7: 4 | E7: =IF(C7="","",C7-D7*$F$1) | F7: =IF(C7="","",C7+D7*$F$1) | G7: =IF(C7="","",C7-(D7^2+$AQ$4^2)^0.5*$F$1) | H7: =IF(C7="","",C7+(D7^2+$AQ$4^2)^0.5*$F$1) | I7: =IF(OR(I$3="",$B7=""),"",I6) | J7: =IF(OR(J$3="",$B7=""),"",J6) | K7: =IF(OR(K$3="",$B7=""),"",K6) | L7: =IF(OR(L$3="",$B7=""),"",L6) | M7: =IF(OR(M$3="",$B7=""),"",M6) | N7: =IF(OR(N$3="",$B7=""),"",N6) | O7: =IF(OR(O$3="",$B7=""),"",O6) | P7: =IF(OR(P$3="",$B7=""),"",P6) | ... AH7: =IF(OR(AH$3="",$B7=""),"",AH6) | AJ7: =IF($B7="",NA(),A7) -> #N/A | AK7: =IF($B7="",NA(),B7) -> #N/A | AM7: 4 | AN7: =IF(AM7>MODEL_FIT!$H$1+1,"",OFFSET(MODEL_FIT!$A$6,0,MODEL_FIT!$H$1+1-ROW()+ROW($AN$4),1,1)) -> 0.46799015 | AO7: =IF(AM7>MODEL_FIT!$H$1+1,"",OFFSET(MODEL_FIT!$A$7,0,MODEL_FIT!$H$1+1-ROW()+ROW($AN$4),1,1)) -> 0.13615377 | AP7: =IF(AM7>MODEL_FIT!$H$1+1,"",OFFSET(MODEL_FIT!$A$5,0,MODEL_FIT!$H$1+1-ROW()+ROW($AN$4),1,1)) -> E | AQ7: =DESIGN_FEATURES!E1 -> 32 | AR7: =MODEL_FIT!C9 -> 26
A8: 5 | E8: =IF(C8="","",C8-D8*$F$1) | F8: =IF(C8="","",C8+D8*$F$1) | I8: =IF(OR(I$3="",$B8=""),"",I7) | J8: =IF(OR(J$3="",$B8=""),"",J7) | K8: =IF(OR(K$3="",$B8=""),"",K7) | L8: =IF(OR(L$3="",$B8=""),"",L7) | M8: =IF(OR(M$3="",$B8=""),"",M7) | N8: =IF(OR(N$3="",$B8=""),"",N7) | O8: =IF(OR(O$3="",$B8=""),"",O7) | P8: =IF(OR(P$3="",$B8=""),"",P7) | ... AH8: =IF(OR(AH$3="",$B8=""),"",AH7) | AJ8: =IF($B8="",NA(),A8) -> #N/A | AK8: =IF($B8="",NA(),B8) -> #N/A | AM8: 5 | AN8: =IF(AM8>MODEL_FIT!$H$1+1,"",OFFSET(MODEL_FIT!$A$6,0,MODEL_FIT!$H$1+1-ROW()+ROW($AN$4),1,1)) -> -0.35986405 | AO8: =IF(AM8>MODEL_FIT!$H$1+1,"",OFFSET(MODEL_FIT!$A$7,0,MODEL_FIT!$H$1+1-ROW()+ROW($AN$4),1,1)) -> 0.13615377 | AP8: =IF(AM8>MODEL_FIT!$H$1+1,"",OFFSET(MODEL_FIT!$A$5,0,MODEL_FIT!$H$1+1-ROW()+ROW($AN$4),1,1)) -> AC
A9: 6 | E9: =IF(C9="","",C9-D9*$F$1) | F9: =IF(C9="","",C9+D9*$F$1) | I9: =IF(OR(I$3="",$B9=""),"",I8) | J9: =IF(OR(J$3="",$B9=""),"",J8) | K9: =IF(OR(K$3="",$B9=""),"",K8) | L9: =IF(OR(L$3="",$B9=""),"",L8) | M9: =IF(OR(M$3="",$B9=""),"",M8) | N9: =IF(OR(N$3="",$B9=""),"",N8) | O9: =IF(OR(O$3="",$B9=""),"",O8) | P9: =IF(OR(P$3="",$B9=""),"",P8) | ... AH9: =IF(OR(AH$3="",$B9=""),"",AH8) | AJ9: =IF($B9="",NA(),A9) -> #N/A | AK9: =IF($B9="",NA(),B9) -> #N/A | AM9: 6 | AN9: =IF(AM9>MODEL_FIT!$H$1+1,"",OFFSET(MODEL_FIT!$A$6,0,MODEL_FIT!$H$1+1-ROW()+ROW($AN$4),1,1)) -> 0.41883355 | AO9: =IF(AM9>MODEL_FIT!$H$1+1,"",OFFSET(MODEL_FIT!$A$7,0,MODEL_FIT!$H$1+1-ROW()+ROW($AN$4),1,1)) -> 0.13615377 | AP9: =IF(AM9>MODEL_FIT!$H$1+1,"",OFFSET(MODEL_FIT!$A$5,0,MODEL_FIT!$H$1+1-ROW()+ROW($AN$4),1,1)) -> AE
A10: 7 | E10: =IF(C10="","",C10-D10*$F$1) | F10: =IF(C10="","",C10+D10*$F$1) | I10: =IF(OR(I$3="",$B10=""),"",I9) | J10: =IF(OR(J$3="",$B10=""),"",J9) | K10: =IF(OR(K$3="",$B10=""),"",K9) | L10: =IF(OR(L$3="",$B10=""),"",L9) | M10: =IF(OR(M$3="",$B10=""),"",M9) | N10: =IF(OR(N$3="",$B10=""),"",N9) | O10: =IF(OR(O$3="",$B10=""),"",O9) | P10: =IF(OR(P$3="",$B10=""),"",P9) | ... AH10: =IF(OR(AH$3="",$B10=""),"",AH9) | AJ10: =IF($B10="",NA(),A10) -> #N/A | AK10: =IF($B10="",NA(),B10) -> #N/A | AM10: 7 | AN10: =IF(AM10>MODEL_FIT!$H$1+1,"",OFFSET(MODEL_FIT!$A$6,0,MODEL_FIT!$H$1+1-ROW()+ROW($AN$4),1,1)) | AO10: =IF(AM10>MODEL_FIT!$H$1+1,"",OFFSET(MODEL_FIT!$A$7,0,MODEL_FIT!$H$1+1-ROW()+ROW($AN$4),1,1)) | AP10: =IF(AM10>MODEL_FIT!$H$1+1,"",OFFSET(MODEL_FIT!$A$5,0,MODEL_FIT!$H$1+1-ROW()+ROW($AN$4),1,1))
A11: 8 | E11: =IF(C11="","",C11-D11*$F$1) | F11: =IF(C11="","",C11+D11*$F$1) | I11: =IF(OR(I$3="",$B11=""),"",I10) | J11: =IF(OR(J$3="",$B11=""),"",J10) | K11: =IF(OR(K$3="",$B11=""),"",K10) | L11: =IF(OR(L$3="",$B11=""),"",L10) | M11: =IF(OR(M$3="",$B11=""),"",M10) | N11: =IF(OR(N$3="",$B11=""),"",N10) | O11: =IF(OR(O$3="",$B11=""),"",O10) | P11: =IF(OR(P$3="",$B11=""),"",P10) | ... AH11: =IF(OR(AH$3="",$B11=""),"",AH10) | AJ11: =IF($B11="",NA(),A11) -> #N/A | AK11: =IF($B11="",NA(),B11) -> #N/A | AM11: 8 | AN11: =IF(AM11>MODEL_FIT!$H$1+1,"",OFFSET(MODEL_FIT!$A$6,0,MODEL_FIT!$H$1+1-ROW()+ROW($AN$4),1,1)) | AO11: =IF(AM11>MODEL_FIT!$H$1+1,"",OFFSET(MODEL_FIT!$A$7,0,MODEL_FIT!$H$1+1-ROW()+ROW($AN$4),1,1)) | AP11: =IF(AM11>MODEL_FIT!$H$1+1,"",OFFSET(MODEL_FIT!$A$5,0,MODEL_FIT!$H$1+1-ROW()+ROW($AN$4),1,1))
A12: 9 | E12: =IF(C12="","",C12-D12*$F$1) | F12: =IF(C12="","",C12+D12*$F$1) | I12: =IF(OR(I$3="",$B12=""),"",I11) | J12: =IF(OR(J$3="",$B12=""),"",J11) | K12: =IF(OR(K$3="",$B12=""),"",K11) | L12: =IF(OR(L$3="",$B12=""),"",L11) | M12: =IF(OR(M$3="",$B12=""),"",M11) | N12: =IF(OR(N$3="",$B12=""),"",N11) | O12: =IF(OR(O$3="",$B12=""),"",O11) | P12: =IF(OR(P$3="",$B12=""),"",P11) | ... AH12: =IF(OR(AH$3="",$B12=""),"",AH11) | AJ12: =IF($B12="",NA(),A12) -> #N/A | AK12: =IF($B12="",NA(),B12) -> #N/A | AM12: 9 | AN12: =IF(AM12>MODEL_FIT!$H$1+1,"",OFFSET(MODEL_FIT!$A$6,0,MODEL_FIT!$H$1+1-ROW()+ROW($AN$4),1,1)) | AO12: =IF(AM12>MODEL_FIT!$H$1+1,"",OFFSET(MODEL_FIT!$A$7,0,MODEL_FIT!$H$1+1-ROW()+ROW($AN$4),1,1)) | AP12: =IF(AM12>MODEL_FIT!$H$1+1,"",OFFSET(MODEL_FIT!$A$5,0,MODEL_FIT!$H$1+1-ROW()+ROW($AN$4),1,1))
A13: 10 | E13: =IF(C13="","",C13-D13*$F$1) | F13: =IF(C13="","",C13+D13*$F$1) | I13: =IF(OR(I$3="",$B13=""),"",I12) | J13: =IF(OR(J$3="",$B13=""),"",J12) | K13: =IF(OR(K$3="",$B13=""),"",K12) | L13: =IF(OR(L$3="",$B13=""),"",L12) | M13: =IF(OR(M$3="",$B13=""),"",M12) | N13: =IF(OR(N$3="",$B13=""),"",N12) | O13: =IF(OR(O$3="",$B13=""),"",O12) | P13: =IF(OR(P$3="",$B13=""),"",P12) | ... AH13: =IF(OR(AH$3="",$B13=""),"",AH12) | AJ13: =IF($B13="",NA(),A13) -> #N/A | AK13: =IF($B13="",NA(),B13) -> #N/A | AM13: 10 | AN13: =IF(AM13>MODEL_FIT!$H$1+1,"",OFFSET(MODEL_FIT!$A$6,0,MODEL_FIT!$H$1+1-ROW()+ROW($AN$4),1,1)) | AO13: =IF(AM13>MODEL_FIT!$H$1+1,"",OFFSET(MODEL_FIT!$A$7,0,MODEL_FIT!$H$1+1-ROW()+ROW($AN$4),1,1)) | AP13: =IF(AM13>MODEL_FIT!$H$1+1,"",OFFSET(MODEL_FIT!$A$5,0,MODEL_FIT!$H$1+1-ROW()+ROW($AN$4),1,1))
A14: 11 | E14: =IF(C14="","",C14-D14*$F$1) | F14: =IF(C14="","",C14+D14*$F$1) | I14: =IF(OR(I$3="",$B14=""),"",I13) | J14: =IF(OR(J$3="",$B14=""),"",J13) | K14: =IF(OR(K$3="",$B14=""),"",K13) | L14: =IF(OR(L$3="",$B14=""),"",L13) | M14: =IF(OR(M$3="",$B14=""),"",M13) | N14: =IF(OR(N$3="",$B14=""),"",N13) | O14: =IF(OR(O$3="",$B14=""),"",O13) | P14: =IF(OR(P$3="",$B14=""),"",P13) | ... AH14: =IF(OR(AH$3="",$B14=""),"",AH13) | AJ14: =IF($B14="",NA(),A14) -> #N/A | AK14: =IF($B14="",NA(),B14) -> #N/A | AM14: 11 | AN14: =IF(AM14>MODEL_FIT!$H$1+1,"",OFFSET(MODEL_FIT!$A$6,0,MODEL_FIT!$H$1+1-ROW()+ROW($AN$4),1,1)) | AO14: =IF(AM14>MODEL_FIT!$H$1+1,"",OFFSET(MODEL_FIT!$A$7,0,MODEL_FIT!$H$1+1-ROW()+ROW($AN$4),1,1)) | AP14: =IF(AM14>MODEL_FIT!$H$1+1,"",OFFSET(MODEL_FIT!$A$5,0,MODEL_FIT!$H$1+1-ROW()+ROW($AN$4),1,1))
A15: 12 | E15: =IF(C15="","",C15-D15*$F$1) | F15: =IF(C15="","",C15+D15*$F$1) | I15: =IF(OR(I$3="",$B15=""),"",I14) | J15: =IF(OR(J$3="",$B15=""),"",J14) | K15: =IF(OR(K$3="",$B15=""),"",K14) | L15: =IF(OR(L$3="",$B15=""),"",L14) | M15: =IF(OR(M$3="",$B15=""),"",M14) | N15: =IF(OR(N$3="",$B15=""),"",N14) | O15: =IF(OR(O$3="",$B15=""),"",O14) | P15: =IF(OR(P$3="",$B15=""),"",P14) | ... AH15: =IF(OR(AH$3="",$B15=""),"",AH14) | AJ15: =IF($B15="",NA(),A15) -> #N/A | AK15: =IF($B15="",NA(),B15) -> #N/A | AM15: 12 | AN15: =IF(AM15>MODEL_FIT!$H$1+1,"",OFFSET(MODEL_FIT!$A$6,0,MODEL_FIT!$H$1+1-ROW()+ROW($AN$4),1,1)) | AO15: =IF(AM15>MODEL_FIT!$H$1+1,"",OFFSET(MODEL_FIT!$A$7,0,MODEL_FIT!$H$1+1-ROW()+ROW($AN$4),1,1)) | AP15: =IF(AM15>MODEL_FIT!$H$1+1,"",OFFSET(MODEL_FIT!$A$5,0,MODEL_FIT!$H$1+1-ROW()+ROW($AN$4),1,1))
A16: 13 | E16: =IF(C16="","",C16-D16*$F$1) | F16: =IF(C16="","",C16+D16*$F$1) | I16: =IF(OR(I$3="",$B16=""),"",I15) | J16: =IF(OR(J$3="",$B16=""),"",J15) | K16: =IF(OR(K$3="",$B16=""),"",K15) | L16: =IF(OR(L$3="",$B16=""),"",L15) | M16: =IF(OR(M$3="",$B16=""),"",M15) | N16: =IF(OR(N$3="",$B16=""),"",N15) | O16: =IF(OR(O$3="",$B16=""),"",O15) | P16: =IF(OR(P$3="",$B16=""),"",P15) | ... AH16: =IF(OR(AH$3="",$B16=""),"",AH15) | AJ16: =IF($B16="",NA(),A16) -> #N/A | AK16: =IF($B16="",NA(),B16) -> #N/A | AM16: 13 | AN16: =IF(AM16>MODEL_FIT!$H$1+1,"",OFFSET(MODEL_FIT!$A$6,0,MODEL_FIT!$H$1+1-ROW()+ROW($AN$4),1,1)) | AO16: =IF(AM16>MODEL_FIT!$H$1+1,"",OFFSET(MODEL_FIT!$A$7,0,MODEL_FIT!$H$1+1-ROW()+ROW($AN$4),1,1)) | AP16: =IF(AM16>MODEL_FIT!$H$1+1,"",OFFSET(MODEL_FIT!$A$5,0,MODEL_FIT!$H$1+1-ROW()+ROW($AN$4),1,1))
A17: 14 | E17: =IF(C17="","",C17-D17*$F$1) | F17: =IF(C17="","",C17+D17*$F$1) | I17: =IF(OR(I$3="",$B17=""),"",I16) | J17: =IF(OR(J$3="",$B17=""),"",J16) | K17: =IF(OR(K$3="",$B17=""),"",K16) | L17: =IF(OR(L$3="",$B17=""),"",L16) | M17: =IF(OR(M$3="",$B17=""),"",M16) | N17: =IF(OR(N$3="",$B17=""),"",N16) | O17: =IF(OR(O$3="",$B17=""),"",O16) | P17: =IF(OR(P$3="",$B17=""),"",P16) | ... AH17: =IF(OR(AH$3="",$B17=""),"",AH16) | AJ17: =IF($B17="",NA(),A17) -> #N/A | AK17: =IF($B17="",NA(),B17) -> #N/A | AM17: 14 | AN17: =IF(AM17>MODEL_FIT!$H$1+1,"",OFFSET(MODEL_FIT!$A$6,0,MODEL_FIT!$H$1+1-ROW()+ROW($AN$4),1,1)) | AO17: =IF(AM17>MODEL_FIT!$H$1+1,"",OFFSET(MODEL_FIT!$A$7,0,MODEL_FIT!$H$1+1-ROW()+ROW($AN$4),1,1)) | AP17: =IF(AM17>MODEL_FIT!$H$1+1,"",OFFSET(MODEL_FIT!$A$5,0,MODEL_FIT!$H$1+1-ROW()+ROW($AN$4),1,1))
A18: 15 | E18: =IF(C18="","",C18-D18*$F$1) | F18: =IF(C18="","",C18+D18*$F$1) | I18: =IF(OR(I$3="",$B18=""),"",I17) | J18: =IF(OR(J$3="",$B18=""),"",J17) | K18: =IF(OR(K$3="",$B18=""),"",K17) | L18: =IF(OR(L$3="",$B18=""),"",L17) | M18: =IF(OR(M$3="",$B18=""),"",M17) | N18: =IF(OR(N$3="",$B18=""),"",N17) | O18: =IF(OR(O$3="",$B18=""),"",O17) | P18: =IF(OR(P$3="",$B18=""),"",P17) | ... AH18: =IF(OR(AH$3="",$B18=""),"",AH17) | AJ18: =IF($B18="",NA(),A18) -> #N/A | AK18: =IF($B18="",NA(),B18) -> #N/A | AM18: 15 | AN18: =IF(AM18>MODEL_FIT!$H$1+1,"",OFFSET(MODEL_FIT!$A$6,0,MODEL_FIT!$H$1+1-ROW()+ROW($AN$4),1,1)) | AO18: =IF(AM18>MODEL_FIT!$H$1+1,"",OFFSET(MODEL_FIT!$A$7,0,MODEL_FIT!$H$1+1-ROW()+ROW($AN$4),1,1)) | AP18: =IF(AM18>MODEL_FIT!$H$1+1,"",OFFSET(MODEL_FIT!$A$5,0,MODEL_FIT!$H$1+1-ROW()+ROW($AN$4),1,1))
A19: 16 | E19: =IF(C19="","",C19-D19*$F$1) | F19: =IF(C19="","",C19+D19*$F$1) | I19: =IF(OR(I$3="",$B19=""),"",I18) | J19: =IF(OR(J$3="",$B19=""),"",J18) | K19: =IF(OR(K$3="",$B19=""),"",K18) | L19: =IF(OR(L$3="",$B19=""),"",L18) | M19: =IF(OR(M$3="",$B19=""),"",M18) | N19: =IF(OR(N$3="",$B19=""),"",N18) | O19: =IF(OR(O$3="",$B19=""),"",O18) | P19: =IF(OR(P$3="",$B19=""),"",P18) | ... AH19: =IF(OR(AH$3="",$B19=""),"",AH18) | AJ19: =IF($B19="",NA(),A19) -> #N/A | AK19: =IF($B19="",NA(),B19) -> #N/A | AM19: 16 | AN19: =IF(AM19>MODEL_FIT!$H$1+1,"",OFFSET(MODEL_FIT!$A$6,0,MODEL_FIT!$H$1+1-ROW()+ROW($AN$4),1,1)) | AO19: =IF(AM19>MODEL_FIT!$H$1+1,"",OFFSET(MODEL_FIT!$A$7,0,MODEL_FIT!$H$1+1-ROW()+ROW($AN$4),1,1)) | AP19: =IF(AM19>MODEL_FIT!$H$1+1,"",OFFSET(MODEL_FIT!$A$5,0,MODEL_FIT!$H$1+1-ROW()+ROW($AN$4),1,1))
... A23: 20 | E23: =IF(C23="","",C23-D23*$F$1) | F23: =IF(C23="","",C23+D23*$F$1) | I23: =IF(OR(I$3="",$B23=""),"",I22) | J23: =IF(OR(J$3="",$B23=""),"",J22) | K23: =IF(OR(K$3="",$B23=""),"",K22) | L23: =IF(OR(L$3="",$B23=""),"",L22) | M23: =IF(OR(M$3="",$B23=""),"",M22) | N23: =IF(OR(N$3="",$B23=""),"",N22) | O23: =IF(OR(O$3="",$B23=""),"",O22) | P23: =IF(OR(P$3="",$B23=""),"",P22) | ... AH23: =IF(OR(AH$3="",$B23=""),"",AH22) | AJ23: =IF($B23="",NA(),A23) -> #N/A | AK23: =IF($B23="",NA(),B23) -> #N/A | AM23: 20 | AN23: =IF(AM23>MODEL_FIT!$H$1+1,"",OFFSET(MODEL_FIT!$A$6,0,MODEL_FIT!$H$1+1-ROW()+ROW($AN$4),1,1)) | AO23: =IF(AM23>MODEL_FIT!$H$1+1,"",OFFSET(MODEL_FIT!$A$7,0,MODEL_FIT!$H$1+1-ROW()+ROW($AN$4),1,1)) | AP23: =IF(AM23>MODEL_FIT!$H$1+1,"",OFFSET(MODEL_FIT!$A$5,0,MODEL_FIT!$H$1+1-ROW()+ROW($AN$4),1,1))
AM24: 21 | AN24: =IF(AM24>MODEL_FIT!$H$1+1,"",OFFSET(MODEL_FIT!$A$6,0,MODEL_FIT!$H$1+1-ROW()+ROW($AN$4),1,1)) | AO24: =IF(AM24>MODEL_FIT!$H$1+1,"",OFFSET(MODEL_FIT!$A$7,0,MODEL_FIT!$H$1+1-ROW()+ROW($AN$4),1,1)) | AP24: =IF(AM24>MODEL_FIT!$H$1+1,"",OFFSET(MODEL_FIT!$A$5,0,MODEL_FIT!$H$1+1-ROW()+ROW($AN$4),1,1))
B25: Av(Y) | C25: SE_Av | E25: Ypred | F25: SDYpred | G25: CI Ypred | K25: Slope | L25: S_slope | M25: CI_lwr | N25: CI_upr | AM25: 22 | AN25: =IF(AM25>MODEL_FIT!$H$1+1,"",OFFSET(MODEL_FIT!$A$6,0,MODEL_FIT!$H$1+1-ROW()+ROW($AN$4),1,1)) | AO25: =IF(AM25>MODEL_FIT!$H$1+1,"",OFFSET(MODEL_FIT!$A$7,0,MODEL_FIT!$H$1+1-ROW()+ROW($AN$4),1,1)) | AP25: =IF(AM25>MODEL_FIT!$H$1+1,"",OFFSET(MODEL_FIT!$A$5,0,MODEL_FIT!$H$1+1-ROW()+ROW($AN$4),1,1))
B26: =AVERAGE(B4:B23) -> #DIV/0! | C26: =STDEV(B4:B23)/SQRT(COUNT(B4:B23)) -> #DIV/0! | E26: =C4 | F26: =D4 | G26: =E4 | H26: =F4 | K26: =G58 -> #REF! | L26: =G59 -> 0 | M26: =IF(K26="","",K26-L26*$F$1) -> #REF! | N26: =IF(K26="","",K26+L26*$F$1) -> #REF! | AM26: 23 | AN26: =IF(AM26>MODEL_FIT!$H$1+1,"",OFFSET(MODEL_FIT!$A$6,0,MODEL_FIT!$H$1+1-ROW()+ROW($AN$4),1,1)) | AO26: =IF(AM26>MODEL_FIT!$H$1+1,"",OFFSET(MODEL_FIT!$A$7,0,MODEL_FIT!$H$1+1-ROW()+ROW($AN$4),1,1)) | AP26: =IF(AM26>MODEL_FIT!$H$1+1,"",OFFSET(MODEL_FIT!$A$5,0,MODEL_FIT!$H$1+1-ROW()+ROW($AN$4),1,1))
AM27: 24 | AN27: =IF(AM27>MODEL_FIT!$H$1+1,"",OFFSET(MODEL_FIT!$A$6,0,MODEL_FIT!$H$1+1-ROW()+ROW($AN$4),1,1)) | AO27: =IF(AM27>MODEL_FIT!$H$1+1,"",OFFSET(MODEL_FIT!$A$7,0,MODEL_FIT!$H$1+1-ROW()+ROW($AN$4),1,1)) | AP27: =IF(AM27>MODEL_FIT!$H$1+1,"",OFFSET(MODEL_FIT!$A$5,0,MODEL_FIT!$H$1+1-ROW()+ROW($AN$4),1,1))
A28: Enter the center or pseudo-center points in the yellow cells (outcome and model components). Include the interactions if needed. (1) Average of experimental outcomes shall be within the CI obtained for the model. (2) Outcomes should not follow any trend. (3) If so, standard deviation of the outcomes provide an estimate for the error of the data. | AM28: 25 | AN28: =IF(AM28>MODEL_FIT!$H$1+1,"",OFFSET(MODEL_FIT!$A$6,0,MODEL_FIT!$H$1+1-ROW()+ROW($AN$4),1,1)) | AO28: =IF(AM28>MODEL_FIT!$H$1+1,"",OFFSET(MODEL_FIT!$A$7,0,MODEL_FIT!$H$1+1-ROW()+ROW($AN$4),1,1)) | AP28: =IF(AM28>MODEL_FIT!$H$1+1,"",OFFSET(MODEL_FIT!$A$5,0,MODEL_FIT!$H$1+1-ROW()+ROW($AN$4),1,1))
AM29: 26 | AN29: =IF(AM29>MODEL_FIT!$H$1+1,"",OFFSET(MODEL_FIT!$A$6,0,MODEL_FIT!$H$1+1-ROW()+ROW($AN$4),1,1)) | AO29: =IF(AM29>MODEL_FIT!$H$1+1,"",OFFSET(MODEL_FIT!$A$7,0,MODEL_FIT!$H$1+1-ROW()+ROW($AN$4),1,1)) | AP29: =IF(AM29>MODEL_FIT!$H$1+1,"",OFFSET(MODEL_FIT!$A$5,0,MODEL_FIT!$H$1+1-ROW()+ROW($AN$4),1,1))
D35: Means x | G35: 1 | H35: =IF(J3="","",AVERAGE(EXP_MATRIX!C2:C71)) -> 0 | I35: =IF(K3="","",AVERAGE(EXP_MATRIX!D2:D71)) -> 0 | J35: =IF(L3="","",AVERAGE(EXP_MATRIX!E2:E71)) -> 0 | K35: =IF(M3="","",AVERAGE(EXP_MATRIX!F2:F71)) -> 0 | L35: =IF(N3="","",AVERAGE(EXP_MATRIX!G2:G71)) -> 0 | M35: =IF(O3="","",AVERAGE(EXP_MATRIX!H2:H71)) | N35: =IF(P3="","",AVERAGE(EXP_MATRIX!I2:I71)) | O35: =IF(Q3="","",AVERAGE(EXP_MATRIX!J2:J71)) | ... AF35: =IF(AH3="","",AVERAGE(EXP_MATRIX!AA2:AA71))
G36: =IF(I4="","",G$35) | H36: =IF(J4="","",H$35) | I36: =IF(K4="","",I$35) | J36: =IF(L4="","",J$35) | K36: =IF(M4="","",K$35) | L36: =IF(N4="","",L$35) | M36: =IF(O4="","",M$35) | N36: =IF(P4="","",N$35) | ... AF36: =IF(AH4="","",AF$35)
E37: {=MMULT((OFFSET(I4,0,0,COUNT(I4:I23),COUNT(I4:AH4))-OFFSET(G35,0,0,COUNT(I4:I23),COUNT(I4:AH4)))^2,OFFSET(AO4,0,0,COUNT(I4:AH4),1)^2)} -> #REF! | G37: =IF(I5="","",G$35) | H37: =IF(J5="","",H$35) | I37: =IF(K5="","",I$35) | J37: =IF(L5="","",J$35) | K37: =IF(M5="","",K$35) | L37: =IF(N5="","",L$35) | M37: =IF(O5="","",M$35) | N37: =IF(P5="","",N$35) | ... AF37: =IF(AH5="","",AF$35)
G38: =IF(I6="","",G$35) | H38: =IF(J6="","",H$35) | I38: =IF(K6="","",I$35) | J38: =IF(L6="","",J$35) | K38: =IF(M6="","",K$35) | L38: =IF(N6="","",L$35) | M38: =IF(O6="","",M$35) | N38: =IF(P6="","",N$35) | ... AF38: =IF(AH6="","",AF$35)
G39: =IF(I7="","",G$35) | H39: =IF(J7="","",H$35) | I39: =IF(K7="","",I$35) | J39: =IF(L7="","",J$35) | K39: =IF(M7="","",K$35) | L39: =IF(N7="","",L$35) | M39: =IF(O7="","",M$35) | N39: =IF(P7="","",N$35) | ... AF39: =IF(AH7="","",AF$35)
G40: =IF(I8="","",G$35) | H40: =IF(J8="","",H$35) | I40: =IF(K8="","",I$35) | J40: =IF(L8="","",J$35) | K40: =IF(M8="","",K$35) | L40: =IF(N8="","",L$35) | M40: =IF(O8="","",M$35) | N40: =IF(P8="","",N$35) | ... AF40: =IF(AH8="","",AF$35)
G41: =IF(I9="","",G$35) | H41: =IF(J9="","",H$35) | I41: =IF(K9="","",I$35) | J41: =IF(L9="","",J$35) | K41: =IF(M9="","",K$35) | L41: =IF(N9="","",L$35) | M41: =IF(O9="","",M$35) | N41: =IF(P9="","",N$35) | ... AF41: =IF(AH9="","",AF$35)
G42: =IF(I10="","",G$35) | H42: =IF(J10="","",H$35) | I42: =IF(K10="","",I$35) | J42: =IF(L10="","",J$35) | K42: =IF(M10="","",K$35) | L42: =IF(N10="","",L$35) | M42: =IF(O10="","",M$35) | N42: =IF(P10="","",N$35) | ... AF42: =IF(AH10="","",AF$35)
G43: =IF(I11="","",G$35) | H43: =IF(J11="","",H$35) | I43: =IF(K11="","",I$35) | J43: =IF(L11="","",J$35) | K43: =IF(M11="","",K$35) | L43: =IF(N11="","",L$35) | M43: =IF(O11="","",M$35) | N43: =IF(P11="","",N$35) | ... AF43: =IF(AH11="","",AF$35)
G44: =IF(I12="","",G$35) | H44: =IF(J12="","",H$35) | I44: =IF(K12="","",I$35) | J44: =IF(L12="","",J$35) | K44: =IF(M12="","",K$35) | L44: =IF(N12="","",L$35) | M44: =IF(O12="","",M$35) | N44: =IF(P12="","",N$35) | ... AF44: =IF(AH12="","",AF$35)
G45: =IF(I13="","",G$35) | H45: =IF(J13="","",H$35) | I45: =IF(K13="","",I$35) | J45: =IF(L13="","",J$35) | K45: =IF(M13="","",K$35) | L45: =IF(N13="","",L$35) | M45: =IF(O13="","",M$35) | N45: =IF(P13="","",N$35) | ... AF45: =IF(AH13="","",AF$35)
G46: =IF(I14="","",G$35) | H46: =IF(J14="","",H$35) | I46: =IF(K14="","",I$35) | J46: =IF(L14="","",J$35) | K46: =IF(M14="","",K$35) | L46: =IF(N14="","",L$35) | M46: =IF(O14="","",M$35) | N46: =IF(P14="","",N$35) | ... AF46: =IF(AH14="","",AF$35)
G47: =IF(I15="","",G$35) | H47: =IF(J15="","",H$35) | I47: =IF(K15="","",I$35) | J47: =IF(L15="","",J$35) | K47: =IF(M15="","",K$35) | L47: =IF(N15="","",L$35) | M47: =IF(O15="","",M$35) | N47: =IF(P15="","",N$35) | ... AF47: =IF(AH15="","",AF$35)
G48: =IF(I16="","",G$35) | H48: =IF(J16="","",H$35) | I48: =IF(K16="","",I$35) | J48: =IF(L16="","",J$35) | K48: =IF(M16="","",K$35) | L48: =IF(N16="","",L$35) | M48: =IF(O16="","",M$35) | N48: =IF(P16="","",N$35) | ... AF48: =IF(AH16="","",AF$35)
G49: =IF(I17="","",G$35) | H49: =IF(J17="","",H$35) | I49: =IF(K17="","",I$35) | J49: =IF(L17="","",J$35) | K49: =IF(M17="","",K$35) | L49: =IF(N17="","",L$35) | M49: =IF(O17="","",M$35) | N49: =IF(P17="","",N$35) | ... AF49: =IF(AH17="","",AF$35)
...

Sheet DESIGN_CORRELATION
