Workbook

Sheet INSTRUCTIONS
A1: INSTRUCTIONS
A3: This workbook can be used to assess the orthogonality of a design matrix. It can also be used interactively to improve the characteristics of a design
A5: To make use of it
B7: Enter or copy your design matrix in the DESIGN_MATRIX sheet. | N7: DESIGN_MATRIX
A9: The orthogonality as determinant of the correlation matrix and J-orthogonailty are shown in same worksheet.
A11: Other worksheets include some intermediate calculations.
A13: This workbook requires Office 365 (Excel 2021 or newer). License: CC-BY-SA 4-0, https://creativecommons.org/licenses/by-sa/4.0/ 2024-2025, Jordi Cuadros, IQS Univ Ramon Llull, https://orcid.org/0000-0001-6513-9140

Sheet DESIGN_MATRIX
A1: Orthogonality checker & calculator | N1: Correlation | S1: =IF(B7="","","CORRELATION_MATRIX!B2:"&ADDRESS(E3+1,E3+1)) -> CORRELATION_MATRIX!B2:$AT$46 | AG1: Orthogonality (D-Optimality) | AT1: =IF(B7="","",AA2) -> 1
A2: # runs | E2: =IF(B7="","",COUNT(B7:B106)) -> 72 | N2: Determinant of correlation matrix | AA2: =IF(B7="","",MDETERM(INDIRECT(S1))) -> 1 | AG2: J-Optimality | AT2: =IF(B7="","",IDENTITY_COUNT!T1) -> 1
A3: # columns | E3: =IF(B7="","",COUNT(B7:CV7)) -> 45 | N3: Maximum non-diagonal correlation (abs.) | AA3: {=IF(B7="","",MAX(IF(ROW(INDIRECT(S1))=COLUMN(INDIRECT(S1)),0,ABS(INDIRECT(S1)))))} -> 0 | AG3: Loss of orthogonality (D-Optimality) | AT3: =IF(B7="","",1-AT1) -> 2.220446e-16
N4: Average non-diagonal sq. correlation | AA4: {=IF(B7="","",AVERAGE(IF(ROW(INDIRECT(S1))>=COLUMN(INDIRECT(S1)),"",INDIRECT(S1)^2)))} -> 0 | AG4: Loss of optimality (J-Optimality) | AT4: =IF(B7="","",1-AT2) -> 4.4408921e-16
B5: Columns
A6: run | B6: 1 | C6: 2 | D6: 3 | E6: 4 | F6: 5 | G6: 6 | H6: 7 | I6: 8 | J6: 9 | K6: 10 | L6: 11 | M6: 12 | N6: 13 | O6: 14 | P6: 15 | Q6: 16 | R6: 17 | S6: 18 | T6: 19 | U6: 20 | V6: 21 | W6: 22 | X6: 23 | Y6: 24 | Z6: 25 | AA6: 26 | AB6: 27 | AC6: 28 | AD6: 29 | AE6: 30 | AF6: 31 | AG6: 32 | AH6: 33 | AI6: 34 | AJ6: 35 | AK6: 36 | AL6: 37 | AM6: 38 | AN6: 39 | AO6: 40 | AP6: 41 | AQ6: 42 | AR6: 43 | AS6: 44 | AT6: 45 | AU6: 46 | AV6: 47 | AW6: 48 | AX6: 49 | AY6: 50 | AZ6: 51 | BA6: 52 | BB6: 53 | BC6: 54 | BD6: 55 | BE6: 56 | BF6: 57 | BG6: 58 | BH6: 59 | BI6: 60 | BJ6: 61 | BK6: 62 | BL6: 63 | BM6: 64 | BN6: 65 | BO6: 66 | BP6: 67 | BQ6: 68 | BR6: 69 | BS6: 70 | BT6: 71 | BU6: 72 | BV6: 73 | BW6: 74 | BX6: 75 | BY6: 76 | BZ6: 77 | CA6: 78 | CB6: 79 | CC6: 80 | CD6: 81 | CE6: 82 | CF6: 83 | CG6: 84 | CH6: 85 | CI6: 86 | CJ6: 87 | CK6: 88 | CL6: 89 | CM6: 90 | CN6: 91 | CO6: 92 | CP6: 93 | CQ6: 94 | CR6: 95 | CS6: 96 | CT6: 97 | CU6: 98 | CV6: 99
A7: 1 | B7: 3 | C7: 1 | D7: 1 | E7: 2 | F7: 2 | G7: 1 | H7: 1 | I7: 2 | J7: 2 | K7: 2 | L7: 2 | M7: 0 | N7: 0 | O7: 2 | P7: 2 | Q7: 0 | R7: 0 | S7: 0 | T7: 0 | U7: 1 | V7: 1 | W7: 0 | X7: 0 | Y7: 1 | Z7: 1 | AA7: 0 | AB7: 0 | AC7: 1 | AD7: 0 | AE7: 1 | AF7: 1 | AG7: 1 | AH7: 1 | AI7: 0 | AJ7: 1 | AK7: 0 | AL7: 0 | AM7: 0 | AN7: 0 | AO7: 0 | AP7: 1 | AQ7: 1 | AR7: 1 | AS7: 0 | AT7: 1
A8: 2 | B8: 0 | C8: 1 | D8: 1 | E8: 2 | F8: 2 | G8: 1 | H8: 1 | I8: 2 | J8: 2 | K8: 0 | L8: 0 | M8: 2 | N8: 2 | O8: 0 | P8: 0 | Q8: 2 | R8: 2 | S8: 1 | T8: 1 | U8: 0 | V8: 0 | W8: 1 | X8: 1 | Y8: 0 | Z8: 0 | AA8: 0 | AB8: 0 | AC8: 1 | AD8: 0 | AE8: 1 | AF8: 1 | AG8: 1 | AH8: 1 | AI8: 0 | AJ8: 1 | AK8: 1 | AL8: 1 | AM8: 1 | AN8: 1 | AO8: 1 | AP8: 0 | AQ8: 0 | AR8: 0 | AS8: 1 | AT8: 0
A9: 3 | B9: 3 | C9: 2 | D9: 2 | E9: 1 | F9: 1 | G9: 2 | H9: 2 | I9: 1 | J9: 1 | K9: 2 | L9: 2 | M9: 0 | N9: 0 | O9: 2 | P9: 2 | Q9: 0 | R9: 0 | S9: 1 | T9: 1 | U9: 0 | V9: 0 | W9: 1 | X9: 1 | Y9: 0 | Z9: 0 | AA9: 1 | AB9: 1 | AC9: 1 | AD9: 1 | AE9: 1 | AF9: 0 | AG9: 1 | AH9: 0 | AI9: 0 | AJ9: 0 | AK9: 0 | AL9: 0 | AM9: 1 | AN9: 1 | AO9: 1 | AP9: 0 | AQ9: 0 | AR9: 1 | AS9: 0 | AT9: 0
A10: 4 | B10: 0 | C10: 2 | D10: 2 | E10: 1 | F10: 1 | G10: 2 | H10: 2 | I10: 1 | J10: 1 | K10: 0 | L10: 0 | M10: 2 | N10: 2 | O10: 0 | P10: 0 | Q10: 2 | R10: 2 | S10: 0 | T10: 0 | U10: 1 | V10: 1 | W10: 0 | X10: 0 | Y10: 1 | Z10: 1 | AA10: 1 | AB10: 1 | AC10: 1 | AD10: 1 | AE10: 1 | AF10: 0 | AG10: 1 | AH10: 0 | AI10: 0 | AJ10: 0 | AK10: 1 | AL10: 1 | AM10: 0 | AN10: 0 | AO10: 0 | AP10: 1 | AQ10: 1 | AR10: 0 | AS10: 1 | AT10: 1
A11: 5 | B11: 2 | C11: 1 | D11: 1 | E11: 2 | F11: 2 | G11: 2 | H11: 2 | I11: 1 | J11: 1 | K11: 0 | L11: 0 | M11: 1 | N11: 1 | O11: 1 | P11: 1 | Q11: 0 | R11: 0 | S11: 2 | T11: 2 | U11: 0 | V11: 0 | W11: 0 | X11: 0 | Y11: 2 | Z11: 2 | AA11: 1 | AB11: 1 | AC11: 0 | AD11: 0 | AE11: 1 | AF11: 1 | AG11: 0 | AH11: 1 | AI11: 0 | AJ11: 0 | AK11: 0 | AL11: 1 | AM11: 0 | AN11: 1 | AO11: 1 | AP11: 1 | AQ11: 1 | AR11: 0 | AS11: 0 | AT11: 0
A12: 6 | B12: 1 | C12: 1 | D12: 1 | E12: 2 | F12: 2 | G12: 2 | H12: 2 | I12: 1 | J12: 1 | K12: 1 | L12: 1 | M12: 0 | N12: 0 | O12: 0 | P12: 0 | Q12: 1 | R12: 1 | S12: 0 | T12: 0 | U12: 2 | V12: 2 | W12: 2 | X12: 2 | Y12: 0 | Z12: 0 | AA12: 1 | AB12: 1 | AC12: 0 | AD12: 0 | AE12: 1 | AF12: 1 | AG12: 0 | AH12: 1 | AI12: 0 | AJ12: 0 | AK12: 1 | AL12: 0 | AM12: 1 | AN12: 0 | AO12: 0 | AP12: 0 | AQ12: 0 | AR12: 1 | AS12: 1 | AT12: 1
A13: 7 | B13: 2 | C13: 2 | D13: 2 | E13: 1 | F13: 1 | G13: 1 | H13: 1 | I13: 2 | J13: 2 | K13: 0 | L13: 0 | M13: 1 | N13: 1 | O13: 1 | P13: 1 | Q13: 0 | R13: 0 | S13: 0 | T13: 0 | U13: 2 | V13: 2 | W13: 2 | X13: 2 | Y13: 0 | Z13: 0 | AA13: 0 | AB13: 0 | AC13: 0 | AD13: 1 | AE13: 1 | AF13: 0 | AG13: 1 | AH13: 1 | AI13: 1 | AJ13: 0 | AK13: 0 | AL13: 1 | AM13: 1 | AN13: 0 | AO13: 0 | AP13: 0 | AQ13: 1 | AR13: 1 | AS13: 1 | AT13: 0
A14: 8 | B14: 1 | C14: 2 | D14: 2 | E14: 1 | F14: 1 | G14: 1 | H14: 1 | I14: 2 | J14: 2 | K14: 1 | L14: 1 | M14: 0 | N14: 0 | O14: 0 | P14: 0 | Q14: 1 | R14: 1 | S14: 2 | T14: 2 | U14: 0 | V14: 0 | W14: 0 | X14: 0 | Y14: 2 | Z14: 2 | AA14: 0 | AB14: 0 | AC14: 0 | AD14: 1 | AE14: 1 | AF14: 0 | AG14: 1 | AH14: 1 | AI14: 1 | AJ14: 0 | AK14: 1 | AL14: 0 | AM14: 0 | AN14: 1 | AO14: 1 | AP14: 1 | AQ14: 0 | AR14: 0 | AS14: 0 | AT14: 1
A15: 9 | B15: 0 | C15: 2 | D15: 0 | E15: 2 | F15: 0 | G15: 0 | H15: 1 | I15: 0 | J15: 1 | K15: 2 | L15: 0 | M15: 2 | N15: 0 | O15: 0 | P15: 1 | Q15: 0 | R15: 1 | S15: 2 | T15: 0 | U15: 2 | V15: 0 | W15: 0 | X15: 1 | Y15: 0 | Z15: 1 | AA15: 0 | AB15: 0 | AC15: 0 | AD15: 0 | AE15: 0 | AF15: 0 | AG15: 0 | AH15: 0 | AI15: 0 | AJ15: 0 | AK15: 0 | AL15: 0 | AM15: 0 | AN15: 0 | AO15: 0 | AP15: 0 | AQ15: 0 | AR15: 0 | AS15: 0 | AT15: 0
A16: 10 | B16: 3 | C16: 2 | D16: 0 | E16: 2 | F16: 0 | G16: 0 | H16: 1 | I16: 0 | J16: 1 | K16: 0 | L16: 2 | M16: 0 | N16: 2 | O16: 1 | P16: 0 | Q16: 1 | R16: 0 | S16: 0 | T16: 2 | U16: 0 | V16: 2 | W16: 1 | X16: 0 | Y16: 1 | Z16: 0 | AA16: 0 | AB16: 0 | AC16: 0 | AD16: 0 | AE16: 0 | AF16: 0 | AG16: 0 | AH16: 0 | AI16: 0 | AJ16: 0 | AK16: 1 | AL16: 1 | AM16: 1 | AN16: 1 | AO16: 1 | AP16: 1 | AQ16: 1 | AR16: 1 | AS16: 1 | AT16: 1
A17: 11 | B17: 1 | C17: 0 | D17: 2 | E17: 0 | F17: 2 | G17: 1 | H17: 0 | I17: 1 | J17: 0 | K17: 2 | L17: 0 | M17: 2 | N17: 0 | O17: 0 | P17: 1 | Q17: 0 | R17: 1 | S17: 0 | T17: 2 | U17: 0 | V17: 2 | W17: 1 | X17: 0 | Y17: 1 | Z17: 0 | AA17: 1 | AB17: 0 | AC17: 1 | AD17: 0 | AE17: 0 | AF17: 1 | AG17: 1 | AH17: 0 | AI17: 1 | AJ17: 0 | AK17: 0 | AL17: 0 | AM17: 1 | AN17: 1 | AO17: 0 | AP17: 1 | AQ17: 1 | AR17: 0 | AS17: 1 | AT17: 0
A18: 12 | B18: 2 | C18: 0 | D18: 2 | E18: 0 | F18: 2 | G18: 1 | H18: 0 | I18: 1 | J18: 0 | K18: 0 | L18: 2 | M18: 0 | N18: 2 | O18: 1 | P18: 0 | Q18: 1 | R18: 0 | S18: 2 | T18: 0 | U18: 2 | V18: 0 | W18: 0 | X18: 1 | Y18: 0 | Z18: 1 | AA18: 1 | AB18: 0 | AC18: 1 | AD18: 0 | AE18: 0 | AF18: 1 | AG18: 1 | AH18: 0 | AI18: 1 | AJ18: 0 | AK18: 1 | AL18: 1 | AM18: 0 | AN18: 0 | AO18: 1 | AP18: 0 | AQ18: 0 | AR18: 1 | AS18: 0 | AT18: 1
... A78: 72 | B78: 2 | C78: 0 | D78: 2 | E78: 2 | F78: 0 | G78: 1 | H78: 2 | I78: 2 | J78: 1 | K78: 0 | L78: 2 | M78: 2 | N78: 0 | O78: 1 | P78: 2 | Q78: 2 | R78: 1 | S78: 1 | T78: 2 | U78: 1 | V78: 2 | W78: 0 | X78: 2 | Y78: 0 | Z78: 2 | AA78: 0 | AB78: 1 | AC78: 0 | AD78: 1 | AE78: 0 | AF78: 1 | AG78: 1 | AH78: 0 | AI78: 0 | AJ78: 1 | AK78: 1 | AL78: 0 | AM78: 0 | AN78: 1 | AO78: 0 | AP78: 1 | AQ78: 0 | AR78: 1 | AS78: 1 | AT78: 0
A79: 73
A80: 74
A81: 75
A82: 76
A83: 77
A84: 78
A85: 79
A86: 80
A87: 81
A88: 82
A89: 83
A90: 84
... A106: 100

Sheet CORRELATION_MATRIX
A1: << | B1: 1 | C1: 2 | D1: 3 | E1: 4 | F1: 5 | G1: 6 | H1: 7 | I1: 8 | J1: 9 | K1: 10 | L1: 11 | M1: 12 | N1: 13 | O1: 14 | P1: 15 | Q1: 16 | R1: 17 | S1: 18 | T1: 19 | U1: 20 | V1: 21 | W1: 22 | X1: 23 | Y1: 24 | Z1: 25 | AA1: 26 | AB1: 27 | AC1: 28 | AD1: 29 | AE1: 30 | AF1: 31 | AG1: 32 | AH1: 33 | AI1: 34 | AJ1: 35 | AK1: 36 | AL1: 37 | AM1: 38 | AN1: 39 | AO1: 40 | AP1: 41 | AQ1: 42 | AR1: 43 | AS1: 44 | AT1: 45 | AU1: 46 | AV1: 47 | AW1: 48 | AX1: 49 | AY1: 50 | AZ1: 51 | BA1: 52 | BB1: 53 | BC1: 54 | BD1: 55 | BE1: 56 | BF1: 57 | BG1: 58 | BH1: 59 | BI1: 60 | BJ1: 61 | BK1: 62 | BL1: 63 | BM1: 64 | BN1: 65 | BO1: 66 | BP1: 67 | BQ1: 68 | BR1: 69 | BS1: 70 | BT1: 71 | BU1: 72 | BV1: 73 | BW1: 74 | BX1: 75 | BY1: 76 | BZ1: 77 | CA1: 78 | CB1: 79 | CC1: 80 | CD1: 81 | CE1: 82 | CF1: 83 | CG1: 84 | CH1: 85 | CI1: 86 | CJ1: 87 | CK1: 88 | CL1: 89 | CM1: 90 | CN1: 91 | CO1: 92 | CP1: 93 | CQ1: 94 | CR1: 95 | CS1: 96 | CT1: 97 | CU1: 98 | CV1: 99
A2: 1 | B2: =IF(OR($A2>DESIGN_MATRIX!$E$3,B$1>DESIGN_MATRIX!$E$3),"",CORREL(INDIRECT("DESIGN_MATRIX!"&ADDRESS(7,$A2+1)&":"&ADDRESS(6+DESIGN_MATRIX!$E$2,$A2+1)),INDIRECT("DESIGN_MATRIX!"&ADDRESS(7,B$1+1)&":"&ADDRESS(6+DESIGN_MATRIX!$E$2,B$1+1)))) -> 1 | C2: =IF(OR($A2>DESIGN_MATRIX!$E$3,C$1>DESIGN_MATRIX!$E$3),"",CORREL(INDIRECT("DESIGN_MATRIX!"&ADDRESS(7,$A2+1)&":"&ADDRESS(6+DESIGN_MATRIX!$E$2,$A2+1)),INDIRECT("DESIGN_MATRIX!"&ADDRESS(7,C$1+1)&":"&ADDRESS(6+DESIGN_MATRIX!$E$2,C$1+1)))) -> 0 | D2: =IF(OR($A2>DESIGN_MATRIX!$E$3,D$1>DESIGN_MATRIX!$E$3),"",CORREL(INDIRECT("DESIGN_MATRIX!"&ADDRESS(7,$A2+1)&":"&ADDRESS(6+DESIGN_MATRIX!$E$2,$A2+1)),INDIRECT("DESIGN_MATRIX!"&ADDRESS(7,D$1+1)&":"&ADDRESS(6+DESIGN_MATRIX!$E$2,D$1+1)))) -> 0 | E2: =IF(OR($A2>DESIGN_MATRIX!$E$3,E$1>DESIGN_MATRIX!$E$3),"",CORREL(INDIRECT("DESIGN_MATRIX!"&ADDRESS(7,$A2+1)&":"&ADDRESS(6+DESIGN_MATRIX!$E$2,$A2+1)),INDIRECT("DESIGN_MATRIX!"&ADDRESS(7,E$1+1)&":"&ADDRESS(6+DESIGN_MATRIX!$E$2,E$1+1)))) -> 0 | F2: =IF(OR($A2>DESIGN_MATRIX!$E$3,F$1>DESIGN_MATRIX!$E$3),"",CORREL(INDIRECT("DESIGN_MATRIX!"&ADDRESS(7,$A2+1)&":"&ADDRESS(6+DESIGN_MATRIX!$E$2,$A2+1)),INDIRECT("DESIGN_MATRIX!"&ADDRESS(7,F$1+1)&":"&ADDRESS(6+DESIGN_MATRIX!$E$2,F$1+1)))) -> 0 | G2: =IF(OR($A2>DESIGN_MATRIX!$E$3,G$1>DESIGN_MATRIX!$E$3),"",CORREL(INDIRECT("DESIGN_MATRIX!"&ADDRESS(7,$A2+1)&":"&ADDRESS(6+DESIGN_MATRIX!$E$2,$A2+1)),INDIRECT("DESIGN_MATRIX!"&ADDRESS(7,G$1+1)&":"&ADDRESS(6+DESIGN_MATRIX!$E$2,G$1+1)))) -> 0 | H2: =IF(OR($A2>DESIGN_MATRIX!$E$3,H$1>DESIGN_MATRIX!$E$3),"",CORREL(INDIRECT("DESIGN_MATRIX!"&ADDRESS(7,$A2+1)&":"&ADDRESS(6+DESIGN_MATRIX!$E$2,$A2+1)),INDIRECT("DESIGN_MATRIX!"&ADDRESS(7,H$1+1)&":"&ADDRESS(6+DESIGN_MATRIX!$E$2,H$1+1)))) -> 0 | I2: =IF(OR($A2>DESIGN_MATRIX!$E$3,I$1>DESIGN_MATRIX!$E$3),"",CORREL(INDIRECT("DESIGN_MATRIX!"&ADDRESS(7,$A2+1)&":"&ADDRESS(6+DESIGN_MATRIX!$E$2,$A2+1)),INDIRECT("DESIGN_MATRIX!"&ADDRESS(7,I$1+1)&":"&ADDRESS(6+DESIGN_MATRIX!$E$2,I$1+1)))) -> 0 | ... CV2: =IF(OR($A2>DESIGN_MATRIX!$E$3,CV$1>DESIGN_MATRIX!$E$3),"",CORREL(INDIRECT("DESIGN_MATRIX!"&ADDRESS(7,$A2+1)&":"&ADDRESS(6+DESIGN_MATRIX!$E$2,$A2+1)),INDIRECT("DESIGN_MATRIX!"&ADDRESS(7,CV$1+1)&":"&ADDRESS(6+DESIGN_MATRIX!$E$2,CV$1+1))))
A3: 2 | B3: =IF(OR($A3>DESIGN_MATRIX!$E$3,B$1>DESIGN_MATRIX!$E$3),"",CORREL(INDIRECT("DESIGN_MATRIX!"&ADDRESS(7,$A3+1)&":"&ADDRESS(6+DESIGN_MATRIX!$E$2,$A3+1)),INDIRECT("DESIGN_MATRIX!"&ADDRESS(7,B$1+1)&":"&ADDRESS(6+DESIGN_MATRIX!$E$2,B$1+1)))) -> 0 | C3: =IF(OR($A3>DESIGN_MATRIX!$E$3,C$1>DESIGN_MATRIX!$E$3),"",CORREL(INDIRECT("DESIGN_MATRIX!"&ADDRESS(7,$A3+1)&":"&ADDRESS(6+DESIGN_MATRIX!$E$2,$A3+1)),INDIRECT("DESIGN_MATRIX!"&ADDRESS(7,C$1+1)&":"&ADDRESS(6+DESIGN_MATRIX!$E$2,C$1+1)))) -> 1 | D3: =IF(OR($A3>DESIGN_MATRIX!$E$3,D$1>DESIGN_MATRIX!$E$3),"",CORREL(INDIRECT("DESIGN_MATRIX!"&ADDRESS(7,$A3+1)&":"&ADDRESS(6+DESIGN_MATRIX!$E$2,$A3+1)),INDIRECT("DESIGN_MATRIX!"&ADDRESS(7,D$1+1)&":"&ADDRESS(6+DESIGN_MATRIX!$E$2,D$1+1)))) -> 0 | E3: =IF(OR($A3>DESIGN_MATRIX!$E$3,E$1>DESIGN_MATRIX!$E$3),"",CORREL(INDIRECT("DESIGN_MATRIX!"&ADDRESS(7,$A3+1)&":"&ADDRESS(6+DESIGN_MATRIX!$E$2,$A3+1)),INDIRECT("DESIGN_MATRIX!"&ADDRESS(7,E$1+1)&":"&ADDRESS(6+DESIGN_MATRIX!$E$2,E$1+1)))) -> 0 | F3: =IF(OR($A3>DESIGN_MATRIX!$E$3,F$1>DESIGN_MATRIX!$E$3),"",CORREL(INDIRECT("DESIGN_MATRIX!"&ADDRESS(7,$A3+1)&":"&ADDRESS(6+DESIGN_MATRIX!$E$2,$A3+1)),INDIRECT("DESIGN_MATRIX!"&ADDRESS(7,F$1+1)&":"&ADDRESS(6+DESIGN_MATRIX!$E$2,F$1+1)))) -> 0 | G3: =IF(OR($A3>DESIGN_MATRIX!$E$3,G$1>DESIGN_MATRIX!$E$3),"",CORREL(INDIRECT("DESIGN_MATRIX!"&ADDRESS(7,$A3+1)&":"&ADDRESS(6+DESIGN_MATRIX!$E$2,$A3+1)),INDIRECT("DESIGN_MATRIX!"&ADDRESS(7,G$1+1)&":"&ADDRESS(6+DESIGN_MATRIX!$E$2,G$1+1)))) -> 0 | H3: =IF(OR($A3>DESIGN_MATRIX!$E$3,H$1>DESIGN_MATRIX!$E$3),"",CORREL(INDIRECT("DESIGN_MATRIX!"&ADDRESS(7,$A3+1)&":"&ADDRESS(6+DESIGN_MATRIX!$E$2,$A3+1)),INDIRECT("DESIGN_MATRIX!"&ADDRESS(7,H$1+1)&":"&ADDRESS(6+DESIGN_MATRIX!$E$2,H$1+1)))) -> 0 | I3: =IF(OR($A3>DESIGN_MATRIX!$E$3,I$1>DESIGN_MATRIX!$E$3),"",CORREL(INDIRECT("DESIGN_MATRIX!"&ADDRESS(7,$A3+1)&":"&ADDRESS(6+DESIGN_MATRIX!$E$2,$A3+1)),INDIRECT("DESIGN_MATRIX!"&ADDRESS(7,I$1+1)&":"&ADDRESS(6+DESIGN_MATRIX!$E$2,I$1+1)))) -> 0 | ... CV3: =IF(OR($A3>DESIGN_MATRIX!$E$3,CV$1>DESIGN_MATRIX!$E$3),"",CORREL(INDIRECT("DESIGN_MATRIX!"&ADDRESS(7,$A3+1)&":"&ADDRESS(6+DESIGN_MATRIX!$E$2,$A3+1)),INDIRECT("DESIGN_MATRIX!"&ADDRESS(7,CV$1+1)&":"&ADDRESS(6+DESIGN_MATRIX!$E$2,CV$1+1))))
A4: 3 | B4: =IF(OR($A4>DESIGN_MATRIX!$E$3,B$1>DESIGN_MATRIX!$E$3),"",CORREL(INDIRECT("DESIGN_MATRIX!"&ADDRESS(7,$A4+1)&":"&ADDRESS(6+DESIGN_MATRIX!$E$2,$A4+1)),INDIRECT("DESIGN_MATRIX!"&ADDRESS(7,B$1+1)&":"&ADDRESS(6+DESIGN_MATRIX!$E$2,B$1+1)))) -> 0 | C4: =IF(OR($A4>DESIGN_MATRIX!$E$3,C$1>DESIGN_MATRIX!$E$3),"",CORREL(INDIRECT("DESIGN_MATRIX!"&ADDRESS(7,$A4+1)&":"&ADDRESS(6+DESIGN_MATRIX!$E$2,$A4+1)),INDIRECT("DESIGN_MATRIX!"&ADDRESS(7,C$1+1)&":"&ADDRESS(6+DESIGN_MATRIX!$E$2,C$1+1)))) -> 0 | D4: =IF(OR($A4>DESIGN_MATRIX!$E$3,D$1>DESIGN_MATRIX!$E$3),"",CORREL(INDIRECT("DESIGN_MATRIX!"&ADDRESS(7,$A4+1)&":"&ADDRESS(6+DESIGN_MATRIX!$E$2,$A4+1)),INDIRECT("DESIGN_MATRIX!"&ADDRESS(7,D$1+1)&":"&ADDRESS(6+DESIGN_MATRIX!$E$2,D$1+1)))) -> 1 | E4: =IF(OR($A4>DESIGN_MATRIX!$E$3,E$1>DESIGN_MATRIX!$E$3),"",CORREL(INDIRECT("DESIGN_MATRIX!"&ADDRESS(7,$A4+1)&":"&ADDRESS(6+DESIGN_MATRIX!$E$2,$A4+1)),INDIRECT("DESIGN_MATRIX!"&ADDRESS(7,E$1+1)&":"&ADDRESS(6+DESIGN_MATRIX!$E$2,E$1+1)))) -> 0 | F4: =IF(OR($A4>DESIGN_MATRIX!$E$3,F$1>DESIGN_MATRIX!$E$3),"",CORREL(INDIRECT("DESIGN_MATRIX!"&ADDRESS(7,$A4+1)&":"&ADDRESS(6+DESIGN_MATRIX!$E$2,$A4+1)),INDIRECT("DESIGN_MATRIX!"&ADDRESS(7,F$1+1)&":"&ADDRESS(6+DESIGN_MATRIX!$E$2,F$1+1)))) -> 0 | G4: =IF(OR($A4>DESIGN_MATRIX!$E$3,G$1>DESIGN_MATRIX!$E$3),"",CORREL(INDIRECT("DESIGN_MATRIX!"&ADDRESS(7,$A4+1)&":"&ADDRESS(6+DESIGN_MATRIX!$E$2,$A4+1)),INDIRECT("DESIGN_MATRIX!"&ADDRESS(7,G$1+1)&":"&ADDRESS(6+DESIGN_MATRIX!$E$2,G$1+1)))) -> 0 | H4: =IF(OR($A4>DESIGN_MATRIX!$E$3,H$1>DESIGN_MATRIX!$E$3),"",CORREL(INDIRECT("DESIGN_MATRIX!"&ADDRESS(7,$A4+1)&":"&ADDRESS(6+DESIGN_MATRIX!$E$2,$A4+1)),INDIRECT("DESIGN_MATRIX!"&ADDRESS(7,H$1+1)&":"&ADDRESS(6+DESIGN_MATRIX!$E$2,H$1+1)))) -> 0 | I4: =IF(OR($A4>DESIGN_MATRIX!$E$3,I$1>DESIGN_MATRIX!$E$3),"",CORREL(INDIRECT("DESIGN_MATRIX!"&ADDRESS(7,$A4+1)&":"&ADDRESS(6+DESIGN_MATRIX!$E$2,$A4+1)),INDIRECT("DESIGN_MATRIX!"&ADDRESS(7,I$1+1)&":"&ADDRESS(6+DESIGN_MATRIX!$E$2,I$1+1)))) -> 0 | ... CV4: =IF(OR($A4>DESIGN_MATRIX!$E$3,CV$1>DESIGN_MATRIX!$E$3),"",CORREL(INDIRECT("DESIGN_MATRIX!"&ADDRESS(7,$A4+1)&":"&ADDRESS(6+DESIGN_MATRIX!$E$2,$A4+1)),INDIRECT("DESIGN_MATRIX!"&ADDRESS(7,CV$1+1)&":"&ADDRESS(6+DESIGN_MATRIX!$E$2,CV$1+1))))
A5: 4 | B5: =IF(OR($A5>DESIGN_MATRIX!$E$3,B$1>DESIGN_MATRIX!$E$3),"",CORREL(INDIRECT("DESIGN_MATRIX!"&ADDRESS(7,$A5+1)&":"&ADDRESS(6+DESIGN_MATRIX!$E$2,$A5+1)),INDIRECT("DESIGN_MATRIX!"&ADDRESS(7,B$1+1)&":"&ADDRESS(6+DESIGN_MATRIX!$E$2,B$1+1)))) -> 0 | C5: =IF(OR($A5>DESIGN_MATRIX!$E$3,C$1>DESIGN_MATRIX!$E$3),"",CORREL(INDIRECT("DESIGN_MATRIX!"&ADDRESS(7,$A5+1)&":"&ADDRESS(6+DESIGN_MATRIX!$E$2,$A5+1)),INDIRECT("DESIGN_MATRIX!"&ADDRESS(7,C$1+1)&":"&ADDRESS(6+DESIGN_MATRIX!$E$2,C$1+1)))) -> 0 | D5: =IF(OR($A5>DESIGN_MATRIX!$E$3,D$1>DESIGN_MATRIX!$E$3),"",CORREL(INDIRECT("DESIGN_MATRIX!"&ADDRESS(7,$A5+1)&":"&ADDRESS(6+DESIGN_MATRIX!$E$2,$A5+1)),INDIRECT("DESIGN_MATRIX!"&ADDRESS(7,D$1+1)&":"&ADDRESS(6+DESIGN_MATRIX!$E$2,D$1+1)))) -> 0 | E5: =IF(OR($A5>DESIGN_MATRIX!$E$3,E$1>DESIGN_MATRIX!$E$3),"",CORREL(INDIRECT("DESIGN_MATRIX!"&ADDRESS(7,$A5+1)&":"&ADDRESS(6+DESIGN_MATRIX!$E$2,$A5+1)),INDIRECT("DESIGN_MATRIX!"&ADDRESS(7,E$1+1)&":"&ADDRESS(6+DESIGN_MATRIX!$E$2,E$1+1)))) -> 1 | F5: =IF(OR($A5>DESIGN_MATRIX!$E$3,F$1>DESIGN_MATRIX!$E$3),"",CORREL(INDIRECT("DESIGN_MATRIX!"&ADDRESS(7,$A5+1)&":"&ADDRESS(6+DESIGN_MATRIX!$E$2,$A5+1)),INDIRECT("DESIGN_MATRIX!"&ADDRESS(7,F$1+1)&":"&ADDRESS(6+DESIGN_MATRIX!$E$2,F$1+1)))) -> 0 | G5: =IF(OR($A5>DESIGN_MATRIX!$E$3,G$1>DESIGN_MATRIX!$E$3),"",CORREL(INDIRECT("DESIGN_MATRIX!"&ADDRESS(7,$A5+1)&":"&ADDRESS(6+DESIGN_MATRIX!$E$2,$A5+1)),INDIRECT("DESIGN_MATRIX!"&ADDRESS(7,G$1+1)&":"&ADDRESS(6+DESIGN_MATRIX!$E$2,G$1+1)))) -> 0 | H5: =IF(OR($A5>DESIGN_MATRIX!$E$3,H$1>DESIGN_MATRIX!$E$3),"",CORREL(INDIRECT("DESIGN_MATRIX!"&ADDRESS(7,$A5+1)&":"&ADDRESS(6+DESIGN_MATRIX!$E$2,$A5+1)),INDIRECT("DESIGN_MATRIX!"&ADDRESS(7,H$1+1)&":"&ADDRESS(6+DESIGN_MATRIX!$E$2,H$1+1)))) -> 0 | I5: =IF(OR($A5>DESIGN_MATRIX!$E$3,I$1>DESIGN_MATRIX!$E$3),"",CORREL(INDIRECT("DESIGN_MATRIX!"&ADDRESS(7,$A5+1)&":"&ADDRESS(6+DESIGN_MATRIX!$E$2,$A5+1)),INDIRECT("DESIGN_MATRIX!"&ADDRESS(7,I$1+1)&":"&ADDRESS(6+DESIGN_MATRIX!$E$2,I$1+1)))) -> 0 | ... CV5: =IF(OR($A5>DESIGN_MATRIX!$E$3,CV$1>DESIGN_MATRIX!$E$3),"",CORREL(INDIRECT("DESIGN_MATRIX!"&ADDRESS(7,$A5+1)&":"&ADDRESS(6+DESIGN_MATRIX!$E$2,$A5+1)),INDIRECT("DESIGN_MATRIX!"&ADDRESS(7,CV$1+1)&":"&ADDRESS(6+DESIGN_MATRIX!$E$2,CV$1+1))))
A6: 5 | B6: =IF(OR($A6>DESIGN_MATRIX!$E$3,B$1>DESIGN_MATRIX!$E$3),"",CORREL(INDIRECT("DESIGN_MATRIX!"&ADDRESS(7,$A6+1)&":"&ADDRESS(6+DESIGN_MATRIX!$E$2,$A6+1)),INDIRECT("DESIGN_MATRIX!"&ADDRESS(7,B$1+1)&":"&ADDRESS(6+DESIGN_MATRIX!$E$2,B$1+1)))) -> 0 | C6: =IF(OR($A6>DESIGN_MATRIX!$E$3,C$1>DESIGN_MATRIX!$E$3),"",CORREL(INDIRECT("DESIGN_MATRIX!"&ADDRESS(7,$A6+1)&":"&ADDRESS(6+DESIGN_MATRIX!$E$2,$A6+1)),INDIRECT("DESIGN_MATRIX!"&ADDRESS(7,C$1+1)&":"&ADDRESS(6+DESIGN_MATRIX!$E$2,C$1+1)))) -> 0 | D6: =IF(OR($A6>DESIGN_MATRIX!$E$3,D$1>DESIGN_MATRIX!$E$3),"",CORREL(INDIRECT("DESIGN_MATRIX!"&ADDRESS(7,$A6+1)&":"&ADDRESS(6+DESIGN_MATRIX!$E$2,$A6+1)),INDIRECT("DESIGN_MATRIX!"&ADDRESS(7,D$1+1)&":"&ADDRESS(6+DESIGN_MATRIX!$E$2,D$1+1)))) -> 0 | E6: =IF(OR($A6>DESIGN_MATRIX!$E$3,E$1>DESIGN_MATRIX!$E$3),"",CORREL(INDIRECT("DESIGN_MATRIX!"&ADDRESS(7,$A6+1)&":"&ADDRESS(6+DESIGN_MATRIX!$E$2,$A6+1)),INDIRECT("DESIGN_MATRIX!"&ADDRESS(7,E$1+1)&":"&ADDRESS(6+DESIGN_MATRIX!$E$2,E$1+1)))) -> 0 | F6: =IF(OR($A6>DESIGN_MATRIX!$E$3,F$1>DESIGN_MATRIX!$E$3),"",CORREL(INDIRECT("DESIGN_MATRIX!"&ADDRESS(7,$A6+1)&":"&ADDRESS(6+DESIGN_MATRIX!$E$2,$A6+1)),INDIRECT("DESIGN_MATRIX!"&ADDRESS(7,F$1+1)&":"&ADDRESS(6+DESIGN_MATRIX!$E$2,F$1+1)))) -> 1 | G6: =IF(OR($A6>DESIGN_MATRIX!$E$3,G$1>DESIGN_MATRIX!$E$3),"",CORREL(INDIRECT("DESIGN_MATRIX!"&ADDRESS(7,$A6+1)&":"&ADDRESS(6+DESIGN_MATRIX!$E$2,$A6+1)),INDIRECT("DESIGN_MATRIX!"&ADDRESS(7,G$1+1)&":"&ADDRESS(6+DESIGN_MATRIX!$E$2,G$1+1)))) -> 0 | H6: =IF(OR($A6>DESIGN_MATRIX!$E$3,H$1>DESIGN_MATRIX!$E$3),"",CORREL(INDIRECT("DESIGN_MATRIX!"&ADDRESS(7,$A6+1)&":"&ADDRESS(6+DESIGN_MATRIX!$E$2,$A6+1)),INDIRECT("DESIGN_MATRIX!"&ADDRESS(7,H$1+1)&":"&ADDRESS(6+DESIGN_MATRIX!$E$2,H$1+1)))) -> 0 | I6: =IF(OR($A6>DESIGN_MATRIX!$E$3,I$1>DESIGN_MATRIX!$E$3),"",CORREL(INDIRECT("DESIGN_MATRIX!"&ADDRESS(7,$A6+1)&":"&ADDRESS(6+DESIGN_MATRIX!$E$2,$A6+1)),INDIRECT("DESIGN_MATRIX!"&ADDRESS(7,I$1+1)&":"&ADDRESS(6+DESIGN_MATRIX!$E$2,I$1+1)))) -> 0 | ... CV6: =IF(OR($A6>DESIGN_MATRIX!$E$3,CV$1>DESIGN_MATRIX!$E$3),"",CORREL(INDIRECT("DESIGN_MATRIX!"&ADDRESS(7,$A6+1)&":"&ADDRESS(6+DESIGN_MATRIX!$E$2,$A6+1)),INDIRECT("DESIGN_MATRIX!"&ADDRESS(7,CV$1+1)&":"&ADDRESS(6+DESIGN_MATRIX!$E$2,CV$1+1))))
A7: 6 | B7: =IF(OR($A7>DESIGN_MATRIX!$E$3,B$1>DESIGN_MATRIX!$E$3),"",CORREL(INDIRECT("DESIGN_MATRIX!"&ADDRESS(7,$A7+1)&":"&ADDRESS(6+DESIGN_MATRIX!$E$2,$A7+1)),INDIRECT("DESIGN_MATRIX!"&ADDRESS(7,B$1+1)&":"&ADDRESS(6+DESIGN_MATRIX!$E$2,B$1+1)))) -> 0 | C7: =IF(OR($A7>DESIGN_MATRIX!$E$3,C$1>DESIGN_MATRIX!$E$3),"",CORREL(INDIRECT("DESIGN_MATRIX!"&ADDRESS(7,$A7+1)&":"&ADDRESS(6+DESIGN_MATRIX!$E$2,$A7+1)),INDIRECT("DESIGN_MATRIX!"&ADDRESS(7,C$1+1)&":"&ADDRESS(6+DESIGN_MATRIX!$E$2,C$1+1)))) -> 0 | D7: =IF(OR($A7>DESIGN_MATRIX!$E$3,D$1>DESIGN_MATRIX!$E$3),"",CORREL(INDIRECT("DESIGN_MATRIX!"&ADDRESS(7,$A7+1)&":"&ADDRESS(6+DESIGN_MATRIX!$E$2,$A7+1)),INDIRECT("DESIGN_MATRIX!"&ADDRESS(7,D$1+1)&":"&ADDRESS(6+DESIGN_MATRIX!$E$2,D$1+1)))) -> 0 | E7: =IF(OR($A7>DESIGN_MATRIX!$E$3,E$1>DESIGN_MATRIX!$E$3),"",CORREL(INDIRECT("DESIGN_MATRIX!"&ADDRESS(7,$A7+1)&":"&ADDRESS(6+DESIGN_MATRIX!$E$2,$A7+1)),INDIRECT("DESIGN_MATRIX!"&ADDRESS(7,E$1+1)&":"&ADDRESS(6+DESIGN_MATRIX!$E$2,E$1+1)))) -> 0 | F7: =IF(OR($A7>DESIGN_MATRIX!$E$3,F$1>DESIGN_MATRIX!$E$3),"",CORREL(INDIRECT("DESIGN_MATRIX!"&ADDRESS(7,$A7+1)&":"&ADDRESS(6+DESIGN_MATRIX!$E$2,$A7+1)),INDIRECT("DESIGN_MATRIX!"&ADDRESS(7,F$1+1)&":"&ADDRESS(6+DESIGN_MATRIX!$E$2,F$1+1)))) -> 0 | G7: =IF(OR($A7>DESIGN_MATRIX!$E$3,G$1>DESIGN_MATRIX!$E$3),"",CORREL(INDIRECT("DESIGN_MATRIX!"&ADDRESS(7,$A7+1)&":"&ADDRESS(6+DESIGN_MATRIX!$E$2,$A7+1)),INDIRECT("DESIGN_MATRIX!"&ADDRESS(7,G$1+1)&":"&ADDRESS(6+DESIGN_MATRIX!$E$2,G$1+1)))) -> 1 | H7: =IF(OR($A7>DESIGN_MATRIX!$E$3,H$1>DESIGN_MATRIX!$E$3),"",CORREL(INDIRECT("DESIGN_MATRIX!"&ADDRESS(7,$A7+1)&":"&ADDRESS(6+DESIGN_MATRIX!$E$2,$A7+1)),INDIRECT("DESIGN_MATRIX!"&ADDRESS(7,H$1+1)&":"&ADDRESS(6+DESIGN_MATRIX!$E$2,H$1+1)))) -> 0 | I7: =IF(OR($A7>DESIGN_MATRIX!$E$3,I$1>DESIGN_MATRIX!$E$3),"",CORREL(INDIRECT("DESIGN_MATRIX!"&ADDRESS(7,$A7+1)&":"&ADDRESS(6+DESIGN_MATRIX!$E$2,$A7+1)),INDIRECT("DESIGN_MATRIX!"&ADDRESS(7,I$1+1)&":"&ADDRESS(6+DESIGN_MATRIX!$E$2,I$1+1)))) -> 0 | ... CV7: =IF(OR($A7>DESIGN_MATRIX!$E$3,CV$1>DESIGN_MATRIX!$E$3),"",CORREL(INDIRECT("DESIGN_MATRIX!"&ADDRESS(7,$A7+1)&":"&ADDRESS(6+DESIGN_MATRIX!$E$2,$A7+1)),INDIRECT("DESIGN_MATRIX!"&ADDRESS(7,CV$1+1)&":"&ADDRESS(6+DESIGN_MATRIX!$E$2,CV$1+1))))
A8: 7 | B8: =IF(OR($A8>DESIGN_MATRIX!$E$3,B$1>DESIGN_MATRIX!$E$3),"",CORREL(INDIRECT("DESIGN_MATRIX!"&ADDRESS(7,$A8+1)&":"&ADDRESS(6+DESIGN_MATRIX!$E$2,$A8+1)),INDIRECT("DESIGN_MATRIX!"&ADDRESS(7,B$1+1)&":"&ADDRESS(6+DESIGN_MATRIX!$E$2,B$1+1)))) -> 0 | C8: =IF(OR($A8>DESIGN_MATRIX!$E$3,C$1>DESIGN_MATRIX!$E$3),"",CORREL(INDIRECT("DESIGN_MATRIX!"&ADDRESS(7,$A8+1)&":"&ADDRESS(6+DESIGN_MATRIX!$E$2,$A8+1)),INDIRECT("DESIGN_MATRIX!"&ADDRESS(7,C$1+1)&":"&ADDRESS(6+DESIGN_MATRIX!$E$2,C$1+1)))) -> 0 | D8: =IF(OR($A8>DESIGN_MATRIX!$E$3,D$1>DESIGN_MATRIX!$E$3),"",CORREL(INDIRECT("DESIGN_MATRIX!"&ADDRESS(7,$A8+1)&":"&ADDRESS(6+DESIGN_MATRIX!$E$2,$A8+1)),INDIRECT("DESIGN_MATRIX!"&ADDRESS(7,D$1+1)&":"&ADDRESS(6+DESIGN_MATRIX!$E$2,D$1+1)))) -> 0 | E8: =IF(OR($A8>DESIGN_MATRIX!$E$3,E$1>DESIGN_MATRIX!$E$3),"",CORREL(INDIRECT("DESIGN_MATRIX!"&ADDRESS(7,$A8+1)&":"&ADDRESS(6+DESIGN_MATRIX!$E$2,$A8+1)),INDIRECT("DESIGN_MATRIX!"&ADDRESS(7,E$1+1)&":"&ADDRESS(6+DESIGN_MATRIX!$E$2,E$1+1)))) -> 0 | F8: =IF(OR($A8>DESIGN_MATRIX!$E$3,F$1>DESIGN_MATRIX!$E$3),"",CORREL(INDIRECT("DESIGN_MATRIX!"&ADDRESS(7,$A8+1)&":"&ADDRESS(6+DESIGN_MATRIX!$E$2,$A8+1)),INDIRECT("DESIGN_MATRIX!"&ADDRESS(7,F$1+1)&":"&ADDRESS(6+DESIGN_MATRIX!$E$2,F$1+1)))) -> 0 | G8: =IF(OR($A8>DESIGN_MATRIX!$E$3,G$1>DESIGN_MATRIX!$E$3),"",CORREL(INDIRECT("DESIGN_MATRIX!"&ADDRESS(7,$A8+1)&":"&ADDRESS(6+DESIGN_MATRIX!$E$2,$A8+1)),INDIRECT("DESIGN_MATRIX!"&ADDRESS(7,G$1+1)&":"&ADDRESS(6+DESIGN_MATRIX!$E$2,G$1+1)))) -> 0 | H8: =IF(OR($A8>DESIGN_MATRIX!$E$3,H$1>DESIGN_MATRIX!$E$3),"",CORREL(INDIRECT("DESIGN_MATRIX!"&ADDRESS(7,$A8+1)&":"&ADDRESS(6+DESIGN_MATRIX!$E$2,$A8+1)),INDIRECT("DESIGN_MATRIX!"&ADDRESS(7,H$1+1)&":"&ADDRESS(6+DESIGN_MATRIX!$E$2,H$1+1)))) -> 1 | I8: =IF(OR($A8>DESIGN_MATRIX!$E$3,I$1>DESIGN_MATRIX!$E$3),"",CORREL(INDIRECT("DESIGN_MATRIX!"&ADDRESS(7,$A8+1)&":"&ADDRESS(6+DESIGN_MATRIX!$E$2,$A8+1)),INDIRECT("DESIGN_MATRIX!"&ADDRESS(7,I$1+1)&":"&ADDRESS(6+DESIGN_MATRIX!$E$2,I$1+1)))) -> 0 | ... CV8: =IF(OR($A8>DESIGN_MATRIX!$E$3,CV$1>DESIGN_MATRIX!$E$3),"",CORREL(INDIRECT("DESIGN_MATRIX!"&ADDRESS(7,$A8+1)&":"&ADDRESS(6+DESIGN_MATRIX!$E$2,$A8+1)),INDIRECT("DESIGN_MATRIX!"&ADDRESS(7,CV$1+1)&":"&ADDRESS(6+DESIGN_MATRIX!$E$2,CV$1+1))))
A9: 8 | B9: =IF(OR($A9>DESIGN_MATRIX!$E$3,B$1>DESIGN_MATRIX!$E$3),"",CORREL(INDIRECT("DESIGN_MATRIX!"&ADDRESS(7,$A9+1)&":"&ADDRESS(6+DESIGN_MATRIX!$E$2,$A9+1)),INDIRECT("DESIGN_MATRIX!"&ADDRESS(7,B$1+1)&":"&ADDRESS(6+DESIGN_MATRIX!$E$2,B$1+1)))) -> 0 | C9: =IF(OR($A9>DESIGN_MATRIX!$E$3,C$1>DESIGN_MATRIX!$E$3),"",CORREL(INDIRECT("DESIGN_MATRIX!"&ADDRESS(7,$A9+1)&":"&ADDRESS(6+DESIGN_MATRIX!$E$2,$A9+1)),INDIRECT("DESIGN_MATRIX!"&ADDRESS(7,C$1+1)&":"&ADDRESS(6+DESIGN_MATRIX!$E$2,C$1+1)))) -> 0 | D9: =IF(OR($A9>DESIGN_MATRIX!$E$3,D$1>DESIGN_MATRIX!$E$3),"",CORREL(INDIRECT("DESIGN_MATRIX!"&ADDRESS(7,$A9+1)&":"&ADDRESS(6+DESIGN_MATRIX!$E$2,$A9+1)),INDIRECT("DESIGN_MATRIX!"&ADDRESS(7,D$1+1)&":"&ADDRESS(6+DESIGN_MATRIX!$E$2,D$1+1)))) -> 0 | E9: =IF(OR($A9>DESIGN_MATRIX!$E$3,E$1>DESIGN_MATRIX!$E$3),"",CORREL(INDIRECT("DESIGN_MATRIX!"&ADDRESS(7,$A9+1)&":"&ADDRESS(6+DESIGN_MATRIX!$E$2,$A9+1)),INDIRECT("DESIGN_MATRIX!"&ADDRESS(7,E$1+1)&":"&ADDRESS(6+DESIGN_MATRIX!$E$2,E$1+1)))) -> 0 | F9: =IF(OR($A9>DESIGN_MATRIX!$E$3,F$1>DESIGN_MATRIX!$E$3),"",CORREL(INDIRECT("DESIGN_MATRIX!"&ADDRESS(7,$A9+1)&":"&ADDRESS(6+DESIGN_MATRIX!$E$2,$A9+1)),INDIRECT("DESIGN_MATRIX!"&ADDRESS(7,F$1+1)&":"&ADDRESS(6+DESIGN_MATRIX!$E$2,F$1+1)))) -> 0 | G9: =IF(OR($A9>DESIGN_MATRIX!$E$3,G$1>DESIGN_MATRIX!$E$3),"",CORREL(INDIRECT("DESIGN_MATRIX!"&ADDRESS(7,$A9+1)&":"&ADDRESS(6+DESIGN_MATRIX!$E$2,$A9+1)),INDIRECT("DESIGN_MATRIX!"&ADDRESS(7,G$1+1)&":"&ADDRESS(6+DESIGN_MATRIX!$E$2,G$1+1)))) -> 0 | H9: =IF(OR($A9>DESIGN_MATRIX!$E$3,H$1>DESIGN_MATRIX!$E$3),"",CORREL(INDIRECT("DESIGN_MATRIX!"&ADDRESS(7,$A9+1)&":"&ADDRESS(6+DESIGN_MATRIX!$E$2,$A9+1)),INDIRECT("DESIGN_MATRIX!"&ADDRESS(7,H$1+1)&":"&ADDRESS(6+DESIGN_MATRIX!$E$2,H$1+1)))) -> 0 | I9: =IF(OR($A9>DESIGN_MATRIX!$E$3,I$1>DESIGN_MATRIX!$E$3),"",CORREL(INDIRECT("DESIGN_MATRIX!"&ADDRESS(7,$A9+1)&":"&ADDRESS(6+DESIGN_MATRIX!$E$2,$A9+1)),INDIRECT("DESIGN_MATRIX!"&ADDRESS(7,I$1+1)&":"&ADDRESS(6+DESIGN_MATRIX!$E$2,I$1+1)))) -> 1 | ... CV9: =IF(OR($A9>DESIGN_MATRIX!$E$3,CV$1>DESIGN_MATRIX!$E$3),"",CORREL(INDIRECT("DESIGN_MATRIX!"&ADDRESS(7,$A9+1)&":"&ADDRESS(6+DESIGN_MATRIX!$E$2,$A9+1)),INDIRECT("DESIGN_MATRIX!"&ADDRESS(7,CV$1+1)&":"&ADDRESS(6+DESIGN_MATRIX!$E$2,CV$1+1))))
A10: 9 | B10: =IF(OR($A10>DESIGN_MATRIX!$E$3,B$1>DESIGN_MATRIX!$E$3),"",CORREL(INDIRECT("DESIGN_MATRIX!"&ADDRESS(7,$A10+1)&":"&ADDRESS(6+DESIGN_MATRIX!$E$2,$A10+1)),INDIRECT("DESIGN_MATRIX!"&ADDRESS(7,B$1+1)&":"&ADDRESS(6+DESIGN_MATRIX!$E$2,B$1+1)))) -> 0 | C10: =IF(OR($A10>DESIGN_MATRIX!$E$3,C$1>DESIGN_MATRIX!$E$3),"",CORREL(INDIRECT("DESIGN_MATRIX!"&ADDRESS(7,$A10+1)&":"&ADDRESS(6+DESIGN_MATRIX!$E$2,$A10+1)),INDIRECT("DESIGN_MATRIX!"&ADDRESS(7,C$1+1)&":"&ADDRESS(6+DESIGN_MATRIX!$E$2,C$1+1)))) -> 0 | D10: =IF(OR($A10>DESIGN_MATRIX!$E$3,D$1>DESIGN_MATRIX!$E$3),"",CORREL(INDIRECT("DESIGN_MATRIX!"&ADDRESS(7,$A10+1)&":"&ADDRESS(6+DESIGN_MATRIX!$E$2,$A10+1)),INDIRECT("DESIGN_MATRIX!"&ADDRESS(7,D$1+1)&":"&ADDRESS(6+DESIGN_MATRIX!$E$2,D$1+1)))) -> 0 | E10: =IF(OR($A10>DESIGN_MATRIX!$E$3,E$1>DESIGN_MATRIX!$E$3),"",CORREL(INDIRECT("DESIGN_MATRIX!"&ADDRESS(7,$A10+1)&":"&ADDRESS(6+DESIGN_MATRIX!$E$2,$A10+1)),INDIRECT("DESIGN_MATRIX!"&ADDRESS(7,E$1+1)&":"&ADDRESS(6+DESIGN_MATRIX!$E$2,E$1+1)))) -> 0 | F10: =IF(OR($A10>DESIGN_MATRIX!$E$3,F$1>DESIGN_MATRIX!$E$3),"",CORREL(INDIRECT("DESIGN_MATRIX!"&ADDRESS(7,$A10+1)&":"&ADDRESS(6+DESIGN_MATRIX!$E$2,$A10+1)),INDIRECT("DESIGN_MATRIX!"&ADDRESS(7,F$1+1)&":"&ADDRESS(6+DESIGN_MATRIX!$E$2,F$1+1)))) -> 0 | G10: =IF(OR($A10>DESIGN_MATRIX!$E$3,G$1>DESIGN_MATRIX!$E$3),"",CORREL(INDIRECT("DESIGN_MATRIX!"&ADDRESS(7,$A10+1)&":"&ADDRESS(6+DESIGN_MATRIX!$E$2,$A10+1)),INDIRECT("DESIGN_MATRIX!"&ADDRESS(7,G$1+1)&":"&ADDRESS(6+DESIGN_MATRIX!$E$2,G$1+1)))) -> 0 | H10: =IF(OR($A10>DESIGN_MATRIX!$E$3,H$1>DESIGN_MATRIX!$E$3),"",CORREL(INDIRECT("DESIGN_MATRIX!"&ADDRESS(7,$A10+1)&":"&ADDRESS(6+DESIGN_MATRIX!$E$2,$A10+1)),INDIRECT("DESIGN_MATRIX!"&ADDRESS(7,H$1+1)&":"&ADDRESS(6+DESIGN_MATRIX!$E$2,H$1+1)))) -> 0 | I10: =IF(OR($A10>DESIGN_MATRIX!$E$3,I$1>DESIGN_MATRIX!$E$3),"",CORREL(INDIRECT("DESIGN_MATRIX!"&ADDRESS(7,$A10+1)&":"&ADDRESS(6+DESIGN_MATRIX!$E$2,$A10+1)),INDIRECT("DESIGN_MATRIX!"&ADDRESS(7,I$1+1)&":"&ADDRESS(6+DESIGN_MATRIX!$E$2,I$1+1)))) -> 0 | ... CV10: =IF(OR($A10>DESIGN_MATRIX!$E$3,CV$1>DESIGN_MATRIX!$E$3),"",CORREL(INDIRECT("DESIGN_MATRIX!"&ADDRESS(7,$A10+1)&":"&ADDRESS(6+DESIGN_MATRIX!$E$2,$A10+1)),INDIRECT("DESIGN_MATRIX!"&ADDRESS(7,CV$1+1)&":"&ADDRESS(6+DESIGN_MATRIX!$E$2,CV$1+1))))
A11: 10 | B11: =IF(OR($A11>DESIGN_MATRIX!$E$3,B$1>DESIGN_MATRIX!$E$3),"",CORREL(INDIRECT("DESIGN_MATRIX!"&ADDRESS(7,$A11+1)&":"&ADDRESS(6+DESIGN_MATRIX!$E$2,$A11+1)),INDIRECT("DESIGN_MATRIX!"&ADDRESS(7,B$1+1)&":"&ADDRESS(6+DESIGN_MATRIX!$E$2,B$1+1)))) -> 0 | C11: =IF(OR($A11>DESIGN_MATRIX!$E$3,C$1>DESIGN_MATRIX!$E$3),"",CORREL(INDIRECT("DESIGN_MATRIX!"&ADDRESS(7,$A11+1)&":"&ADDRESS(6+DESIGN_MATRIX!$E$2,$A11+1)),INDIRECT("DESIGN_MATRIX!"&ADDRESS(7,C$1+1)&":"&ADDRESS(6+DESIGN_MATRIX!$E$2,C$1+1)))) -> 0 | D11: =IF(OR($A11>DESIGN_MATRIX!$E$3,D$1>DESIGN_MATRIX!$E$3),"",CORREL(INDIRECT("DESIGN_MATRIX!"&ADDRESS(7,$A11+1)&":"&ADDRESS(6+DESIGN_MATRIX!$E$2,$A11+1)),INDIRECT("DESIGN_MATRIX!"&ADDRESS(7,D$1+1)&":"&ADDRESS(6+DESIGN_MATRIX!$E$2,D$1+1)))) -> 0 | E11: =IF(OR($A11>DESIGN_MATRIX!$E$3,E$1>DESIGN_MATRIX!$E$3),"",CORREL(INDIRECT("DESIGN_MATRIX!"&ADDRESS(7,$A11+1)&":"&ADDRESS(6+DESIGN_MATRIX!$E$2,$A11+1)),INDIRECT("DESIGN_MATRIX!"&ADDRESS(7,E$1+1)&":"&ADDRESS(6+DESIGN_MATRIX!$E$2,E$1+1)))) -> 0 | F11: =IF(OR($A11>DESIGN_MATRIX!$E$3,F$1>DESIGN_MATRIX!$E$3),"",CORREL(INDIRECT("DESIGN_MATRIX!"&ADDRESS(7,$A11+1)&":"&ADDRESS(6+DESIGN_MATRIX!$E$2,$A11+1)),INDIRECT("DESIGN_MATRIX!"&ADDRESS(7,F$1+1)&":"&ADDRESS(6+DESIGN_MATRIX!$E$2,F$1+1)))) -> 0 | G11: =IF(OR($A11>DESIGN_MATRIX!$E$3,G$1>DESIGN_MATRIX!$E$3),"",CORREL(INDIRECT("DESIGN_MATRIX!"&ADDRESS(7,$A11+1)&":"&ADDRESS(6+DESIGN_MATRIX!$E$2,$A11+1)),INDIRECT("DESIGN_MATRIX!"&ADDRESS(7,G$1+1)&":"&ADDRESS(6+DESIGN_MATRIX!$E$2,G$1+1)))) -> 0 | H11: =IF(OR($A11>DESIGN_MATRIX!$E$3,H$1>DESIGN_MATRIX!$E$3),"",CORREL(INDIRECT("DESIGN_MATRIX!"&ADDRESS(7,$A11+1)&":"&ADDRESS(6+DESIGN_MATRIX!$E$2,$A11+1)),INDIRECT("DESIGN_MATRIX!"&ADDRESS(7,H$1+1)&":"&ADDRESS(6+DESIGN_MATRIX!$E$2,H$1+1)))) -> 0 | I11: =IF(OR($A11>DESIGN_MATRIX!$E$3,I$1>DESIGN_MATRIX!$E$3),"",CORREL(INDIRECT("DESIGN_MATRIX!"&ADDRESS(7,$A11+1)&":"&ADDRESS(6+DESIGN_MATRIX!$E$2,$A11+1)),INDIRECT("DESIGN_MATRIX!"&ADDRESS(7,I$1+1)&":"&ADDRESS(6+DESIGN_MATRIX!$E$2,I$1+1)))) -> 0 | ... CV11: =IF(OR($A11>DESIGN_MATRIX!$E$3,CV$1>DESIGN_MATRIX!$E$3),"",CORREL(INDIRECT("DESIGN_MATRIX!"&ADDRESS(7,$A11+1)&":"&ADDRESS(6+DESIGN_MATRIX!$E$2,$A11+1)),INDIRECT("DESIGN_MATRIX!"&ADDRESS(7,CV$1+1)&":"&ADDRESS(6+DESIGN_MATRIX!$E$2,CV$1+1))))
A12: 11 | B12: =IF(OR($A12>DESIGN_MATRIX!$E$3,B$1>DESIGN_MATRIX!$E$3),"",CORREL(INDIRECT("DESIGN_MATRIX!"&ADDRESS(7,$A12+1)&":"&ADDRESS(6+DESIGN_MATRIX!$E$2,$A12+1)),INDIRECT("DESIGN_MATRIX!"&ADDRESS(7,B$1+1)&":"&ADDRESS(6+DESIGN_MATRIX!$E$2,B$1+1)))) -> 0 | C12: =IF(OR($A12>DESIGN_MATRIX!$E$3,C$1>DESIGN_MATRIX!$E$3),"",CORREL(INDIRECT("DESIGN_MATRIX!"&ADDRESS(7,$A12+1)&":"&ADDRESS(6+DESIGN_MATRIX!$E$2,$A12+1)),INDIRECT("DESIGN_MATRIX!"&ADDRESS(7,C$1+1)&":"&ADDRESS(6+DESIGN_MATRIX!$E$2,C$1+1)))) -> 0 | D12: =IF(OR($A12>DESIGN_MATRIX!$E$3,D$1>DESIGN_MATRIX!$E$3),"",CORREL(INDIRECT("DESIGN_MATRIX!"&ADDRESS(7,$A12+1)&":"&ADDRESS(6+DESIGN_MATRIX!$E$2,$A12+1)),INDIRECT("DESIGN_MATRIX!"&ADDRESS(7,D$1+1)&":"&ADDRESS(6+DESIGN_MATRIX!$E$2,D$1+1)))) -> 0 | E12: =IF(OR($A12>DESIGN_MATRIX!$E$3,E$1>DESIGN_MATRIX!$E$3),"",CORREL(INDIRECT("DESIGN_MATRIX!"&ADDRESS(7,$A12+1)&":"&ADDRESS(6+DESIGN_MATRIX!$E$2,$A12+1)),INDIRECT("DESIGN_MATRIX!"&ADDRESS(7,E$1+1)&":"&ADDRESS(6+DESIGN_MATRIX!$E$2,E$1+1)))) -> 0 | F12: =IF(OR($A12>DESIGN_MATRIX!$E$3,F$1>DESIGN_MATRIX!$E$3),"",CORREL(INDIRECT("DESIGN_MATRIX!"&ADDRESS(7,$A12+1)&":"&ADDRESS(6+DESIGN_MATRIX!$E$2,$A12+1)),INDIRECT("DESIGN_MATRIX!"&ADDRESS(7,F$1+1)&":"&ADDRESS(6+DESIGN_MATRIX!$E$2,F$1+1)))) -> 0 | G12: =IF(OR($A12>DESIGN_MATRIX!$E$3,G$1>DESIGN_MATRIX!$E$3),"",CORREL(INDIRECT("DESIGN_MATRIX!"&ADDRESS(7,$A12+1)&":"&ADDRESS(6+DESIGN_MATRIX!$E$2,$A12+1)),INDIRECT("DESIGN_MATRIX!"&ADDRESS(7,G$1+1)&":"&ADDRESS(6+DESIGN_MATRIX!$E$2,G$1+1)))) -> 0 | H12: =IF(OR($A12>DESIGN_MATRIX!$E$3,H$1>DESIGN_MATRIX!$E$3),"",CORREL(INDIRECT("DESIGN_MATRIX!"&ADDRESS(7,$A12+1)&":"&ADDRESS(6+DESIGN_MATRIX!$E$2,$A12+1)),INDIRECT("DESIGN_MATRIX!"&ADDRESS(7,H$1+1)&":"&ADDRESS(6+DESIGN_MATRIX!$E$2,H$1+1)))) -> 0 | I12: =IF(OR($A12>DESIGN_MATRIX!$E$3,I$1>DESIGN_MATRIX!$E$3),"",CORREL(INDIRECT("DESIGN_MATRIX!"&ADDRESS(7,$A12+1)&":"&ADDRESS(6+DESIGN_MATRIX!$E$2,$A12+1)),INDIRECT("DESIGN_MATRIX!"&ADDRESS(7,I$1+1)&":"&ADDRESS(6+DESIGN_MATRIX!$E$2,I$1+1)))) -> 0 | ... CV12: =IF(OR($A12>DESIGN_MATRIX!$E$3,CV$1>DESIGN_MATRIX!$E$3),"",CORREL(INDIRECT("DESIGN_MATRIX!"&ADDRESS(7,$A12+1)&":"&ADDRESS(6+DESIGN_MATRIX!$E$2,$A12+1)),INDIRECT("DESIGN_MATRIX!"&ADDRESS(7,CV$1+1)&":"&ADDRESS(6+DESIGN_MATRIX!$E$2,CV$1+1))))
A13: 12 | B13: =IF(OR($A13>DESIGN_MATRIX!$E$3,B$1>DESIGN_MATRIX!$E$3),"",CORREL(INDIRECT("DESIGN_MATRIX!"&ADDRESS(7,$A13+1)&":"&ADDRESS(6+DESIGN_MATRIX!$E$2,$A13+1)),INDIRECT("DESIGN_MATRIX!"&ADDRESS(7,B$1+1)&":"&ADDRESS(6+DESIGN_MATRIX!$E$2,B$1+1)))) -> 0 | C13: =IF(OR($A13>DESIGN_MATRIX!$E$3,C$1>DESIGN_MATRIX!$E$3),"",CORREL(INDIRECT("DESIGN_MATRIX!"&ADDRESS(7,$A13+1)&":"&ADDRESS(6+DESIGN_MATRIX!$E$2,$A13+1)),INDIRECT("DESIGN_MATRIX!"&ADDRESS(7,C$1+1)&":"&ADDRESS(6+DESIGN_MATRIX!$E$2,C$1+1)))) -> 0 | D13: =IF(OR($A13>DESIGN_MATRIX!$E$3,D$1>DESIGN_MATRIX!$E$3),"",CORREL(INDIRECT("DESIGN_MATRIX!"&ADDRESS(7,$A13+1)&":"&ADDRESS(6+DESIGN_MATRIX!$E$2,$A13+1)),INDIRECT("DESIGN_MATRIX!"&ADDRESS(7,D$1+1)&":"&ADDRESS(6+DESIGN_MATRIX!$E$2,D$1+1)))) -> 0 | E13: =IF(OR($A13>DESIGN_MATRIX!$E$3,E$1>DESIGN_MATRIX!$E$3),"",CORREL(INDIRECT("DESIGN_MATRIX!"&ADDRESS(7,$A13+1)&":"&ADDRESS(6+DESIGN_MATRIX!$E$2,$A13+1)),INDIRECT("DESIGN_MATRIX!"&ADDRESS(7,E$1+1)&":"&ADDRESS(6+DESIGN_MATRIX!$E$2,E$1+1)))) -> 0 | F13: =IF(OR($A13>DESIGN_MATRIX!$E$3,F$1>DESIGN_MATRIX!$E$3),"",CORREL(INDIRECT("DESIGN_MATRIX!"&ADDRESS(7,$A13+1)&":"&ADDRESS(6+DESIGN_MATRIX!$E$2,$A13+1)),INDIRECT("DESIGN_MATRIX!"&ADDRESS(7,F$1+1)&":"&ADDRESS(6+DESIGN_MATRIX!$E$2,F$1+1)))) -> 0 | G13: =IF(OR($A13>DESIGN_MATRIX!$E$3,G$1>DESIGN_MATRIX!$E$3),"",CORREL(INDIRECT("DESIGN_MATRIX!"&ADDRESS(7,$A13+1)&":"&ADDRESS(6+DESIGN_MATRIX!$E$2,$A13+1)),INDIRECT("DESIGN_MATRIX!"&ADDRESS(7,G$1+1)&":"&ADDRESS(6+DESIGN_MATRIX!$E$2,G$1+1)))) -> 0 | H13: =IF(OR($A13>DESIGN_MATRIX!$E$3,H$1>DESIGN_MATRIX!$E$3),"",CORREL(INDIRECT("DESIGN_MATRIX!"&ADDRESS(7,$A13+1)&":"&ADDRESS(6+DESIGN_MATRIX!$E$2,$A13+1)),INDIRECT("DESIGN_MATRIX!"&ADDRESS(7,H$1+1)&":"&ADDRESS(6+DESIGN_MATRIX!$E$2,H$1+1)))) -> 0 | I13: =IF(OR($A13>DESIGN_MATRIX!$E$3,I$1>DESIGN_MATRIX!$E$3),"",CORREL(INDIRECT("DESIGN_MATRIX!"&ADDRESS(7,$A13+1)&":"&ADDRESS(6+DESIGN_MATRIX!$E$2,$A13+1)),INDIRECT("DESIGN_MATRIX!"&ADDRESS(7,I$1+1)&":"&ADDRESS(6+DESIGN_MATRIX!$E$2,I$1+1)))) -> 0 | ... CV13: =IF(OR($A13>DESIGN_MATRIX!$E$3,CV$1>DESIGN_MATRIX!$E$3),"",CORREL(INDIRECT("DESIGN_MATRIX!"&ADDRESS(7,$A13+1)&":"&ADDRESS(6+DESIGN_MATRIX!$E$2,$A13+1)),INDIRECT("DESIGN_MATRIX!"&ADDRESS(7,CV$1+1)&":"&ADDRESS(6+DESIGN_MATRIX!$E$2,CV$1+1))))
... A100: 99 | B100: =IF(OR($A100>DESIGN_MATRIX!$E$3,B$1>DESIGN_MATRIX!$E$3),"",CORREL(INDIRECT("DESIGN_MATRIX!"&ADDRESS(7,$A100+1)&":"&ADDRESS(6+DESIGN_MATRIX!$E$2,$A100+1)),INDIRECT("DESIGN_MATRIX!"&ADDRESS(7,B$1+1)&":"&ADDRESS(6+DESIGN_MATRIX!$E$2,B$1+1)))) | C100: =IF(OR($A100>DESIGN_MATRIX!$E$3,C$1>DESIGN_MATRIX!$E$3),"",CORREL(INDIRECT("DESIGN_MATRIX!"&ADDRESS(7,$A100+1)&":"&ADDRESS(6+DESIGN_MATRIX!$E$2,$A100+1)),INDIRECT("DESIGN_MATRIX!"&ADDRESS(7,C$1+1)&":"&ADDRESS(6+DESIGN_MATRIX!$E$2,C$1+1)))) | D100: =IF(OR($A100>DESIGN_MATRIX!$E$3,D$1>DESIGN_MATRIX!$E$3),"",CORREL(INDIRECT("DESIGN_MATRIX!"&ADDRESS(7,$A100+1)&":"&ADDRESS(6+DESIGN_MATRIX!$E$2,$A100+1)),INDIRECT("DESIGN_MATRIX!"&ADDRESS(7,D$1+1)&":"&ADDRESS(6+DESIGN_MATRIX!$E$2,D$1+1)))) | E100: =IF(OR($A100>DESIGN_MATRIX!$E$3,E$1>DESIGN_MATRIX!$E$3),"",CORREL(INDIRECT("DESIGN_MATRIX!"&ADDRESS(7,$A100+1)&":"&ADDRESS(6+DESIGN_MATRIX!$E$2,$A100+1)),INDIRECT("DESIGN_MATRIX!"&ADDRESS(7,E$1+1)&":"&ADDRESS(6+DESIGN_MATRIX!$E$2,E$1+1)))) | F100: =IF(OR($A100>DESIGN_MATRIX!$E$3,F$1>DESIGN_MATRIX!$E$3),"",CORREL(INDIRECT("DESIGN_MATRIX!"&ADDRESS(7,$A100+1)&":"&ADDRESS(6+DESIGN_MATRIX!$E$2,$A100+1)),INDIRECT("DESIGN_MATRIX!"&ADDRESS(7,F$1+1)&":"&ADDRESS(6+DESIGN_MATRIX!$E$2,F$1+1)))) | G100: =IF(OR($A100>DESIGN_MATRIX!$E$3,G$1>DESIGN_MATRIX!$E$3),"",CORREL(INDIRECT("DESIGN_MATRIX!"&ADDRESS(7,$A100+1)&":"&ADDRESS(6+DESIGN_MATRIX!$E$2,$A100+1)),INDIRECT("DESIGN_MATRIX!"&ADDRESS(7,G$1+1)&":"&ADDRESS(6+DESIGN_MATRIX!$E$2,G$1+1)))) | H100: =IF(OR($A100>DESIGN_MATRIX!$E$3,H$1>DESIGN_MATRIX!$E$3),"",CORREL(INDIRECT("DESIGN_MATRIX!"&ADDRESS(7,$A100+1)&":"&ADDRESS(6+DESIGN_MATRIX!$E$2,$A100+1)),INDIRECT("DESIGN_MATRIX!"&ADDRESS(7,H$1+1)&":"&ADDRESS(6+DESIGN_MATRIX!$E$2,H$1+1)))) | I100: =IF(OR($A100>DESIGN_MATRIX!$E$3,I$1>DESIGN_MATRIX!$E$3),"",CORREL(INDIRECT("DESIGN_MATRIX!"&ADDRESS(7,$A100+1)&":"&ADDRESS(6+DESIGN_MATRIX!$E$2,$A100+1)),INDIRECT("DESIGN_MATRIX!"&ADDRESS(7,I$1+1)&":"&ADDRESS(6+DESIGN_MATRIX!$E$2,I$1+1)))) | ... CV100: =IF(OR($A100>DESIGN_MATRIX!$E$3,CV$1>DESIGN_MATRIX!$E$3),"",CORREL(INDIRECT("DESIGN_MATRIX!"&ADDRESS(7,$A100+1)&":"&ADDRESS(6+DESIGN_MATRIX!$E$2,$A100+1)),INDIRECT("DESIGN_MATRIX!"&ADDRESS(7,CV$1+1)&":"&ADDRESS(6+DESIGN_MATRIX!$E$2,CV$1+1))))

Sheet IDENTITY_COUNT
A1: Expected count | D1: {=((DESIGN_MATRIX!E2*SUM(1/INDIRECT("B4:"&ADDRESS(4,DESIGN_MATRIX!E3+1))))^2+SUM(B5:CV5)-DESIGN_MATRIX!E2*DESIGN_MATRIX!E3^2)/2} -> 817668 | H1: Real count | K1: =SUM(B8:CW107) -> 817668 | P1: J-Optimality | T1: =2-K1/D1 -> 1
A4: Levels | B4: =COUNT(_xlfn.UNIQUE(DESIGN_MATRIX!B7:B106)) -> 4 | C4: =COUNT(_xlfn.UNIQUE(DESIGN_MATRIX!C7:C106)) -> 3 | D4: =COUNT(_xlfn.UNIQUE(DESIGN_MATRIX!D7:D106)) -> 3 | E4: =COUNT(_xlfn.UNIQUE(DESIGN_MATRIX!E7:E106)) -> 3 | F4: =COUNT(_xlfn.UNIQUE(DESIGN_MATRIX!F7:F106)) -> 3 | G4: =COUNT(_xlfn.UNIQUE(DESIGN_MATRIX!G7:G106)) -> 3 | H4: =COUNT(_xlfn.UNIQUE(DESIGN_MATRIX!H7:H106)) -> 3 | I4: =COUNT(_xlfn.UNIQUE(DESIGN_MATRIX!I7:I106)) -> 3 | ... CV4: =COUNT(_xlfn.UNIQUE(DESIGN_MATRIX!CV7:CV106)) -> 0
B5: =IFERROR((B4-1)*(DESIGN_MATRIX!$E$2/B4)^2,0) -> 972 | C5: =IFERROR((C4-1)*(DESIGN_MATRIX!$E$2/C4)^2,0) -> 1152 | D5: =IFERROR((D4-1)*(DESIGN_MATRIX!$E$2/D4)^2,0) -> 1152 | E5: =IFERROR((E4-1)*(DESIGN_MATRIX!$E$2/E4)^2,0) -> 1152 | F5: =IFERROR((F4-1)*(DESIGN_MATRIX!$E$2/F4)^2,0) -> 1152 | G5: =IFERROR((G4-1)*(DESIGN_MATRIX!$E$2/G4)^2,0) -> 1152 | H5: =IFERROR((H4-1)*(DESIGN_MATRIX!$E$2/H4)^2,0) -> 1152 | I5: =IFERROR((I4-1)*(DESIGN_MATRIX!$E$2/I4)^2,0) -> 1152 | ... CV5: =IFERROR((CV4-1)*(DESIGN_MATRIX!$E$2/CV4)^2,0) -> 0
B7: 1 | C7: 2 | D7: 3 | E7: 4 | F7: 5 | G7: 6 | H7: 7 | I7: 8 | J7: 9 | K7: 10 | L7: 11 | M7: 12 | N7: 13 | O7: 14 | P7: 15 | Q7: 16 | R7: 17 | S7: 18 | T7: 19 | U7: 20 | V7: 21 | W7: 22 | X7: 23 | Y7: 24 | Z7: 25 | AA7: 26 | AB7: 27 | AC7: 28 | AD7: 29 | AE7: 30 | AF7: 31 | AG7: 32 | AH7: 33 | AI7: 34 | AJ7: 35 | AK7: 36 | AL7: 37 | AM7: 38 | AN7: 39 | AO7: 40 | AP7: 41 | AQ7: 42 | AR7: 43 | AS7: 44 | AT7: 45 | AU7: 46 | AV7: 47 | AW7: 48 | AX7: 49 | AY7: 50 | AZ7: 51 | BA7: 52 | BB7: 53 | BC7: 54 | BD7: 55 | BE7: 56 | BF7: 57 | BG7: 58 | BH7: 59 | BI7: 60 | BJ7: 61 | BK7: 62 | BL7: 63 | BM7: 64 | BN7: 65 | BO7: 66 | BP7: 67 | BQ7: 68 | BR7: 69 | BS7: 70 | BT7: 71 | BU7: 72 | BV7: 73 | BW7: 74 | BX7: 75 | BY7: 76 | BZ7: 77 | CA7: 78 | CB7: 79 | CC7: 80 | CD7: 81 | CE7: 82 | CF7: 83 | CG7: 84 | CH7: 85 | CI7: 86 | CJ7: 87 | CK7: 88 | CL7: 89 | CM7: 90 | CN7: 91 | CO7: 92 | CP7: 93 | CQ7: 94 | CR7: 95 | CS7: 96 | CT7: 97 | CU7: 98 | CV7: 99 | CW7: 100
A8: 1 | B8: {=IF(AND($A8<B$7,B$7<=DESIGN_MATRIX!$E$2),SUM(IF(INDIRECT("DESIGN_MATRIX!"&ADDRESS(ROW(DESIGN_MATRIX!$B$6)+$A8,2)&":"&ADDRESS(ROW(DESIGN_MATRIX!$B$6)+$A8,1+DESIGN_MATRIX!$E$3))=INDIRECT("DESIGN_MATRIX!"&ADDRESS(ROW(DESIGN_MATRIX!$B$6)+B$7,2)&":"&ADDRESS(ROW(DESIGN_MATRIX!$B$6)+B$7,1+DESIGN_MATRIX!$E$3)),1,0))^2,"")} | C8: {=IF(AND($A8<C$7,C$7<=DESIGN_MATRIX!$E$2),SUM(IF(INDIRECT("DESIGN_MATRIX!"&ADDRESS(ROW(DESIGN_MATRIX!$B$6)+$A8,2)&":"&ADDRESS(ROW(DESIGN_MATRIX!$B$6)+$A8,1+DESIGN_MATRIX!$E$3))=INDIRECT("DESIGN_MATRIX!"&ADDRESS(ROW(DESIGN_MATRIX!$B$6)+C$7,2)&":"&ADDRESS(ROW(DESIGN_MATRIX!$B$6)+C$7,1+DESIGN_MATRIX!$E$3)),1,0))^2,"")} -> 324 | D8: {=IF(AND($A8<D$7,D$7<=DESIGN_MATRIX!$E$2),SUM(IF(INDIRECT("DESIGN_MATRIX!"&ADDRESS(ROW(DESIGN_MATRIX!$B$6)+$A8,2)&":"&ADDRESS(ROW(DESIGN_MATRIX!$B$6)+$A8,1+DESIGN_MATRIX!$E$3))=INDIRECT("DESIGN_MATRIX!"&ADDRESS(ROW(DESIGN_MATRIX!$B$6)+D$7,2)&":"&ADDRESS(ROW(DESIGN_MATRIX!$B$6)+D$7,1+DESIGN_MATRIX!$E$3)),1,0))^2,"")} -> 289 | E8: {=IF(AND($A8<E$7,E$7<=DESIGN_MATRIX!$E$2),SUM(IF(INDIRECT("DESIGN_MATRIX!"&ADDRESS(ROW(DESIGN_MATRIX!$B$6)+$A8,2)&":"&ADDRESS(ROW(DESIGN_MATRIX!$B$6)+$A8,1+DESIGN_MATRIX!$E$3))=INDIRECT("DESIGN_MATRIX!"&ADDRESS(ROW(DESIGN_MATRIX!$B$6)+E$7,2)&":"&ADDRESS(ROW(DESIGN_MATRIX!$B$6)+E$7,1+DESIGN_MATRIX!$E$3)),1,0))^2,"")} -> 324 | F8: {=IF(AND($A8<F$7,F$7<=DESIGN_MATRIX!$E$2),SUM(IF(INDIRECT("DESIGN_MATRIX!"&ADDRESS(ROW(DESIGN_MATRIX!$B$6)+$A8,2)&":"&ADDRESS(ROW(DESIGN_MATRIX!$B$6)+$A8,1+DESIGN_MATRIX!$E$3))=INDIRECT("DESIGN_MATRIX!"&ADDRESS(ROW(DESIGN_MATRIX!$B$6)+F$7,2)&":"&ADDRESS(ROW(DESIGN_MATRIX!$B$6)+F$7,1+DESIGN_MATRIX!$E$3)),1,0))^2,"")} -> 324 | G8: {=IF(AND($A8<G$7,G$7<=DESIGN_MATRIX!$E$2),SUM(IF(INDIRECT("DESIGN_MATRIX!"&ADDRESS(ROW(DESIGN_MATRIX!$B$6)+$A8,2)&":"&ADDRESS(ROW(DESIGN_MATRIX!$B$6)+$A8,1+DESIGN_MATRIX!$E$3))=INDIRECT("DESIGN_MATRIX!"&ADDRESS(ROW(DESIGN_MATRIX!$B$6)+G$7,2)&":"&ADDRESS(ROW(DESIGN_MATRIX!$B$6)+G$7,1+DESIGN_MATRIX!$E$3)),1,0))^2,"")} -> 324 | H8: {=IF(AND($A8<H$7,H$7<=DESIGN_MATRIX!$E$2),SUM(IF(INDIRECT("DESIGN_MATRIX!"&ADDRESS(ROW(DESIGN_MATRIX!$B$6)+$A8,2)&":"&ADDRESS(ROW(DESIGN_MATRIX!$B$6)+$A8,1+DESIGN_MATRIX!$E$3))=INDIRECT("DESIGN_MATRIX!"&ADDRESS(ROW(DESIGN_MATRIX!$B$6)+H$7,2)&":"&ADDRESS(ROW(DESIGN_MATRIX!$B$6)+H$7,1+DESIGN_MATRIX!$E$3)),1,0))^2,"")} -> 324 | I8: {=IF(AND($A8<I$7,I$7<=DESIGN_MATRIX!$E$2),SUM(IF(INDIRECT("DESIGN_MATRIX!"&ADDRESS(ROW(DESIGN_MATRIX!$B$6)+$A8,2)&":"&ADDRESS(ROW(DESIGN_MATRIX!$B$6)+$A8,1+DESIGN_MATRIX!$E$3))=INDIRECT("DESIGN_MATRIX!"&ADDRESS(ROW(DESIGN_MATRIX!$B$6)+I$7,2)&":"&ADDRESS(ROW(DESIGN_MATRIX!$B$6)+I$7,1+DESIGN_MATRIX!$E$3)),1,0))^2,"")} -> 324 | ... CW8: {=IF(AND($A8<CW$7,CW$7<=DESIGN_MATRIX!$E$2),SUM(IF(INDIRECT("DESIGN_MATRIX!"&ADDRESS(ROW(DESIGN_MATRIX!$B$6)+$A8,2)&":"&ADDRESS(ROW(DESIGN_MATRIX!$B$6)+$A8,1+DESIGN_MATRIX!$E$3))=INDIRECT("DESIGN_MATRIX!"&ADDRESS(ROW(DESIGN_MATRIX!$B$6)+CW$7,2)&":"&ADDRESS(ROW(DESIGN_MATRIX!$B$6)+CW$7,1+DESIGN_MATRIX!$E$3)),1,0))^2,"")}
A9: 2 | B9: {=IF(AND($A9<B$7,B$7<=DESIGN_MATRIX!$E$2),SUM(IF(INDIRECT("DESIGN_MATRIX!"&ADDRESS(ROW(DESIGN_MATRIX!$B$6)+$A9,2)&":"&ADDRESS(ROW(DESIGN_MATRIX!$B$6)+$A9,1+DESIGN_MATRIX!$E$3))=INDIRECT("DESIGN_MATRIX!"&ADDRESS(ROW(DESIGN_MATRIX!$B$6)+B$7,2)&":"&ADDRESS(ROW(DESIGN_MATRIX!$B$6)+B$7,1+DESIGN_MATRIX!$E$3)),1,0))^2,"")} | C9: {=IF(AND($A9<C$7,C$7<=DESIGN_MATRIX!$E$2),SUM(IF(INDIRECT("DESIGN_MATRIX!"&ADDRESS(ROW(DESIGN_MATRIX!$B$6)+$A9,2)&":"&ADDRESS(ROW(DESIGN_MATRIX!$B$6)+$A9,1+DESIGN_MATRIX!$E$3))=INDIRECT("DESIGN_MATRIX!"&ADDRESS(ROW(DESIGN_MATRIX!$B$6)+C$7,2)&":"&ADDRESS(ROW(DESIGN_MATRIX!$B$6)+C$7,1+DESIGN_MATRIX!$E$3)),1,0))^2,"")} | D9: {=IF(AND($A9<D$7,D$7<=DESIGN_MATRIX!$E$2),SUM(IF(INDIRECT("DESIGN_MATRIX!"&ADDRESS(ROW(DESIGN_MATRIX!$B$6)+$A9,2)&":"&ADDRESS(ROW(DESIGN_MATRIX!$B$6)+$A9,1+DESIGN_MATRIX!$E$3))=INDIRECT("DESIGN_MATRIX!"&ADDRESS(ROW(DESIGN_MATRIX!$B$6)+D$7,2)&":"&ADDRESS(ROW(DESIGN_MATRIX!$B$6)+D$7,1+DESIGN_MATRIX!$E$3)),1,0))^2,"")} -> 324 | E9: {=IF(AND($A9<E$7,E$7<=DESIGN_MATRIX!$E$2),SUM(IF(INDIRECT("DESIGN_MATRIX!"&ADDRESS(ROW(DESIGN_MATRIX!$B$6)+$A9,2)&":"&ADDRESS(ROW(DESIGN_MATRIX!$B$6)+$A9,1+DESIGN_MATRIX!$E$3))=INDIRECT("DESIGN_MATRIX!"&ADDRESS(ROW(DESIGN_MATRIX!$B$6)+E$7,2)&":"&ADDRESS(ROW(DESIGN_MATRIX!$B$6)+E$7,1+DESIGN_MATRIX!$E$3)),1,0))^2,"")} -> 289 | F9: {=IF(AND($A9<F$7,F$7<=DESIGN_MATRIX!$E$2),SUM(IF(INDIRECT("DESIGN_MATRIX!"&ADDRESS(ROW(DESIGN_MATRIX!$B$6)+$A9,2)&":"&ADDRESS(ROW(DESIGN_MATRIX!$B$6)+$A9,1+DESIGN_MATRIX!$E$3))=INDIRECT("DESIGN_MATRIX!"&ADDRESS(ROW(DESIGN_MATRIX!$B$6)+F$7,2)&":"&ADDRESS(ROW(DESIGN_MATRIX!$B$6)+F$7,1+DESIGN_MATRIX!$E$3)),1,0))^2,"")} -> 324 | G9: {=IF(AND($A9<G$7,G$7<=DESIGN_MATRIX!$E$2),SUM(IF(INDIRECT("DESIGN_MATRIX!"&ADDRESS(ROW(DESIGN_MATRIX!$B$6)+$A9,2)&":"&ADDRESS(ROW(DESIGN_MATRIX!$B$6)+$A9,1+DESIGN_MATRIX!$E$3))=INDIRECT("DESIGN_MATRIX!"&ADDRESS(ROW(DESIGN_MATRIX!$B$6)+G$7,2)&":"&ADDRESS(ROW(DESIGN_MATRIX!$B$6)+G$7,1+DESIGN_MATRIX!$E$3)),1,0))^2,"")} -> 324 | H9: {=IF(AND($A9<H$7,H$7<=DESIGN_MATRIX!$E$2),SUM(IF(INDIRECT("DESIGN_MATRIX!"&ADDRESS(ROW(DESIGN_MATRIX!$B$6)+$A9,2)&":"&ADDRESS(ROW(DESIGN_MATRIX!$B$6)+$A9,1+DESIGN_MATRIX!$E$3))=INDIRECT("DESIGN_MATRIX!"&ADDRESS(ROW(DESIGN_MATRIX!$B$6)+H$7,2)&":"&ADDRESS(ROW(DESIGN_MATRIX!$B$6)+H$7,1+DESIGN_MATRIX!$E$3)),1,0))^2,"")} -> 324 | I9: {=IF(AND($A9<I$7,I$7<=DESIGN_MATRIX!$E$2),SUM(IF(INDIRECT("DESIGN_MATRIX!"&ADDRESS(ROW(DESIGN_MATRIX!$B$6)+$A9,2)&":"&ADDRESS(ROW(DESIGN_MATRIX!$B$6)+$A9,1+DESIGN_MATRIX!$E$3))=INDIRECT("DESIGN_MATRIX!"&ADDRESS(ROW(DESIGN_MATRIX!$B$6)+I$7,2)&":"&ADDRESS(ROW(DESIGN_MATRIX!$B$6)+I$7,1+DESIGN_MATRIX!$E$3)),1,0))^2,"")} -> 324 | ... CW9: {=IF(AND($A9<CW$7,CW$7<=DESIGN_MATRIX!$E$2),SUM(IF(INDIRECT("DESIGN_MATRIX!"&ADDRESS(ROW(DESIGN_MATRIX!$B$6)+$A9,2)&":"&ADDRESS(ROW(DESIGN_MATRIX!$B$6)+$A9,1+DESIGN_MATRIX!$E$3))=INDIRECT("DESIGN_MATRIX!"&ADDRESS(ROW(DESIGN_MATRIX!$B$6)+CW$7,2)&":"&ADDRESS(ROW(DESIGN_MATRIX!$B$6)+CW$7,1+DESIGN_MATRIX!$E$3)),1,0))^2,"")}
A10: 3 | B10: {=IF(AND($A10<B$7,B$7<=DESIGN_MATRIX!$E$2),SUM(IF(INDIRECT("DESIGN_MATRIX!"&ADDRESS(ROW(DESIGN_MATRIX!$B$6)+$A10,2)&":"&ADDRESS(ROW(DESIGN_MATRIX!$B$6)+$A10,1+DESIGN_MATRIX!$E$3))=INDIRECT("DESIGN_MATRIX!"&ADDRESS(ROW(DESIGN_MATRIX!$B$6)+B$7,2)&":"&ADDRESS(ROW(DESIGN_MATRIX!$B$6)+B$7,1+DESIGN_MATRIX!$E$3)),1,0))^2,"")} | C10: {=IF(AND($A10<C$7,C$7<=DESIGN_MATRIX!$E$2),SUM(IF(INDIRECT("DESIGN_MATRIX!"&ADDRESS(ROW(DESIGN_MATRIX!$B$6)+$A10,2)&":"&ADDRESS(ROW(DESIGN_MATRIX!$B$6)+$A10,1+DESIGN_MATRIX!$E$3))=INDIRECT("DESIGN_MATRIX!"&ADDRESS(ROW(DESIGN_MATRIX!$B$6)+C$7,2)&":"&ADDRESS(ROW(DESIGN_MATRIX!$B$6)+C$7,1+DESIGN_MATRIX!$E$3)),1,0))^2,"")} | D10: {=IF(AND($A10<D$7,D$7<=DESIGN_MATRIX!$E$2),SUM(IF(INDIRECT("DESIGN_MATRIX!"&ADDRESS(ROW(DESIGN_MATRIX!$B$6)+$A10,2)&":"&ADDRESS(ROW(DESIGN_MATRIX!$B$6)+$A10,1+DESIGN_MATRIX!$E$3))=INDIRECT("DESIGN_MATRIX!"&ADDRESS(ROW(DESIGN_MATRIX!$B$6)+D$7,2)&":"&ADDRESS(ROW(DESIGN_MATRIX!$B$6)+D$7,1+DESIGN_MATRIX!$E$3)),1,0))^2,"")} | E10: {=IF(AND($A10<E$7,E$7<=DESIGN_MATRIX!$E$2),SUM(IF(INDIRECT("DESIGN_MATRIX!"&ADDRESS(ROW(DESIGN_MATRIX!$B$6)+$A10,2)&":"&ADDRESS(ROW(DESIGN_MATRIX!$B$6)+$A10,1+DESIGN_MATRIX!$E$3))=INDIRECT("DESIGN_MATRIX!"&ADDRESS(ROW(DESIGN_MATRIX!$B$6)+E$7,2)&":"&ADDRESS(ROW(DESIGN_MATRIX!$B$6)+E$7,1+DESIGN_MATRIX!$E$3)),1,0))^2,"")} -> 324 | F10: {=IF(AND($A10<F$7,F$7<=DESIGN_MATRIX!$E$2),SUM(IF(INDIRECT("DESIGN_MATRIX!"&ADDRESS(ROW(DESIGN_MATRIX!$B$6)+$A10,2)&":"&ADDRESS(ROW(DESIGN_MATRIX!$B$6)+$A10,1+DESIGN_MATRIX!$E$3))=INDIRECT("DESIGN_MATRIX!"&ADDRESS(ROW(DESIGN_MATRIX!$B$6)+F$7,2)&":"&ADDRESS(ROW(DESIGN_MATRIX!$B$6)+F$7,1+DESIGN_MATRIX!$E$3)),1,0))^2,"")} -> 324 | G10: {=IF(AND($A10<G$7,G$7<=DESIGN_MATRIX!$E$2),SUM(IF(INDIRECT("DESIGN_MATRIX!"&ADDRESS(ROW(DESIGN_MATRIX!$B$6)+$A10,2)&":"&ADDRESS(ROW(DESIGN_MATRIX!$B$6)+$A10,1+DESIGN_MATRIX!$E$3))=INDIRECT("DESIGN_MATRIX!"&ADDRESS(ROW(DESIGN_MATRIX!$B$6)+G$7,2)&":"&ADDRESS(ROW(DESIGN_MATRIX!$B$6)+G$7,1+DESIGN_MATRIX!$E$3)),1,0))^2,"")} -> 324 | H10: {=IF(AND($A10<H$7,H$7<=DESIGN_MATRIX!$E$2),SUM(IF(INDIRECT("DESIGN_MATRIX!"&ADDRESS(ROW(DESIGN_MATRIX!$B$6)+$A10,2)&":"&ADDRESS(ROW(DESIGN_MATRIX!$B$6)+$A10,1+DESIGN_MATRIX!$E$3))=INDIRECT("DESIGN_MATRIX!"&ADDRESS(ROW(DESIGN_MATRIX!$B$6)+H$7,2)&":"&ADDRESS(ROW(DESIGN_MATRIX!$B$6)+H$7,1+DESIGN_MATRIX!$E$3)),1,0))^2,"")} -> 324 | I10: {=IF(AND($A10<I$7,I$7<=DESIGN_MATRIX!$E$2),SUM(IF(INDIRECT("DESIGN_MATRIX!"&ADDRESS(ROW(DESIGN_MATRIX!$B$6)+$A10,2)&":"&ADDRESS(ROW(DESIGN_MATRIX!$B$6)+$A10,1+DESIGN_MATRIX!$E$3))=INDIRECT("DESIGN_MATRIX!"&ADDRESS(ROW(DESIGN_MATRIX!$B$6)+I$7,2)&":"&ADDRESS(ROW(DESIGN_MATRIX!$B$6)+I$7,1+DESIGN_MATRIX!$E$3)),1,0))^2,"")} -> 324 | ... CW10: {=IF(AND($A10<CW$7,CW$7<=DESIGN_MATRIX!$E$2),SUM(IF(INDIRECT("DESIGN_MATRIX!"&ADDRESS(ROW(DESIGN_MATRIX!$B$6)+$A10,2)&":"&ADDRESS(ROW(DESIGN_MATRIX!$B$6)+$A10,1+DESIGN_MATRIX!$E$3))=INDIRECT("DESIGN_MATRIX!"&ADDRESS(ROW(DESIGN_MATRIX!$B$6)+CW$7,2)&":"&ADDRESS(ROW(DESIGN_MATRIX!$B$6)+CW$7,1+DESIGN_MATRIX!$E$3)),1,0))^2,"")}
A11: 4 | B11: {=IF(AND($A11<B$7,B$7<=DESIGN_MATRIX!$E$2),SUM(IF(INDIRECT("DESIGN_MATRIX!"&ADDRESS(ROW(DESIGN_MATRIX!$B$6)+$A11,2)&":"&ADDRESS(ROW(DESIGN_MATRIX!$B$6)+$A11,1+DESIGN_MATRIX!$E$3))=INDIRECT("DESIGN_MATRIX!"&ADDRESS(ROW(DESIGN_MATRIX!$B$6)+B$7,2)&":"&ADDRESS(ROW(DESIGN_MATRIX!$B$6)+B$7,1+DESIGN_MATRIX!$E$3)),1,0))^2,"")} | C11: {=IF(AND($A11<C$7,C$7<=DESIGN_MATRIX!$E$2),SUM(IF(INDIRECT("DESIGN_MATRIX!"&ADDRESS(ROW(DESIGN_MATRIX!$B$6)+$A11,2)&":"&ADDRESS(ROW(DESIGN_MATRIX!$B$6)+$A11,1+DESIGN_MATRIX!$E$3))=INDIRECT("DESIGN_MATRIX!"&ADDRESS(ROW(DESIGN_MATRIX!$B$6)+C$7,2)&":"&ADDRESS(ROW(DESIGN_MATRIX!$B$6)+C$7,1+DESIGN_MATRIX!$E$3)),1,0))^2,"")} | D11: {=IF(AND($A11<D$7,D$7<=DESIGN_MATRIX!$E$2),SUM(IF(INDIRECT("DESIGN_MATRIX!"&ADDRESS(ROW(DESIGN_MATRIX!$B$6)+$A11,2)&":"&ADDRESS(ROW(DESIGN_MATRIX!$B$6)+$A11,1+DESIGN_MATRIX!$E$3))=INDIRECT("DESIGN_MATRIX!"&ADDRESS(ROW(DESIGN_MATRIX!$B$6)+D$7,2)&":"&ADDRESS(ROW(DESIGN_MATRIX!$B$6)+D$7,1+DESIGN_MATRIX!$E$3)),1,0))^2,"")} | E11: {=IF(AND($A11<E$7,E$7<=DESIGN_MATRIX!$E$2),SUM(IF(INDIRECT("DESIGN_MATRIX!"&ADDRESS(ROW(DESIGN_MATRIX!$B$6)+$A11,2)&":"&ADDRESS(ROW(DESIGN_MATRIX!$B$6)+$A11,1+DESIGN_MATRIX!$E$3))=INDIRECT("DESIGN_MATRIX!"&ADDRESS(ROW(DESIGN_MATRIX!$B$6)+E$7,2)&":"&ADDRESS(ROW(DESIGN_MATRIX!$B$6)+E$7,1+DESIGN_MATRIX!$E$3)),1,0))^2,"")} | F11: {=IF(AND($A11<F$7,F$7<=DESIGN_MATRIX!$E$2),SUM(IF(INDIRECT("DESIGN_MATRIX!"&ADDRESS(ROW(DESIGN_MATRIX!$B$6)+$A11,2)&":"&ADDRESS(ROW(DESIGN_MATRIX!$B$6)+$A11,1+DESIGN_MATRIX!$E$3))=INDIRECT("DESIGN_MATRIX!"&ADDRESS(ROW(DESIGN_MATRIX!$B$6)+F$7,2)&":"&ADDRESS(ROW(DESIGN_MATRIX!$B$6)+F$7,1+DESIGN_MATRIX!$E$3)),1,0))^2,"")} -> 324 | G11: {=IF(AND($A11<G$7,G$7<=DESIGN_MATRIX!$E$2),SUM(IF(INDIRECT("DESIGN_MATRIX!"&ADDRESS(ROW(DESIGN_MATRIX!$B$6)+$A11,2)&":"&ADDRESS(ROW(DESIGN_MATRIX!$B$6)+$A11,1+DESIGN_MATRIX!$E$3))=INDIRECT("DESIGN_MATRIX!"&ADDRESS(ROW(DESIGN_MATRIX!$B$6)+G$7,2)&":"&ADDRESS(ROW(DESIGN_MATRIX!$B$6)+G$7,1+DESIGN_MATRIX!$E$3)),1,0))^2,"")} -> 324 | H11: {=IF(AND($A11<H$7,H$7<=DESIGN_MATRIX!$E$2),SUM(IF(INDIRECT("DESIGN_MATRIX!"&ADDRESS(ROW(DESIGN_MATRIX!$B$6)+$A11,2)&":"&ADDRESS(ROW(DESIGN_MATRIX!$B$6)+$A11,1+DESIGN_MATRIX!$E$3))=INDIRECT("DESIGN_MATRIX!"&ADDRESS(ROW(DESIGN_MATRIX!$B$6)+H$7,2)&":"&ADDRESS(ROW(DESIGN_MATRIX!$B$6)+H$7,1+DESIGN_MATRIX!$E$3)),1,0))^2,"")} -> 324 | I11: {=IF(AND($A11<I$7,I$7<=DESIGN_MATRIX!$E$2),SUM(IF(INDIRECT("DESIGN_MATRIX!"&ADDRESS(ROW(DESIGN_MATRIX!$B$6)+$A11,2)&":"&ADDRESS(ROW(DESIGN_MATRIX!$B$6)+$A11,1+DESIGN_MATRIX!$E$3))=INDIRECT("DESIGN_MATRIX!"&ADDRESS(ROW(DESIGN_MATRIX!$B$6)+I$7,2)&":"&ADDRESS(ROW(DESIGN_MATRIX!$B$6)+I$7,1+DESIGN_MATRIX!$E$3)),1,0))^2,"")} -> 324 | ... CW11: {=IF(AND($A11<CW$7,CW$7<=DESIGN_MATRIX!$E$2),SUM(IF(INDIRECT("DESIGN_MATRIX!"&ADDRESS(ROW(DESIGN_MATRIX!$B$6)+$A11,2)&":"&ADDRESS(ROW(DESIGN_MATRIX!$B$6)+$A11,1+DESIGN_MATRIX!$E$3))=INDIRECT("DESIGN_MATRIX!"&ADDRESS(ROW(DESIGN_MATRIX!$B$6)+CW$7,2)&":"&ADDRESS(ROW(DESIGN_MATRIX!$B$6)+CW$7,1+DESIGN_MATRIX!$E$3)),1,0))^2,"")}
A12: 5 | B12: {=IF(AND($A12<B$7,B$7<=DESIGN_MATRIX!$E$2),SUM(IF(INDIRECT("DESIGN_MATRIX!"&ADDRESS(ROW(DESIGN_MATRIX!$B$6)+$A12,2)&":"&ADDRESS(ROW(DESIGN_MATRIX!$B$6)+$A12,1+DESIGN_MATRIX!$E$3))=INDIRECT("DESIGN_MATRIX!"&ADDRESS(ROW(DESIGN_MATRIX!$B$6)+B$7,2)&":"&ADDRESS(ROW(DESIGN_MATRIX!$B$6)+B$7,1+DESIGN_MATRIX!$E$3)),1,0))^2,"")} | C12: {=IF(AND($A12<C$7,C$7<=DESIGN_MATRIX!$E$2),SUM(IF(INDIRECT("DESIGN_MATRIX!"&ADDRESS(ROW(DESIGN_MATRIX!$B$6)+$A12,2)&":"&ADDRESS(ROW(DESIGN_MATRIX!$B$6)+$A12,1+DESIGN_MATRIX!$E$3))=INDIRECT("DESIGN_MATRIX!"&ADDRESS(ROW(DESIGN_MATRIX!$B$6)+C$7,2)&":"&ADDRESS(ROW(DESIGN_MATRIX!$B$6)+C$7,1+DESIGN_MATRIX!$E$3)),1,0))^2,"")} | D12: {=IF(AND($A12<D$7,D$7<=DESIGN_MATRIX!$E$2),SUM(IF(INDIRECT("DESIGN_MATRIX!"&ADDRESS(ROW(DESIGN_MATRIX!$B$6)+$A12,2)&":"&ADDRESS(ROW(DESIGN_MATRIX!$B$6)+$A12,1+DESIGN_MATRIX!$E$3))=INDIRECT("DESIGN_MATRIX!"&ADDRESS(ROW(DESIGN_MATRIX!$B$6)+D$7,2)&":"&ADDRESS(ROW(DESIGN_MATRIX!$B$6)+D$7,1+DESIGN_MATRIX!$E$3)),1,0))^2,"")} | E12: {=IF(AND($A12<E$7,E$7<=DESIGN_MATRIX!$E$2),SUM(IF(INDIRECT("DESIGN_MATRIX!"&ADDRESS(ROW(DESIGN_MATRIX!$B$6)+$A12,2)&":"&ADDRESS(ROW(DESIGN_MATRIX!$B$6)+$A12,1+DESIGN_MATRIX!$E$3))=INDIRECT("DESIGN_MATRIX!"&ADDRESS(ROW(DESIGN_MATRIX!$B$6)+E$7,2)&":"&ADDRESS(ROW(DESIGN_MATRIX!$B$6)+E$7,1+DESIGN_MATRIX!$E$3)),1,0))^2,"")} | F12: {=IF(AND($A12<F$7,F$7<=DESIGN_MATRIX!$E$2),SUM(IF(INDIRECT("DESIGN_MATRIX!"&ADDRESS(ROW(DESIGN_MATRIX!$B$6)+$A12,2)&":"&ADDRESS(ROW(DESIGN_MATRIX!$B$6)+$A12,1+DESIGN_MATRIX!$E$3))=INDIRECT("DESIGN_MATRIX!"&ADDRESS(ROW(DESIGN_MATRIX!$B$6)+F$7,2)&":"&ADDRESS(ROW(DESIGN_MATRIX!$B$6)+F$7,1+DESIGN_MATRIX!$E$3)),1,0))^2,"")} | G12: {=IF(AND($A12<G$7,G$7<=DESIGN_MATRIX!$E$2),SUM(IF(INDIRECT("DESIGN_MATRIX!"&ADDRESS(ROW(DESIGN_MATRIX!$B$6)+$A12,2)&":"&ADDRESS(ROW(DESIGN_MATRIX!$B$6)+$A12,1+DESIGN_MATRIX!$E$3))=INDIRECT("DESIGN_MATRIX!"&ADDRESS(ROW(DESIGN_MATRIX!$B$6)+G$7,2)&":"&ADDRESS(ROW(DESIGN_MATRIX!$B$6)+G$7,1+DESIGN_MATRIX!$E$3)),1,0))^2,"")} -> 324 | H12: {=IF(AND($A12<H$7,H$7<=DESIGN_MATRIX!$E$2),SUM(IF(INDIRECT("DESIGN_MATRIX!"&ADDRESS(ROW(DESIGN_MATRIX!$B$6)+$A12,2)&":"&ADDRESS(ROW(DESIGN_MATRIX!$B$6)+$A12,1+DESIGN_MATRIX!$E$3))=INDIRECT("DESIGN_MATRIX!"&ADDRESS(ROW(DESIGN_MATRIX!$B$6)+H$7,2)&":"&ADDRESS(ROW(DESIGN_MATRIX!$B$6)+H$7,1+DESIGN_MATRIX!$E$3)),1,0))^2,"")} -> 289 | I12: {=IF(AND($A12<I$7,I$7<=DESIGN_MATRIX!$E$2),SUM(IF(INDIRECT("DESIGN_MATRIX!"&ADDRESS(ROW(DESIGN_MATRIX!$B$6)+$A12,2)&":"&ADDRESS(ROW(DESIGN_MATRIX!$B$6)+$A12,1+DESIGN_MATRIX!$E$3))=INDIRECT("DESIGN_MATRIX!"&ADDRESS(ROW(DESIGN_MATRIX!$B$6)+I$7,2)&":"&ADDRESS(ROW(DESIGN_MATRIX!$B$6)+I$7,1+DESIGN_MATRIX!$E$3)),1,0))^2,"")} -> 324 | ... CW12: {=IF(AND($A12<CW$7,CW$7<=DESIGN_MATRIX!$E$2),SUM(IF(INDIRECT("DESIGN_MATRIX!"&ADDRESS(ROW(DESIGN_MATRIX!$B$6)+$A12,2)&":"&ADDRESS(ROW(DESIGN_MATRIX!$B$6)+$A12,1+DESIGN_MATRIX!$E$3))=INDIRECT("DESIGN_MATRIX!"&ADDRESS(ROW(DESIGN_MATRIX!$B$6)+CW$7,2)&":"&ADDRESS(ROW(DESIGN_MATRIX!$B$6)+CW$7,1+DESIGN_MATRIX!$E$3)),1,0))^2,"")}
A13: 6 | B13: {=IF(AND($A13<B$7,B$7<=DESIGN_MATRIX!$E$2),SUM(IF(INDIRECT("DESIGN_MATRIX!"&ADDRESS(ROW(DESIGN_MATRIX!$B$6)+$A13,2)&":"&ADDRESS(ROW(DESIGN_MATRIX!$B$6)+$A13,1+DESIGN_MATRIX!$E$3))=INDIRECT("DESIGN_MATRIX!"&ADDRESS(ROW(DESIGN_MATRIX!$B$6)+B$7,2)&":"&ADDRESS(ROW(DESIGN_MATRIX!$B$6)+B$7,1+DESIGN_MATRIX!$E$3)),1,0))^2,"")} | C13: {=IF(AND($A13<C$7,C$7<=DESIGN_MATRIX!$E$2),SUM(IF(INDIRECT("DESIGN_MATRIX!"&ADDRESS(ROW(DESIGN_MATRIX!$B$6)+$A13,2)&":"&ADDRESS(ROW(DESIGN_MATRIX!$B$6)+$A13,1+DESIGN_MATRIX!$E$3))=INDIRECT("DESIGN_MATRIX!"&ADDRESS(ROW(DESIGN_MATRIX!$B$6)+C$7,2)&":"&ADDRESS(ROW(DESIGN_MATRIX!$B$6)+C$7,1+DESIGN_MATRIX!$E$3)),1,0))^2,"")} | D13: {=IF(AND($A13<D$7,D$7<=DESIGN_MATRIX!$E$2),SUM(IF(INDIRECT("DESIGN_MATRIX!"&ADDRESS(ROW(DESIGN_MATRIX!$B$6)+$A13,2)&":"&ADDRESS(ROW(DESIGN_MATRIX!$B$6)+$A13,1+DESIGN_MATRIX!$E$3))=INDIRECT("DESIGN_MATRIX!"&ADDRESS(ROW(DESIGN_MATRIX!$B$6)+D$7,2)&":"&ADDRESS(ROW(DESIGN_MATRIX!$B$6)+D$7,1+DESIGN_MATRIX!$E$3)),1,0))^2,"")} | E13: {=IF(AND($A13<E$7,E$7<=DESIGN_MATRIX!$E$2),SUM(IF(INDIRECT("DESIGN_MATRIX!"&ADDRESS(ROW(DESIGN_MATRIX!$B$6)+$A13,2)&":"&ADDRESS(ROW(DESIGN_MATRIX!$B$6)+$A13,1+DESIGN_MATRIX!$E$3))=INDIRECT("DESIGN_MATRIX!"&ADDRESS(ROW(DESIGN_MATRIX!$B$6)+E$7,2)&":"&ADDRESS(ROW(DESIGN_MATRIX!$B$6)+E$7,1+DESIGN_MATRIX!$E$3)),1,0))^2,"")} | F13: {=IF(AND($A13<F$7,F$7<=DESIGN_MATRIX!$E$2),SUM(IF(INDIRECT("DESIGN_MATRIX!"&ADDRESS(ROW(DESIGN_MATRIX!$B$6)+$A13,2)&":"&ADDRESS(ROW(DESIGN_MATRIX!$B$6)+$A13,1+DESIGN_MATRIX!$E$3))=INDIRECT("DESIGN_MATRIX!"&ADDRESS(ROW(DESIGN_MATRIX!$B$6)+F$7,2)&":"&ADDRESS(ROW(DESIGN_MATRIX!$B$6)+F$7,1+DESIGN_MATRIX!$E$3)),1,0))^2,"")} | G13: {=IF(AND($A13<G$7,G$7<=DESIGN_MATRIX!$E$2),SUM(IF(INDIRECT("DESIGN_MATRIX!"&ADDRESS(ROW(DESIGN_MATRIX!$B$6)+$A13,2)&":"&ADDRESS(ROW(DESIGN_MATRIX!$B$6)+$A13,1+DESIGN_MATRIX!$E$3))=INDIRECT("DESIGN_MATRIX!"&ADDRESS(ROW(DESIGN_MATRIX!$B$6)+G$7,2)&":"&ADDRESS(ROW(DESIGN_MATRIX!$B$6)+G$7,1+DESIGN_MATRIX!$E$3)),1,0))^2,"")} | H13: {=IF(AND($A13<H$7,H$7<=DESIGN_MATRIX!$E$2),SUM(IF(INDIRECT("DESIGN_MATRIX!"&ADDRESS(ROW(DESIGN_MATRIX!$B$6)+$A13,2)&":"&ADDRESS(ROW(DESIGN_MATRIX!$B$6)+$A13,1+DESIGN_MATRIX!$E$3))=INDIRECT("DESIGN_MATRIX!"&ADDRESS(ROW(DESIGN_MATRIX!$B$6)+H$7,2)&":"&ADDRESS(ROW(DESIGN_MATRIX!$B$6)+H$7,1+DESIGN_MATRIX!$E$3)),1,0))^2,"")} -> 324 | I13: {=IF(AND($A13<I$7,I$7<=DESIGN_MATRIX!$E$2),SUM(IF(INDIRECT("DESIGN_MATRIX!"&ADDRESS(ROW(DESIGN_MATRIX!$B$6)+$A13,2)&":"&ADDRESS(ROW(DESIGN_MATRIX!$B$6)+$A13,1+DESIGN_MATRIX!$E$3))=INDIRECT("DESIGN_MATRIX!"&ADDRESS(ROW(DESIGN_MATRIX!$B$6)+I$7,2)&":"&ADDRESS(ROW(DESIGN_MATRIX!$B$6)+I$7,1+DESIGN_MATRIX!$E$3)),1,0))^2,"")} -> 289 | ... CW13: {=IF(AND($A13<CW$7,CW$7<=DESIGN_MATRIX!$E$2),SUM(IF(INDIRECT("DESIGN_MATRIX!"&ADDRESS(ROW(DESIGN_MATRIX!$B$6)+$A13,2)&":"&ADDRESS(ROW(DESIGN_MATRIX!$B$6)+$A13,1+DESIGN_MATRIX!$E$3))=INDIRECT("DESIGN_MATRIX!"&ADDRESS(ROW(DESIGN_MATRIX!$B$6)+CW$7,2)&":"&ADDRESS(ROW(DESIGN_MATRIX!$B$6)+CW$7,1+DESIGN_MATRIX!$E$3)),1,0))^2,"")}
